[11/Apr/2019 12:50:10] "GET /blog/index/ HTTP/1.1" 200 540
[11/Apr/2019 12:50:20] "GET /blog/index/ HTTP/1.1" 200 540
[11/Apr/2019 12:50:22] "GET /blog/article/12/ HTTP/1.1" 200 342
[11/Apr/2019 12:50:33] "GET /blog/article/12/ HTTP/1.1" 200 342
[11/Apr/2019 12:50:36] "GET /blog/index/ HTTP/1.1" 200 540
[11/Apr/2019 12:50:37] "GET /blog/article/2/ HTTP/1.1" 200 409
[11/Apr/2019 12:51:47] "GET /blog/article/2/ HTTP/1.1" 200 409
[11/Apr/2019 12:51:49] "GET /blog/index/ HTTP/1.1" 200 540
[11/Apr/2019 12:53:37] "GET /blog/index/ HTTP/1.1" 200 540
[11/Apr/2019 12:53:39] "GET /blog/article/2/ HTTP/1.1" 200 409
[11/Apr/2019 12:53:43] "GET /blog/article/3/ HTTP/1.1" 200 400
[11/Apr/2019 12:53:50] "GET /blog/article/12/ HTTP/1.1" 200 342
Not Found: /blog/admin
[11/Apr/2019 12:54:14] "GET /blog/admin HTTP/1.1" 404 3326
[11/Apr/2019 12:54:20] "GET /admin HTTP/1.1" 301 0
[11/Apr/2019 12:54:20] "GET /admin/ HTTP/1.1" 302 0
[11/Apr/2019 12:54:20] "GET /admin/login/?next=/admin/ HTTP/1.1" 200 1819
[11/Apr/2019 12:54:20] "GET /static/admin/css/base.css HTTP/1.1" 200 16225
[11/Apr/2019 12:54:20] "GET /static/admin/css/login.css HTTP/1.1" 200 1203
[11/Apr/2019 12:54:20] "GET /static/admin/css/responsive.css HTTP/1.1" 200 17976
[11/Apr/2019 12:54:20] "GET /static/admin/css/fonts.css HTTP/1.1" 304 0
[11/Apr/2019 12:54:20] "GET /static/admin/fonts/Roboto-Regular-webfont.woff HTTP/1.1" 304 0
[11/Apr/2019 12:54:20] "GET /static/admin/fonts/Roboto-Light-webfont.woff HTTP/1.1" 304 0
[11/Apr/2019 12:54:27] "POST /admin/login/?next=/admin/ HTTP/1.1" 302 0
[11/Apr/2019 12:54:27] "GET /admin/ HTTP/1.1" 200 5116
[11/Apr/2019 12:54:27] "GET /static/admin/css/dashboard.css HTTP/1.1" 200 412
[11/Apr/2019 12:54:27] "GET /static/admin/img/icon-addlink.svg HTTP/1.1" 200 331
[11/Apr/2019 12:54:28] "GET /static/admin/img/icon-changelink.svg HTTP/1.1" 200 380
[11/Apr/2019 12:54:28] "GET /static/admin/img/icon-deletelink.svg HTTP/1.1" 200 392
[11/Apr/2019 12:54:28] "GET /static/admin/fonts/Roboto-Bold-webfont.woff HTTP/1.1" 304 0
[11/Apr/2019 12:54:29] "GET /admin/blog/article/ HTTP/1.1" 200 4800
[11/Apr/2019 12:54:29] "GET /static/admin/css/changelists.css HTTP/1.1" 200 6170
[11/Apr/2019 12:54:29] "GET /admin/jsi18n/ HTTP/1.1" 200 3185
[11/Apr/2019 12:54:29] "GET /static/admin/js/jquery.init.js HTTP/1.1" 200 363
[11/Apr/2019 12:54:29] "GET /static/admin/js/core.js HTTP/1.1" 200 7135
[11/Apr/2019 12:54:29] "GET /static/admin/js/admin/RelatedObjectLookups.js HTTP/1.1" 200 6918
[11/Apr/2019 12:54:29] "GET /static/admin/js/actions.js HTTP/1.1" 200 6538
[11/Apr/2019 12:54:29] "GET /static/admin/js/urlify.js HTTP/1.1" 200 8972
[11/Apr/2019 12:54:29] "GET /static/admin/js/prepopulate.js HTTP/1.1" 200 1530
[11/Apr/2019 12:54:30] "GET /static/admin/js/vendor/xregexp/xregexp.js HTTP/1.1" 200 128820
[11/Apr/2019 12:54:30] "GET /static/admin/js/vendor/jquery/jquery.js HTTP/1.1" 200 271751
[11/Apr/2019 12:54:30] "GET /static/admin/img/tooltag-add.svg HTTP/1.1" 200 331
[11/Apr/2019 12:54:32] "GET /admin/blog/article/3/change/ HTTP/1.1" 200 4853
[11/Apr/2019 12:54:32] "GET /admin/jsi18n/ HTTP/1.1" 200 3185
[11/Apr/2019 12:54:32] "GET /static/admin/css/forms.css HTTP/1.1" 200 8505
[11/Apr/2019 12:54:32] "GET /static/admin/js/prepopulate_init.js HTTP/1.1" 200 495
[11/Apr/2019 12:54:32] "GET /static/admin/js/change_form.js HTTP/1.1" 200 712
[11/Apr/2019 12:54:32] "GET /static/admin/css/widgets.css HTTP/1.1" 200 10340
[11/Apr/2019 12:54:34] "GET /admin/blog/article/ HTTP/1.1" 200 4800
[11/Apr/2019 12:54:35] "GET /admin/blog/article/2/change/ HTTP/1.1" 200 4862
[11/Apr/2019 12:54:35] "GET /admin/jsi18n/ HTTP/1.1" 200 3185
[11/Apr/2019 12:54:37] "GET /admin/blog/article/ HTTP/1.1" 200 4800
[11/Apr/2019 12:54:38] "GET /admin/blog/article/12/change/ HTTP/1.1" 200 4791
[11/Apr/2019 12:54:39] "GET /admin/jsi18n/ HTTP/1.1" 200 3185
[11/Apr/2019 12:54:43] "GET /admin/blog/article/ HTTP/1.1" 200 4800
[11/Apr/2019 13:00:25] "GET /blog/article/3/ HTTP/1.1" 200 400
[11/Apr/2019 13:00:26] "GET /blog/edit/tocha/3/ HTTP/1.1" 200 704
[11/Apr/2019 13:10:19] "GET /blog/edit/ HTTP/1.1" 200 552
[11/Apr/2019 13:10:34] "POST /blog/edit/action/ HTTP/1.1" 200 644
[11/Apr/2019 13:10:45] "GET /blog/article/14/ HTTP/1.1" 200 263
[11/Apr/2019 13:10:47] "GET /blog/edit/tocha/14/ HTTP/1.1" 200 567
[11/Apr/2019 13:10:52] "POST /blog/edit/change/14/ HTTP/1.1" 200 644
[11/Apr/2019 13:10:56] "GET /blog/article/14/ HTTP/1.1" 200 270
[11/Apr/2019 13:10:57] "GET /blog/index/ HTTP/1.1" 200 644
[11/Apr/2019 13:10:59] "GET /blog/article/14/ HTTP/1.1" 200 270
[11/Apr/2019 13:11:01] "GET /blog/index/ HTTP/1.1" 200 644
[11/Apr/2019 13:11:02] "GET /blog/article/14/ HTTP/1.1" 200 270
[11/Apr/2019 13:11:04] "GET /blog/edit/tocha/14/ HTTP/1.1" 200 574
[11/Apr/2019 13:11:09] "POST /blog/edit/change/14/ HTTP/1.1" 200 653
[11/Apr/2019 13:11:10] "GET /blog/article/14/ HTTP/1.1" 200 279
[11/Apr/2019 13:11:12] "GET /blog/index/ HTTP/1.1" 200 653
[11/Apr/2019 13:11:13] "GET /blog/article/2/ HTTP/1.1" 200 409
[11/Apr/2019 13:11:14] "GET /blog/index/ HTTP/1.1" 200 653
[11/Apr/2019 13:11:16] "GET /blog/article/3/ HTTP/1.1" 200 400
[11/Apr/2019 13:11:17] "GET /blog/edit/tocha/3/ HTTP/1.1" 200 704
[11/Apr/2019 13:11:20] "POST /blog/edit/change/3/ HTTP/1.1" 200 653
[11/Apr/2019 13:11:23] "GET /blog/edit/ HTTP/1.1" 200 552
[11/Apr/2019 13:11:30] "GET /blog/article/14/ HTTP/1.1" 200 279
[11/Apr/2019 13:15:42] "GET /blog/edit/delete/14/ HTTP/1.1" 200 540
[11/Apr/2019 14:50:38] "GET /blog/article/2/ HTTP/1.1" 200 409
[11/Apr/2019 14:50:39] "GET /blog/index/ HTTP/1.1" 200 540
[11/Apr/2019 14:51:34] "GET /blog/index/ HTTP/1.1" 200 540
[11/Apr/2019 14:51:37] "GET /blog/article/2/ HTTP/1.1" 200 409
[11/Apr/2019 14:51:41] "GET /blog/article/3/ HTTP/1.1" 200 400
[11/Apr/2019 14:51:44] "GET /blog/article/12/ HTTP/1.1" 200 342
[11/Apr/2019 15:01:36] "GET /blog/article/3/ HTTP/1.1" 200 400
[11/Apr/2019 15:01:44] "GET /blog/index/ HTTP/1.1" 200 540
[11/Apr/2019 15:01:45] "GET /blog/article/2/ HTTP/1.1" 200 409
[11/Apr/2019 15:01:46] "GET /blog/index/ HTTP/1.1" 200 540
[11/Apr/2019 15:01:47] "GET /blog/article/12/ HTTP/1.1" 200 342
[11/Apr/2019 15:01:51] "GET /blog/index/ HTTP/1.1" 200 540
[11/Apr/2019 15:04:32] "GET /blog/index/?nsukey=VXTtA3jZKIURu7lYqTRehOpCeP4hTWDdTwkETy9lDDl%2FIrz6v8UT6qROZQQSIGVkcbGkP5d5IrKHHQ%2B06aKqsPI5k4jYXJNYoOBvwpCJ7mBsyr7AEgx1rIONSf7v%2BQC0ucrnOs1a%2BHZYB98XcJFTHLLx4A5GE16B6eWCad1IDXlBLe6946El%2Fof9AbChSW6UwBtwNUtDvAWfSQvWvP%2FTjQ%3D%3D HTTP/1.1" 200 540
[11/Apr/2019 15:04:35] "GET /blog/article/2/ HTTP/1.1" 200 409
[11/Apr/2019 15:04:36] "GET /blog/article/2/?nsukey=2pmIF6FS5mWd6edyVCLP85NfmR1Z26kZHGWsJvjs0xZZ0rUQwyhLdUXI3fanZTlkCjrwM3N3uU%2FqSwFyI8ggsDpW2OcudPdI3qiweJLV%2BLXKMy6omHVfzbEo%2Fwb%2F%2BkOXLAsbbJ%2FspUMFjCvsR0rmsRGoBx5C0sWKwUNh65BdaPgrI2M%2BYGASd0fN66pW9dQYwr%2BbNWpx1Vj7Hf9g3r%2B0Mg%3D%3D HTTP/1.1" 200 409
----------------------------------------
Exception happened during processing of request from ('220.112.121.253', 50115)
Traceback (most recent call last):
  File "/usr/local/lib/python3.6/socketserver.py", line 636, in process_request_thread
    self.finish_request(request, client_address)
  File "/usr/local/lib/python3.6/socketserver.py", line 358, in finish_request
    self.RequestHandlerClass(request, client_address, self)
  File "/usr/local/lib/python3.6/socketserver.py", line 692, in __init__
    self.handle()
  File "/usr/local/lib/python3.6/site-packages/django/core/servers/basehttp.py", line 171, in handle
    self.handle_one_request()
  File "/usr/local/lib/python3.6/site-packages/django/core/servers/basehttp.py", line 179, in handle_one_request
    self.raw_requestline = self.rfile.readline(65537)
  File "/usr/local/lib/python3.6/socket.py", line 575, in readinto
    return self._sock.recv_into(b)
ConnectionResetError: [Errno 104] Connection reset by peer
----------------------------------------
[11/Apr/2019 15:05:30] "GET /blog/index HTTP/1.1" 301 0
[11/Apr/2019 15:05:32] "GET /blog/index/?nsukey=VXTtA3jZKIURu7lYqTRehOpCeP4hTWDdTwkETy9lDDl%2FIrz6v8UT6qROZQQSIGVkcbGkP5d5IrKHHQ%2B06aKqsPI5k4jYXJNYoOBvwpCJ7mBsyr7AEgx1rIONSf7v%2BQC0ucrnOs1a%2BHZYB98XcJFTHLLx4A5GE16B6eWCad1IDXlBLe6946El%2Fof9AbChSW6UwBtwNUtDvAWfSQvWvP%2FTjQ%3D%3D HTTP/1.1" 200 540
[11/Apr/2019 15:05:35] "GET /blog/article/2 HTTP/1.1" 301 0
[11/Apr/2019 15:05:36] "GET /blog/article/2/?nsukey=2pmIF6FS5mWd6edyVCLP85NfmR1Z26kZHGWsJvjs0xZZ0rUQwyhLdUXI3fanZTlkCjrwM3N3uU%2FqSwFyI8ggsDpW2OcudPdI3qiweJLV%2BLXKMy6omHVfzbEo%2Fwb%2F%2BkOXLAsbbJ%2FspUMFjCvsR0rmsRGoBx5C0sWKwUNh65BdaPgrI2M%2BYGASd0fN66pW9dQYwr%2BbNWpx1Vj7Hf9g3r%2B0Mg%3D%3D HTTP/1.1" 200 409
[11/Apr/2019 15:39:00] "GET /blog/index/ HTTP/1.1" 200 626
[11/Apr/2019 15:41:11] "GET /blog/index/ HTTP/1.1" 200 642
[11/Apr/2019 15:42:03] "GET /blog/article/2/ HTTP/1.1" 200 409
[11/Apr/2019 15:42:06] "GET /blog/edit/ HTTP/1.1" 200 552
[11/Apr/2019 15:42:11] "GET /blog/article/12/ HTTP/1.1" 200 342
[11/Apr/2019 15:42:17] "GET /blog/article/3/ HTTP/1.1" 200 400
[11/Apr/2019 15:43:21] "GET /blog/index/?nsukey=whiCJUlKDHHxrAsSC3ExBv%2BhSy7pSoCREl2DNS6JwsGBw9zCfx99TA8Rzy6XgRIIJLDgHhDcBUviD1qvqxuzABgYdth7%2Fc%2Be3bfdPfKp0Hm2VTp1MUXRafh0KF%2BkILN8sgVvHP9HdTctnQWZLQG8hLr%2FY0Ez6Wr%2B8cDSk%2F3ARRH5cwXa%2BHWzrHlAsapTv%2F7bNZCQSDOaI6Q8KyyiiCxkSw%3D%3D HTTP/1.1" 200 642
----------------------------------------
Exception happened during processing of request from ('220.112.121.253', 50127)
Traceback (most recent call last):
  File "/usr/local/lib/python3.6/socketserver.py", line 636, in process_request_thread
    self.finish_request(request, client_address)
  File "/usr/local/lib/python3.6/socketserver.py", line 358, in finish_request
    self.RequestHandlerClass(request, client_address, self)
  File "/usr/local/lib/python3.6/socketserver.py", line 692, in __init__
    self.handle()
  File "/usr/local/lib/python3.6/site-packages/django/core/servers/basehttp.py", line 171, in handle
    self.handle_one_request()
  File "/usr/local/lib/python3.6/site-packages/django/core/servers/basehttp.py", line 179, in handle_one_request
    self.raw_requestline = self.rfile.readline(65537)
  File "/usr/local/lib/python3.6/socket.py", line 575, in readinto
    return self._sock.recv_into(b)
ConnectionResetError: [Errno 104] Connection reset by peer
----------------------------------------
[11/Apr/2019 15:44:21] "GET /blog/index/?nsukey=whiCJUlKDHHxrAsSC3ExBv%2BhSy7pSoCREl2DNS6JwsGBw9zCfx99TA8Rzy6XgRIIJLDgHhDcBUviD1qvqxuzABgYdth7%2Fc%2Be3bfdPfKp0Hm2VTp1MUXRafh0KF%2BkILN8sgVvHP9HdTctnQWZLQG8hLr%2FY0Ez6Wr%2B8cDSk%2F3ARRH5cwXa%2BHWzrHlAsapTv%2F7bNZCQSDOaI6Q8KyyiiCxkSw%3D%3D HTTP/1.1" 200 642
[11/Apr/2019 16:06:35] "GET /blog/index/ HTTP/1.1" 200 642
[11/Apr/2019 16:06:38] "GET /blog/article/12/ HTTP/1.1" 200 342
[11/Apr/2019 16:06:44] "GET /blog/article/3/ HTTP/1.1" 200 400
[11/Apr/2019 16:06:46] "GET /blog/article/2/ HTTP/1.1" 200 409
[11/Apr/2019 16:06:49] "GET /blog/article/3/ HTTP/1.1" 200 400
[11/Apr/2019 16:08:02] "GET /blog/index/ HTTP/1.1" 200 642
[11/Apr/2019 16:08:06] "GET /blog/article/2/ HTTP/1.1" 200 409
[11/Apr/2019 16:08:10] "GET /blog/edit/ HTTP/1.1" 200 552
[11/Apr/2019 16:08:12] "POST /blog/edit/action/ HTTP/1.1" 200 740
Not Found: /http:/www.baidu.com/cache/global/img/gs.gif
[11/Apr/2019 16:13:40] "GET http://www.baidu.com/cache/global/img/gs.gif HTTP/1.1" 404 1738
----------------------------------------
Exception happened during processing of request from ('80.82.70.187', 58390)
Traceback (most recent call last):
  File "/usr/local/lib/python3.6/socketserver.py", line 636, in process_request_thread
    self.finish_request(request, client_address)
  File "/usr/local/lib/python3.6/socketserver.py", line 358, in finish_request
    self.RequestHandlerClass(request, client_address, self)
  File "/usr/local/lib/python3.6/socketserver.py", line 692, in __init__
    self.handle()
  File "/usr/local/lib/python3.6/site-packages/django/core/servers/basehttp.py", line 171, in handle
    self.handle_one_request()
  File "/usr/local/lib/python3.6/site-packages/django/core/servers/basehttp.py", line 179, in handle_one_request
    self.raw_requestline = self.rfile.readline(65537)
  File "/usr/local/lib/python3.6/socket.py", line 575, in readinto
    return self._sock.recv_into(b)
ConnectionResetError: [Errno 104] Connection reset by peer
----------------------------------------
[11/Apr/2019 16:34:39] "GET /blog/index/?nsukey=VR0v303ClYme%2BoyTd8NeINbcOg23i6Sm17tLC8YdmDZ0olNWQKN7Cl9fzdQwPltBJFPdWq2Wax8WOo79oWKlEnTdBdp2hQSP13J5tXgj8Ms2gWtVEPh3bZfieZ8ntLwB1kVgnmMkIpH%2F4tuzWTtwZXzgHMRarZhlvIBLXBX6iVpONauX%2Bta7HH5YjP3lm3xDIc6YGuLXKn2ZpfdnySSTbg%3D%3D HTTP/1.1" 200 740
[11/Apr/2019 16:34:43] "GET /blog/article/2/ HTTP/1.1" 200 409
[11/Apr/2019 16:34:44] "GET /blog/article/2/?nsukey=igk9jZ6wjbKFaaDN93cPlFYGJQKHc6nRzASyh42tdw0J%2B41URGJCbaEyUn0jQktzZALplkBHAgWn2LIXL9BHueDeWNVIOooky5DvJC4nStSUG0YzHgdDO%2FtzHt%2BpIIn5yfTJtF3Pvm17HRXvmeX3I4S3ZchHMM8%2FEdM7F5ILN6aKgcZHllwfBQsZe8%2Ftv9E2MEqVLZ%2FjGtfhFTyrA1Rrug%3D%3D HTTP/1.1" 200 409
----------------------------------------
Exception happened during processing of request from ('220.112.121.253', 50200)
Traceback (most recent call last):
  File "/usr/local/lib/python3.6/socketserver.py", line 636, in process_request_thread
    self.finish_request(request, client_address)
  File "/usr/local/lib/python3.6/socketserver.py", line 358, in finish_request
    self.RequestHandlerClass(request, client_address, self)
  File "/usr/local/lib/python3.6/socketserver.py", line 692, in __init__
    self.handle()
  File "/usr/local/lib/python3.6/site-packages/django/core/servers/basehttp.py", line 171, in handle
    self.handle_one_request()
  File "/usr/local/lib/python3.6/site-packages/django/core/servers/basehttp.py", line 179, in handle_one_request
    self.raw_requestline = self.rfile.readline(65537)
  File "/usr/local/lib/python3.6/socket.py", line 575, in readinto
    return self._sock.recv_into(b)
ConnectionResetError: [Errno 104] Connection reset by peer
----------------------------------------
[11/Apr/2019 16:35:39] "GET /blog/index/?nsukey=VR0v303ClYme%2BoyTd8NeINbcOg23i6Sm17tLC8YdmDZ0olNWQKN7Cl9fzdQwPltBJFPdWq2Wax8WOo79oWKlEnTdBdp2hQSP13J5tXgj8Ms2gWtVEPh3bZfieZ8ntLwB1kVgnmMkIpH%2F4tuzWTtwZXzgHMRarZhlvIBLXBX6iVpONauX%2Bta7HH5YjP3lm3xDIc6YGuLXKn2ZpfdnySSTbg%3D%3D HTTP/1.1" 200 740
[11/Apr/2019 16:35:44] "GET /blog/article/2/?nsukey=igk9jZ6wjbKFaaDN93cPlFYGJQKHc6nRzASyh42tdw0J%2B41URGJCbaEyUn0jQktzZALplkBHAgWn2LIXL9BHueDeWNVIOooky5DvJC4nStSUG0YzHgdDO%2FtzHt%2BpIIn5yfTJtF3Pvm17HRXvmeX3I4S3ZchHMM8%2FEdM7F5ILN6aKgcZHllwfBQsZe8%2Ftv9E2MEqVLZ%2FjGtfhFTyrA1Rrug%3D%3D HTTP/1.1" 200 409
[12/Apr/2019 01:57:26] "GET /blog/index/ HTTP/1.1" 200 740
Not Found: /favicon.ico
[12/Apr/2019 01:57:27] "GET /favicon.ico HTTP/1.1" 404 2081
[12/Apr/2019 01:57:47] "GET /blog/edit/delete/15/ HTTP/1.1" 200 642
[12/Apr/2019 01:57:53] "GET /blog/article/12/ HTTP/1.1" 200 342
[12/Apr/2019 01:57:56] "GET /blog/index/ HTTP/1.1" 200 642
[12/Apr/2019 01:57:58] "GET /blog/article/2/ HTTP/1.1" 200 409
[12/Apr/2019 01:58:09] "GET /blog/edit/ HTTP/1.1" 200 552
[12/Apr/2019 01:58:10] "POST /blog/edit/action/ HTTP/1.1" 200 740
[12/Apr/2019 01:58:13] "GET /blog/edit/delete/16/ HTTP/1.1" 200 642
Not Found: /http:/www.baidu.com/cache/global/img/gs.gif
[12/Apr/2019 02:17:27] "GET http://www.baidu.com/cache/global/img/gs.gif HTTP/1.1" 404 1738
----------------------------------------
Exception happened during processing of request from ('80.82.70.187', 52678)
Traceback (most recent call last):
  File "/usr/local/lib/python3.6/socketserver.py", line 636, in process_request_thread
    self.finish_request(request, client_address)
  File "/usr/local/lib/python3.6/socketserver.py", line 358, in finish_request
    self.RequestHandlerClass(request, client_address, self)
  File "/usr/local/lib/python3.6/socketserver.py", line 692, in __init__
    self.handle()
  File "/usr/local/lib/python3.6/site-packages/django/core/servers/basehttp.py", line 171, in handle
    self.handle_one_request()
  File "/usr/local/lib/python3.6/site-packages/django/core/servers/basehttp.py", line 179, in handle_one_request
    self.raw_requestline = self.rfile.readline(65537)
  File "/usr/local/lib/python3.6/socket.py", line 575, in readinto
    return self._sock.recv_into(b)
ConnectionResetError: [Errno 104] Connection reset by peer
----------------------------------------
Performing system checks...

System check identified no issues (0 silenced).
April 11, 2019 - 12:49:57
Django version 2.1.8, using settings 'myblog.settings'
Starting development server at http://0.0.0.0:8000/
Quit the server with CONTROL-C.
[12/Apr/2019 02:26:33] "GET /blog/edit/delete/16/ HTTP/1.1" 200 642
[12/Apr/2019 03:50:27] "GET /blog/index HTTP/1.1" 301 0
[12/Apr/2019 03:50:27] "GET /blog/index/ HTTP/1.1" 200 642
Not Found: /favicon.ico
[12/Apr/2019 03:50:29] "GET /favicon.ico HTTP/1.1" 404 2081
[12/Apr/2019 03:50:31] "GET /blog/article/3/ HTTP/1.1" 200 400
Not Found: /favicon.ico
[12/Apr/2019 03:50:31] "GET /favicon.ico HTTP/1.1" 404 2081
[12/Apr/2019 03:50:41] "GET /blog/edit/ HTTP/1.1" 200 552
Not Found: /favicon.ico
[12/Apr/2019 03:50:41] "GET /favicon.ico HTTP/1.1" 404 2081
Performing system checks...

System check identified no issues (0 silenced).
April 12, 2019 - 02:26:13
Django version 2.1.8, using settings 'myblog.settings'
Starting development server at http://0.0.0.0:8000/
Quit the server with CONTROL-C.
[12/Apr/2019 13:41:27] "GET /blog/edit/action/ HTTP/1.1" 200 864
[12/Apr/2019 13:41:34] "GET /blog/article/2/ HTTP/1.1" 200 409
[12/Apr/2019 13:41:50] "GET /mooc/show HTTP/1.1" 301 0
[12/Apr/2019 13:41:50] "GET /mooc/show/ HTTP/1.1" 200 168
[12/Apr/2019 13:41:50] "GET /media/img/aa_VmTs3QE.jpg HTTP/1.1" 200 208275
[12/Apr/2019 13:42:07] "GET /admin/ HTTP/1.1" 200 5763
[12/Apr/2019 13:42:07] "GET /static/admin/css/base.css HTTP/1.1" 304 0
[12/Apr/2019 13:42:07] "GET /static/admin/css/dashboard.css HTTP/1.1" 304 0
[12/Apr/2019 13:42:07] "GET /static/admin/css/responsive.css HTTP/1.1" 304 0
[12/Apr/2019 13:42:07] "GET /static/admin/css/fonts.css HTTP/1.1" 304 0
[12/Apr/2019 13:42:07] "GET /static/admin/img/icon-deletelink.svg HTTP/1.1" 304 0
[12/Apr/2019 13:42:07] "GET /static/admin/img/icon-changelink.svg HTTP/1.1" 304 0
[12/Apr/2019 13:42:07] "GET /static/admin/img/icon-addlink.svg HTTP/1.1" 304 0
[12/Apr/2019 13:42:07] "GET /static/admin/fonts/Roboto-Light-webfont.woff HTTP/1.1" 304 0
[12/Apr/2019 13:42:07] "GET /static/admin/fonts/Roboto-Bold-webfont.woff HTTP/1.1" 304 0
[12/Apr/2019 13:42:07] "GET /static/admin/fonts/Roboto-Regular-webfont.woff HTTP/1.1" 304 0
[12/Apr/2019 13:42:09] "GET /admin/mooc/img/ HTTP/1.1" 200 4290
[12/Apr/2019 13:42:09] "GET /admin/jsi18n/ HTTP/1.1" 200 3185
[12/Apr/2019 13:42:09] "GET /static/admin/css/changelists.css HTTP/1.1" 304 0
[12/Apr/2019 13:42:09] "GET /static/admin/js/vendor/jquery/jquery.js HTTP/1.1" 304 0
[12/Apr/2019 13:42:09] "GET /static/admin/js/jquery.init.js HTTP/1.1" 304 0
[12/Apr/2019 13:42:09] "GET /static/admin/js/core.js HTTP/1.1" 304 0
[12/Apr/2019 13:42:09] "GET /static/admin/js/admin/RelatedObjectLookups.js HTTP/1.1" 304 0
[12/Apr/2019 13:42:09] "GET /static/admin/js/actions.js HTTP/1.1" 304 0
[12/Apr/2019 13:42:09] "GET /static/admin/js/prepopulate.js HTTP/1.1" 304 0
[12/Apr/2019 13:42:09] "GET /static/admin/js/vendor/xregexp/xregexp.js HTTP/1.1" 304 0
[12/Apr/2019 13:42:09] "GET /static/admin/js/urlify.js HTTP/1.1" 304 0
[12/Apr/2019 13:42:09] "GET /static/admin/img/tooltag-add.svg HTTP/1.1" 304 0
[12/Apr/2019 13:42:22] "POST /admin/mooc/img/ HTTP/1.1" 200 3298
[12/Apr/2019 13:42:22] "GET /static/admin/js/cancel.js HTTP/1.1" 200 410
[12/Apr/2019 13:42:23] "POST /admin/mooc/img/ HTTP/1.1" 302 0
[12/Apr/2019 13:42:24] "GET /admin/mooc/img/ HTTP/1.1" 200 3259
[12/Apr/2019 13:42:24] "GET /admin/jsi18n/ HTTP/1.1" 200 3185
[12/Apr/2019 13:42:24] "GET /static/admin/img/icon-yes.svg HTTP/1.1" 200 436
[12/Apr/2019 14:04:42] "GET /admin/mooc/img/ HTTP/1.1" 200 3140
[12/Apr/2019 14:04:42] "GET /admin/jsi18n/ HTTP/1.1" 200 3185
[12/Apr/2019 14:04:45] "GET /admin/mooc/ HTTP/1.1" 200 2401
[12/Apr/2019 14:04:47] "GET /admin/ HTTP/1.1" 200 6002
[12/Apr/2019 14:05:56] "GET /admin/mooc/img/ HTTP/1.1" 200 3140
[12/Apr/2019 14:05:56] "GET /admin/jsi18n/ HTTP/1.1" 200 3185
Not Found: /
[12/Apr/2019 16:23:27] "GET / HTTP/1.1" 404 2262
----------------------------------------
Exception happened during processing of request from ('101.251.242.238', 46172)
Traceback (most recent call last):
  File "/usr/local/lib/python3.6/socketserver.py", line 636, in process_request_thread
    self.finish_request(request, client_address)
  File "/usr/local/lib/python3.6/socketserver.py", line 358, in finish_request
    self.RequestHandlerClass(request, client_address, self)
  File "/usr/local/lib/python3.6/socketserver.py", line 692, in __init__
    self.handle()
  File "/usr/local/lib/python3.6/site-packages/django/core/servers/basehttp.py", line 171, in handle
    self.handle_one_request()
  File "/usr/local/lib/python3.6/site-packages/django/core/servers/basehttp.py", line 179, in handle_one_request
    self.raw_requestline = self.rfile.readline(65537)
  File "/usr/local/lib/python3.6/socket.py", line 575, in readinto
    return self._sock.recv_into(b)
ConnectionResetError: [Errno 104] Connection reset by peer
----------------------------------------
Not Found: /http:/www.baidu.com/cache/global/img/gs.gif
[12/Apr/2019 22:28:07] "GET http://www.baidu.com/cache/global/img/gs.gif HTTP/1.1" 404 1738
----------------------------------------
Exception happened during processing of request from ('80.82.70.187', 42766)
Traceback (most recent call last):
  File "/usr/local/lib/python3.6/socketserver.py", line 636, in process_request_thread
    self.finish_request(request, client_address)
  File "/usr/local/lib/python3.6/socketserver.py", line 358, in finish_request
    self.RequestHandlerClass(request, client_address, self)
  File "/usr/local/lib/python3.6/socketserver.py", line 692, in __init__
    self.handle()
  File "/usr/local/lib/python3.6/site-packages/django/core/servers/basehttp.py", line 171, in handle
    self.handle_one_request()
  File "/usr/local/lib/python3.6/site-packages/django/core/servers/basehttp.py", line 179, in handle_one_request
    self.raw_requestline = self.rfile.readline(65537)
  File "/usr/local/lib/python3.6/socket.py", line 575, in readinto
    return self._sock.recv_into(b)
ConnectionResetError: [Errno 104] Connection reset by peer
----------------------------------------
Not Found: /http:/www.qq.com/404/search_children.js
[13/Apr/2019 05:21:13] "GET http://www.qq.com/404/search_children.js HTTP/1.1" 404 1723
----------------------------------------
Exception happened during processing of request from ('120.132.3.65', 55840)
Traceback (most recent call last):
  File "/usr/local/lib/python3.6/socketserver.py", line 636, in process_request_thread
    self.finish_request(request, client_address)
  File "/usr/local/lib/python3.6/socketserver.py", line 358, in finish_request
    self.RequestHandlerClass(request, client_address, self)
  File "/usr/local/lib/python3.6/socketserver.py", line 692, in __init__
    self.handle()
  File "/usr/local/lib/python3.6/site-packages/django/core/servers/basehttp.py", line 171, in handle
    self.handle_one_request()
  File "/usr/local/lib/python3.6/site-packages/django/core/servers/basehttp.py", line 179, in handle_one_request
    self.raw_requestline = self.rfile.readline(65537)
  File "/usr/local/lib/python3.6/socket.py", line 575, in readinto
    return self._sock.recv_into(b)
ConnectionResetError: [Errno 104] Connection reset by peer
----------------------------------------
[13/Apr/2019 05:21:18] code 400, message Bad request syntax ('\x04\x01\x00PpTi4\x00')
[13/Apr/2019 05:21:18] " PpTi4 " 400 -
[13/Apr/2019 05:21:18] code 400, message Bad request syntax ('\x05\x01\x00')
[13/Apr/2019 05:21:18] " " 400 -
[13/Apr/2019 07:30:52] "GET /blog/index/ HTTP/1.1" 200 864
[13/Apr/2019 07:32:04] "GET /blog/article/17/ HTTP/1.1" 200 263
[13/Apr/2019 07:32:13] "GET /blog/article/17/ HTTP/1.1" 200 263
[13/Apr/2019 07:32:22] "GET /blog/article/12/ HTTP/1.1" 200 342
Not Found: /
[13/Apr/2019 08:12:11] "GET / HTTP/1.0" 404 2272
Not Found: /http:/www.baidu.com/cache/global/img/gs.gif
[13/Apr/2019 08:34:56] "GET http://www.baidu.com/cache/global/img/gs.gif HTTP/1.1" 404 1738
----------------------------------------
Exception happened during processing of request from ('80.82.70.187', 52119)
Traceback (most recent call last):
  File "/usr/local/lib/python3.6/socketserver.py", line 636, in process_request_thread
    self.finish_request(request, client_address)
  File "/usr/local/lib/python3.6/socketserver.py", line 358, in finish_request
    self.RequestHandlerClass(request, client_address, self)
  File "/usr/local/lib/python3.6/socketserver.py", line 692, in __init__
    self.handle()
  File "/usr/local/lib/python3.6/site-packages/django/core/servers/basehttp.py", line 171, in handle
    self.handle_one_request()
  File "/usr/local/lib/python3.6/site-packages/django/core/servers/basehttp.py", line 179, in handle_one_request
    self.raw_requestline = self.rfile.readline(65537)
  File "/usr/local/lib/python3.6/socket.py", line 575, in readinto
    return self._sock.recv_into(b)
ConnectionResetError: [Errno 104] Connection reset by peer
----------------------------------------
[13/Apr/2019 09:47:04] code 400, message Bad HTTP/0.9 request type ('service')
[13/Apr/2019 09:47:04] "service launcher" 400 -
Not Found: /
[13/Apr/2019 09:47:05] "GET / HTTP/1.0" 404 2272
Not Found: /
[13/Apr/2019 09:47:05] "GET / HTTP/1.0" 404 2262
Not Found: /
[13/Apr/2019 09:47:06] "GET / HTTP/1.1" 404 2262
Not Found: /
[13/Apr/2019 10:56:46] "GET / HTTP/1.1" 404 2262
----------------------------------------
Exception happened during processing of request from ('198.108.67.48', 8122)
Traceback (most recent call last):
  File "/usr/local/lib/python3.6/socketserver.py", line 636, in process_request_thread
    self.finish_request(request, client_address)
  File "/usr/local/lib/python3.6/socketserver.py", line 358, in finish_request
    self.RequestHandlerClass(request, client_address, self)
  File "/usr/local/lib/python3.6/socketserver.py", line 692, in __init__
    self.handle()
  File "/usr/local/lib/python3.6/site-packages/django/core/servers/basehttp.py", line 171, in handle
    self.handle_one_request()
  File "/usr/local/lib/python3.6/site-packages/django/core/servers/basehttp.py", line 179, in handle_one_request
    self.raw_requestline = self.rfile.readline(65537)
  File "/usr/local/lib/python3.6/socket.py", line 575, in readinto
    return self._sock.recv_into(b)
ConnectionResetError: [Errno 104] Connection reset by peer
----------------------------------------
[13/Apr/2019 15:14:04] code 400, message Bad request syntax ('\x01\x00\x00\x00\x01\x00\x00\x00\x08\x08')
[13/Apr/2019 15:14:04] "      " 400 -
Not Found: /http:/www.baidu.com/cache/global/img/gs.gif
[13/Apr/2019 18:42:07] "GET http://www.baidu.com/cache/global/img/gs.gif HTTP/1.1" 404 1738
----------------------------------------
Exception happened during processing of request from ('80.82.70.187', 50355)
Traceback (most recent call last):
  File "/usr/local/lib/python3.6/socketserver.py", line 636, in process_request_thread
    self.finish_request(request, client_address)
  File "/usr/local/lib/python3.6/socketserver.py", line 358, in finish_request
    self.RequestHandlerClass(request, client_address, self)
  File "/usr/local/lib/python3.6/socketserver.py", line 692, in __init__
    self.handle()
  File "/usr/local/lib/python3.6/site-packages/django/core/servers/basehttp.py", line 171, in handle
    self.handle_one_request()
  File "/usr/local/lib/python3.6/site-packages/django/core/servers/basehttp.py", line 179, in handle_one_request
    self.raw_requestline = self.rfile.readline(65537)
  File "/usr/local/lib/python3.6/socket.py", line 575, in readinto
    return self._sock.recv_into(b)
ConnectionResetError: [Errno 104] Connection reset by peer
----------------------------------------
Not Found: /
[14/Apr/2019 04:11:50] "GET / HTTP/1.1" 404 2262
[14/Apr/2019 04:31:55] "GET /blog/index/ HTTP/1.1" 200 864
Not Found: /favicon.ico
[14/Apr/2019 04:31:55] "GET /favicon.ico HTTP/1.1" 404 2313
[14/Apr/2019 04:32:06] "GET /blog/article/2/ HTTP/1.1" 200 409
[14/Apr/2019 04:32:09] "GET /blog/edit/delete/2/ HTTP/1.1" 200 750
[14/Apr/2019 04:32:11] "GET /blog/edit/delete/3/ HTTP/1.1" 200 636
[14/Apr/2019 04:32:12] "GET /blog/article/17/ HTTP/1.1" 200 263
[14/Apr/2019 04:32:16] "GET /blog/edit/ HTTP/1.1" 200 552
Not Found: /http:/www.baidu.com/cache/global/img/gs.gif
[14/Apr/2019 04:41:47] "GET http://www.baidu.com/cache/global/img/gs.gif HTTP/1.1" 404 1738
----------------------------------------
Exception happened during processing of request from ('80.82.70.187', 39375)
Traceback (most recent call last):
  File "/usr/local/lib/python3.6/socketserver.py", line 636, in process_request_thread
    self.finish_request(request, client_address)
  File "/usr/local/lib/python3.6/socketserver.py", line 358, in finish_request
    self.RequestHandlerClass(request, client_address, self)
  File "/usr/local/lib/python3.6/socketserver.py", line 692, in __init__
    self.handle()
  File "/usr/local/lib/python3.6/site-packages/django/core/servers/basehttp.py", line 171, in handle
    self.handle_one_request()
  File "/usr/local/lib/python3.6/site-packages/django/core/servers/basehttp.py", line 179, in handle_one_request
    self.raw_requestline = self.rfile.readline(65537)
  File "/usr/local/lib/python3.6/socket.py", line 575, in readinto
    return self._sock.recv_into(b)
ConnectionResetError: [Errno 104] Connection reset by peer
----------------------------------------
Not Found: /
[14/Apr/2019 10:54:55] "GET / HTTP/1.1" 404 2257
Not Found: /favicon.ico
[14/Apr/2019 10:54:59] "GET /favicon.ico HTTP/1.1" 404 2313
[14/Apr/2019 14:06:36] "GET /blog/index/ HTTP/1.1" 200 636
Not Found: /favicon.ico
[14/Apr/2019 14:06:37] "GET /favicon.ico HTTP/1.1" 404 2313
[14/Apr/2019 14:06:40] "GET /blog/article/12/ HTTP/1.1" 200 342
[14/Apr/2019 14:06:45] "GET /blog/index/ HTTP/1.1" 200 636
[14/Apr/2019 14:06:46] "GET /blog/edit/ HTTP/1.1" 200 552
Not Found: /http:/www.baidu.com/cache/global/img/gs.gif
[14/Apr/2019 14:47:37] "GET http://www.baidu.com/cache/global/img/gs.gif HTTP/1.1" 404 1738
----------------------------------------
Exception happened during processing of request from ('80.82.70.187', 55346)
Traceback (most recent call last):
  File "/usr/local/lib/python3.6/socketserver.py", line 636, in process_request_thread
    self.finish_request(request, client_address)
  File "/usr/local/lib/python3.6/socketserver.py", line 358, in finish_request
    self.RequestHandlerClass(request, client_address, self)
  File "/usr/local/lib/python3.6/socketserver.py", line 692, in __init__
    self.handle()
  File "/usr/local/lib/python3.6/site-packages/django/core/servers/basehttp.py", line 171, in handle
    self.handle_one_request()
  File "/usr/local/lib/python3.6/site-packages/django/core/servers/basehttp.py", line 179, in handle_one_request
    self.raw_requestline = self.rfile.readline(65537)
  File "/usr/local/lib/python3.6/socket.py", line 575, in readinto
    return self._sock.recv_into(b)
ConnectionResetError: [Errno 104] Connection reset by peer
----------------------------------------
Not Found: /
[14/Apr/2019 15:18:19] "GET / HTTP/1.0" 404 2272
[14/Apr/2019 15:18:21] code 400, message Bad HTTP/0.9 request type ('l\x00')
[14/Apr/2019 15:18:21] "l          " 400 -
[2019-04-14 15:18:21,711] - Broken pipe from ('45.79.13.120', 34700)

Not Found: /nice ports,/Trinity.txt.bak
[14/Apr/2019 15:18:22] "GET /nice%20ports%2C/Tri%6Eity.txt%2ebak HTTP/1.0" 404 2373
[14/Apr/2019 15:18:23] code 400, message Bad request syntax ('\x05\x04\x00\x01\x02\x80\x05\x01\x00\x03')
[14/Apr/2019 15:18:23] "  " 400 -
[14/Apr/2019 15:18:25] code 400, message Bad request syntax ('\x04\x01\x00\x16\x7f\x00\x00\x01root\x00')
[14/Apr/2019 15:18:25] "   root " 400 -
[2019-04-14 15:18:25,470] - Broken pipe from ('45.79.13.120', 37248)

[14/Apr/2019 15:18:25] code 400, message Bad request syntax ('#ST')
[14/Apr/2019 15:18:25] "#ST" 400 -
[14/Apr/2019 15:18:27] code 400, message Bad HTTP/0.9 request type ('\x00')
[14/Apr/2019 15:18:27] " n    beio" 400 -
[2019-04-14 15:18:27,817] - Broken pipe from ('45.79.13.120', 38898)

[14/Apr/2019 15:18:29] code 400, message Bad request syntax ('\x00\x00\x07\x00\x08\x00\x03\x00\x04\x00\x05\x00\x06')
[14/Apr/2019 15:18:29] "       " 400 -
[2019-04-14 15:18:29,587] - Broken pipe from ('45.79.13.120', 40082)

Not Found: /
[14/Apr/2019 15:18:29] "OPTIONS / HTTP/1.0" 404 2276
[14/Apr/2019 15:18:30] code 400, message Bad request version ('RTSP/1.0')
[14/Apr/2019 15:18:30] "OPTIONS / RTSP/1.0" 400 -
----------------------------------------
Exception happened during processing of request from ('45.79.13.120', 42060)
Traceback (most recent call last):
  File "/usr/local/lib/python3.6/socketserver.py", line 636, in process_request_thread
    self.finish_request(request, client_address)
  File "/usr/local/lib/python3.6/socketserver.py", line 358, in finish_request
    self.RequestHandlerClass(request, client_address, self)
  File "/usr/local/lib/python3.6/socketserver.py", line 692, in __init__
    self.handle()
  File "/usr/local/lib/python3.6/site-packages/django/core/servers/basehttp.py", line 169, in handle
    self.handle_one_request()
  File "/usr/local/lib/python3.6/site-packages/django/core/servers/basehttp.py", line 179, in handle_one_request
    self.raw_requestline = self.rfile.readline(65537)
  File "/usr/local/lib/python3.6/socket.py", line 575, in readinto
    return self._sock.recv_into(b)
ConnectionResetError: [Errno 104] Connection reset by peer
----------------------------------------
[14/Apr/2019 15:18:34] code 400, message Bad HTTP/0.9 request type ('\x00')
[14/Apr/2019 15:18:34] "          versionbind   " 400 -
[2019-04-14 15:18:34,392] - Broken pipe from ('45.79.13.120', 43188)

[14/Apr/2019 15:18:36] code 400, message Bad HTTP/0.9 request type ('\x00')
[14/Apr/2019 15:18:36] "            " 400 -
[2019-04-14 15:18:36,233] - Broken pipe from ('45.79.13.120', 44396)

[14/Apr/2019 15:18:36] code 400, message Bad request syntax ('HELP')
[14/Apr/2019 15:18:36] "HELP" 400 -
[14/Apr/2019 15:18:37] code 400, message Bad request syntax ('\x16\x03\x00\x00S\x01\x00\x00O\x03\x00?G×÷º,îê²`~ó\x00ý\x82{¹Õ\x96Èw\x9bæÄÛ<=Ûoï\x10n\x00\x00(\x00\x16\x00\x13\x00')
[14/Apr/2019 15:18:37] You're accessing the development server over HTTPS, but it only supports HTTP.

[14/Apr/2019 15:18:38] code 400, message Bad HTTP/0.9 request type ('\x03\x00\x00*%à\x00\x00\x00\x00\x00Cookie:')
[14/Apr/2019 15:18:38] "  *%à     Cookie: mstshash=beio" 400 -
[14/Apr/2019 15:18:38] code 400, message Bad request version ('\x00/\x00')
[14/Apr/2019 15:18:38] You're accessing the development server over HTTPS, but it only supports HTTP.

[14/Apr/2019 15:18:40] code 400, message Bad request syntax ('\x00\x00\x00qj\x81n0\x81k¡\x03\x02\x01\x05¢\x03\x02\x01')
[14/Apr/2019 15:18:40] "   qjn0k¡¢" 400 -
[14/Apr/2019 15:18:42] code 400, message Bad request syntax ('\x00\x00\x00¤ÿSMBr\x00\x00\x00\x00\x08\x01@\x00\x00\x00\x00\x00\x00\x00\x00\x00\x00\x00\x00\x00\x00@\x06\x00\x00\x01\x00\x00\x81\x00\x02PC NETWORK PROGRAM 1.0\x00\x02MICROSOFT NETWORKS 1.03\x00\x02MICROSOFT NETWORKS 3.0\x00\x02LANMAN1.0\x00\x02LM1.2X002\x00\x02Samba\x00\x02NT LANMAN 1.0\x00\x02NT LM 0.12\x00')
[14/Apr/2019 15:18:42] "   ¤ÿSMBr    @              @     PC NETWORK PROGRAM 1.0 MICROSOFT NETWORKS 1.03 MICROSOFT NETWORKS 3.0 LANMAN1.0 LM1.2X002 Samba NT LANMAN 1.0 NT LM 0.12 " 400 -
[2019-04-14 15:18:42,081] - Broken pipe from ('45.79.13.120', 49068)

[14/Apr/2019 15:18:42] code 400, message Bad request syntax ('\x01default')
[14/Apr/2019 15:18:42] "default" 400 -
[14/Apr/2019 15:18:43] code 400, message Bad request syntax ('0\x84\x00\x00\x00-\x02\x01\x07c\x84\x00\x00\x00$\x04\x00')
[14/Apr/2019 15:18:43] "0   -c   $ " 400 -
[14/Apr/2019 15:18:45] code 400, message Bad HTTP/0.9 request type ('0')
[14/Apr/2019 15:18:45] "0`  " 400 -
[2019-04-14 15:18:45,105] - Broken pipe from ('45.79.13.120', 51974)

[14/Apr/2019 15:18:45] code 400, message Bad request version ('SIP/2.0')
[14/Apr/2019 15:18:45] "OPTIONS sip:nm SIP/2.0" 400 -
[14/Apr/2019 15:18:47] code 400, message Bad request syntax ('TNMP\x04\x00\x00\x00TNME\x00\x00\x04\x00')
[14/Apr/2019 15:18:47] "TNMP   TNME   " 400 -
[2019-04-14 15:18:47,505] - Broken pipe from ('45.79.13.120', 54084)

[14/Apr/2019 15:18:49] code 400, message Bad HTTP/0.9 request type ('\x03\x00\x00')
[14/Apr/2019 15:18:49] "  à     " 400 -
[2019-04-14 15:18:49,378] - Broken pipe from ('45.79.13.120', 55714)

[14/Apr/2019 15:18:51] code 400, message Bad request syntax ('DmdT\x00\x00\x00\x17\x00\x00\x00\x01\x00\x00\x00\x00\x11\x11\x00ÿ\x01ÿ\x13')
[14/Apr/2019 15:18:51] "DmdT           ÿÿ" 400 -
[2019-04-14 15:18:51,156] - Broken pipe from ('45.79.13.120', 57336)

[14/Apr/2019 15:18:52] code 400, message Bad HTTP/0.9 request type (':\x00\x00\x00/\x00\x00\x00\x02\x00\x00@\x02\x0f\x00\x01\x00=\x05\x00\x00\x00\x00\x00\x00\x00\x00\x00\x00\x00\x00/\x00\x00\x00\x00\x00\x00\x00\x00\x00@')
[14/Apr/2019 15:18:52] ":   /     @  =            /         @                 " 400 -
[14/Apr/2019 15:18:54] code 400, message Bad request syntax ('JRMI\x00\x02K')
[14/Apr/2019 15:18:54] "JRMI K" 400 -
[2019-04-14 15:18:54,791] - Broken pipe from ('45.79.13.120', 60452)

[14/Apr/2019 15:18:56] code 400, message Bad request syntax ('\x01\x00\x00ýÎú\x0b°\xa0\x00\x00\x00MMS\x14\x00\x00\x00\x00\x00\x00\x00\x00\x00\x00\x00\x00\x00\x00\x00\x12\x00\x00\x00\x01\x00\x03\x00ðððð\x0b\x00\x04\x00\x1c\x00\x03\x00N\x00S\x00P\x00l\x00a\x00y\x00e\x00r\x00/\x009\x00.\x00\x00.\x00\x00.\x02\x009\x008\x00\x00;\x00 \x00{\x00\x00\x00\x00\x00A\x00A\x00\x00\x00-\x00\x00A\x00\x00\x00-\x00\x00\x00a\x00\x00-\x00A\x00A\x00\x00A\x00-\x00\x00\x00\x00\x00A\x00\x00A\x00A\x00\x00A\x00A\x00\x00}\x00\x00\x00àmß_')
[14/Apr/2019 15:18:56] "  ýÎú°    MMS                    ðððð    N S P l a y e r / 9 .  .  . 9 8  ;   {     A A   -  A   -   a  - A A  A -     A  A A  A A  }   àmß_" 400 -
[2019-04-14 15:18:56,527] - Broken pipe from ('45.79.13.120', 33760)

[14/Apr/2019 15:18:58] code 400, message Bad HTTP/0.9 request type ('\x00Z\x00\x00\x01\x00\x00\x00\x016\x01,\x00\x00\x08\x00\x7fÿ\x7f\x08\x00\x00\x00\x01\x00')
[14/Apr/2019 15:18:58] " Z     6,   ÿ      :               æ           (CONNECT_DATA=(COMMAND=version))" 400 -
[2019-04-14 15:18:58,302] - Broken pipe from ('45.79.13.120', 35176)

----------------------------------------
Exception happened during processing of request from ('45.79.13.120', 36576)
Traceback (most recent call last):
  File "/usr/local/lib/python3.6/socketserver.py", line 636, in process_request_thread
    self.finish_request(request, client_address)
  File "/usr/local/lib/python3.6/socketserver.py", line 358, in finish_request
    self.RequestHandlerClass(request, client_address, self)
  File "/usr/local/lib/python3.6/socketserver.py", line 692, in __init__
    self.handle()
  File "/usr/local/lib/python3.6/site-packages/django/core/servers/basehttp.py", line 169, in handle
    self.handle_one_request()
  File "/usr/local/lib/python3.6/site-packages/django/core/servers/basehttp.py", line 179, in handle_one_request
    self.raw_requestline = self.rfile.readline(65537)
  File "/usr/local/lib/python3.6/socket.py", line 575, in readinto
    return self._sock.recv_into(b)
ConnectionResetError: [Errno 104] Connection reset by peer
----------------------------------------
[14/Apr/2019 15:19:01] code 400, message Bad request syntax ('\x00\x03\x00\x01\x00\x00\x00\x00\x00\x00\x00\x02\x00\x00\x00\x00\x0f\x00')
[14/Apr/2019 15:19:01] "              " 400 -
[2019-04-14 15:19:01,951] - Broken pipe from ('45.79.13.120', 37886)

[14/Apr/2019 15:19:03] code 400, message Bad request syntax ('GIOP\x01\x00\x01\x00$\x00\x00\x00\x00\x00\x00\x00\x01\x00\x00\x00\x01\x00\x00\x00\x06\x00\x00\x00abcdef\x00\x00\x04\x00\x00\x00get\x00\x00\x00\x00\x00')
[14/Apr/2019 15:19:03] "GIOP  $                abcdef     get     " 400 -
[2019-04-14 15:19:03,769] - Broken pipe from ('45.79.13.120', 39190)

[14/Apr/2019 15:19:06] code 400, message Bad request syntax ('\x00\x9c\x00\x01\x1a+<M\x00\x01\x00\x00\x01\x00\x00\x00\x00\x00\x00\x01\x00\x00\x00\x01ÿÿ\x00\x01none\x00\x00\x00\x00\x00\x00\x00\x00\x00\x00\x00\x00\x00\x00\x00\x00\x00\x00\x00\x00\x00\x00\x00\x00\x00\x00\x00\x00\x00\x00\x00\x00\x00\x00\x00\x00\x00\x00\x00\x00\x00\x00\x00\x00\x00\x00\x00\x00\x00\x00\x00\x00\x00\x00\x00\x00\x00\x00\x00\x00beio\x00\x00\x00\x00\x00\x00\x00\x00\x00\x00\x00\x00\x00\x00\x00\x00\x00\x00\x00\x00\x00\x00\x00\x00\x00\x00\x00\x00\x00\x00\x00\x00\x00\x00\x00\x00\x00\x00\x00\x00\x00\x00\x00\x00\x00\x00\x00\x00\x00\x00\x00\x00\x00\x00\x00\x00\x00\x00\x00\x00')
[14/Apr/2019 15:19:06] "  +<M            ÿÿ none                                                            beio                                                            " 400 -
[2019-04-14 15:19:06,577] - Broken pipe from ('45.79.13.120', 40460)

[14/Apr/2019 15:19:09] code 400, message Bad request syntax ('\x00\x00\x00\x01\x00\x00\x00\x01\x00\x00\x00\x04\x00\x00\x00\x08\x00\x00\x00\x01\x00\x00\x00\x00')
[14/Apr/2019 15:19:09] "                   " 400 -
[2019-04-14 15:19:09,416] - Broken pipe from ('45.79.13.120', 42282)

[14/Apr/2019 15:19:11] code 400, message Bad request syntax ('\x03\x81\x00\x00\x00\x00\x00_@\x00\x017\x00\x00\x00\x00\x00\x00\x00\x01\x00\x01\x00\x00\x00\x00\x00\x01\x00\x00\x00\x01\x00\x00\x00\x00\x00\x00\x00\x00\x00\x00\x00\x00\x00\x00\x00\x00InitiatorName=iqn.1991-05.com.microsoft:beio-iscsi-probe\x00SessionType=Discovery\x00AuthMethod=None\x00\x00')
[14/Apr/2019 15:19:11] "     _@ 7                                InitiatorName=iqn.1991-05.com.microsoft:beio-iscsi-probe SessionType=Discovery AuthMethod=None  " 400 -
[2019-04-14 15:19:11,168] - Broken pipe from ('45.79.13.120', 44154)

[14/Apr/2019 15:19:12] code 400, message Bad request syntax ('\x01\x00\x00\x00\x00Í\x00\x01\x00\x00ANY-SCP\x00\x00\x00\x00\x00\x00\x00\x00\x00FINDSCU\x00\x00\x00\x00\x00\x00\x00\x00\x00\x00\x00\x00\x00\x00\x00\x00\x00\x00\x00\x00\x00\x00\x00\x00\x00\x00\x00\x00\x00\x00\x00\x00\x00\x00\x00\x00\x00\x00\x00\x00\x00\x10\x00\x00\x151.2.840.10008.3.1.1.1 \x00\x00.\x01\x00\x00\x000\x00\x00\x111.2.840.10008.1.1@\x00\x00\x111.2.840.10008.1.2P\x00\x00:Q\x00\x00\x04\x00\x00@\x00R\x00\x00\x1e1.2.826.0.1.3680043.2.1396.999U\x00\x00\x0cCharruaVista')
[14/Apr/2019 15:19:12] "    Í   ANY-SCP         FINDSCU                                           1.2.840.10008.3.1.1.1   .   0  1.2.840.10008.1.1@  1.2.840.10008.1.2P  :Q    @ R  1.2.826.0.1.3680043.2.1396.999U  CharruaVista" 400 -
----------------------------------------
Exception happened during processing of request from ('159.203.169.16', 51081)
Traceback (most recent call last):
  File "/usr/local/lib/python3.6/socketserver.py", line 636, in process_request_thread
    self.finish_request(request, client_address)
  File "/usr/local/lib/python3.6/socketserver.py", line 358, in finish_request
    self.RequestHandlerClass(request, client_address, self)
  File "/usr/local/lib/python3.6/socketserver.py", line 692, in __init__
    self.handle()
  File "/usr/local/lib/python3.6/site-packages/django/core/servers/basehttp.py", line 169, in handle
    self.handle_one_request()
  File "/usr/local/lib/python3.6/site-packages/django/core/servers/basehttp.py", line 179, in handle_one_request
    self.raw_requestline = self.rfile.readline(65537)
  File "/usr/local/lib/python3.6/socket.py", line 575, in readinto
    return self._sock.recv_into(b)
ConnectionResetError: [Errno 104] Connection reset by peer
----------------------------------------
Not Found: /
[14/Apr/2019 22:44:45] "GET / HTTP/1.1" 404 2263
Not Found: /http:/www.baidu.com/cache/global/img/gs.gif
[15/Apr/2019 00:54:47] "GET http://www.baidu.com/cache/global/img/gs.gif HTTP/1.1" 404 1738
----------------------------------------
Exception happened during processing of request from ('80.82.70.187', 38872)
Traceback (most recent call last):
  File "/usr/local/lib/python3.6/socketserver.py", line 636, in process_request_thread
    self.finish_request(request, client_address)
  File "/usr/local/lib/python3.6/socketserver.py", line 358, in finish_request
    self.RequestHandlerClass(request, client_address, self)
  File "/usr/local/lib/python3.6/socketserver.py", line 692, in __init__
    self.handle()
  File "/usr/local/lib/python3.6/site-packages/django/core/servers/basehttp.py", line 171, in handle
    self.handle_one_request()
  File "/usr/local/lib/python3.6/site-packages/django/core/servers/basehttp.py", line 179, in handle_one_request
    self.raw_requestline = self.rfile.readline(65537)
  File "/usr/local/lib/python3.6/socket.py", line 575, in readinto
    return self._sock.recv_into(b)
ConnectionResetError: [Errno 104] Connection reset by peer
----------------------------------------
[15/Apr/2019 01:37:56] "GET /blog/index HTTP/1.1" 301 0
[15/Apr/2019 01:37:56] "GET /blog/index/ HTTP/1.1" 200 636
Not Found: /favicon.ico
[15/Apr/2019 01:37:56] "GET /favicon.ico HTTP/1.1" 404 2313
[15/Apr/2019 01:38:06] "GET /blog/article/12/ HTTP/1.1" 200 342
Not Found: /favicon.ico
[15/Apr/2019 01:38:06] "GET /favicon.ico HTTP/1.1" 404 2313
[15/Apr/2019 01:38:13] "GET /blog/article/17/ HTTP/1.1" 200 263
Not Found: /favicon.ico
[15/Apr/2019 01:38:13] "GET /favicon.ico HTTP/1.1" 404 2313
[15/Apr/2019 01:39:05] "GET /mooc/show HTTP/1.1" 301 0
[15/Apr/2019 01:39:05] "GET /mooc/show/ HTTP/1.1" 200 123
Not Found: /favicon.ico
[15/Apr/2019 01:39:05] "GET /favicon.ico HTTP/1.1" 404 2313
[15/Apr/2019 02:04:03] "GET /blog/index/ HTTP/1.1" 200 650
Not Found: /favicon.ico
[15/Apr/2019 02:04:03] "GET /favicon.ico HTTP/1.1" 404 2313
[15/Apr/2019 02:04:07] "GET /blog/index/ HTTP/1.1" 200 650
[15/Apr/2019 02:05:05] "GET /blog/edit/ HTTP/1.1" 200 552
[15/Apr/2019 02:07:05] "POST /blog/edit/action/ HTTP/1.1" 200 782
[15/Apr/2019 02:07:07] "GET /blog/article/18/ HTTP/1.1" 200 394
[15/Apr/2019 02:07:09] "GET /blog/edit/tocha/18/ HTTP/1.1" 200 698
[15/Apr/2019 02:07:16] "GET /blog/index/ HTTP/1.1" 200 782
[15/Apr/2019 02:07:18] "GET /blog/article/17/ HTTP/1.1" 200 263
[15/Apr/2019 02:07:21] "GET /blog/edit/ HTTP/1.1" 200 552
[15/Apr/2019 02:13:04] "GET /blog/index/ HTTP/1.1" 200 884
[15/Apr/2019 02:16:01] "GET /blog/index/ HTTP/1.1" 200 899
[15/Apr/2019 02:16:05] "GET /blog/article/18/ HTTP/1.1" 200 394
[15/Apr/2019 02:16:07] "GET /blog/edit/tocha/18/ HTTP/1.1" 200 698
[15/Apr/2019 02:16:09] "POST /blog/edit/change/18/ HTTP/1.1" 200 899
[15/Apr/2019 02:16:11] "GET /blog/edit/ HTTP/1.1" 200 552
[15/Apr/2019 02:18:02] "POST /blog/edit/action/ HTTP/1.1" 200 1027
[15/Apr/2019 02:18:03] "GET /blog/article/19/ HTTP/1.1" 200 412
[15/Apr/2019 02:29:59] "GET /blog/article/19/ HTTP/1.1" 200 412
[15/Apr/2019 02:30:03] "GET /blog/article/19/ HTTP/1.1" 200 412
[15/Apr/2019 02:30:10] "GET /blog/edit/tocha/19/ HTTP/1.1" 200 716
Not Found: /
[15/Apr/2019 03:44:42] "GET / HTTP/1.1" 404 2262
----------------------------------------
Exception happened during processing of request from ('198.108.67.48', 34940)
Traceback (most recent call last):
  File "/usr/local/lib/python3.6/socketserver.py", line 636, in process_request_thread
    self.finish_request(request, client_address)
  File "/usr/local/lib/python3.6/socketserver.py", line 358, in finish_request
    self.RequestHandlerClass(request, client_address, self)
  File "/usr/local/lib/python3.6/socketserver.py", line 692, in __init__
    self.handle()
  File "/usr/local/lib/python3.6/site-packages/django/core/servers/basehttp.py", line 171, in handle
    self.handle_one_request()
  File "/usr/local/lib/python3.6/site-packages/django/core/servers/basehttp.py", line 179, in handle_one_request
    self.raw_requestline = self.rfile.readline(65537)
  File "/usr/local/lib/python3.6/socket.py", line 575, in readinto
    return self._sock.recv_into(b)
ConnectionResetError: [Errno 104] Connection reset by peer
----------------------------------------
[15/Apr/2019 04:29:36] "GET /blog/index/ HTTP/1.1" 200 1027
Not Found: /favicon.ico
[15/Apr/2019 04:29:37] "GET /favicon.ico HTTP/1.1" 404 2313
[15/Apr/2019 04:29:38] "GET /blog/article/12/ HTTP/1.1" 200 342
Not Found: /favicon.ico
[15/Apr/2019 04:29:38] "GET /favicon.ico HTTP/1.1" 404 2313
[15/Apr/2019 04:29:41] "GET /blog/article/17/ HTTP/1.1" 200 263
[15/Apr/2019 04:29:43] "GET /blog/article/18/ HTTP/1.1" 200 394
[15/Apr/2019 04:29:44] "GET /blog/article/19/ HTTP/1.1" 200 412
[15/Apr/2019 05:56:49] "POST /blog/edit/action/ HTTP/1.1" 200 1155
[15/Apr/2019 05:56:53] "GET /blog/article/20/ HTTP/1.1" 200 412
[15/Apr/2019 05:56:58] "GET /blog/index/ HTTP/1.1" 200 1155
[15/Apr/2019 05:57:06] "GET /blog/index/ HTTP/1.1" 200 1155
[15/Apr/2019 05:57:09] "GET /blog/article/19/ HTTP/1.1" 200 412
[15/Apr/2019 05:57:11] "GET /blog/index/ HTTP/1.1" 200 1155
[15/Apr/2019 05:57:14] "GET /blog/article/18/ HTTP/1.1" 200 394
[15/Apr/2019 06:53:53] "GET /blog/index/ HTTP/1.1" 200 1155
Unhandled exception in thread started by <function check_errors.<locals>.wrapper at 0x7f343052e488>
Traceback (most recent call last):
  File "/usr/local/lib/python3.6/site-packages/django/utils/autoreload.py", line 225, in wrapper
    fn(*args, **kwargs)
  File "/usr/local/lib/python3.6/site-packages/django/core/management/commands/runserver.py", line 117, in inner_run
    self.check(display_num_errors=True)
  File "/usr/local/lib/python3.6/site-packages/django/core/management/base.py", line 425, in check
    raise SystemCheckError(msg)
django.core.management.base.SystemCheckError: SystemCheckError: System check identified some issues:

ERRORS:
mooc.Img.img: (fields.E210) Cannot use ImageField because Pillow is not installed.
	HINT: Get Pillow at https://pypi.org/project/Pillow/ or run command "pip install Pillow".

System check identified 1 issue (0 silenced).
Performing system checks...

Performing system checks...

System check identified no issues (0 silenced).
April 12, 2019 - 13:41:17
Django version 2.1.8, using settings 'myblog.settings'
Starting development server at http://0.0.0.0:8000/
Quit the server with CONTROL-C.
<class 'mooc.models.Img'>
/media/img/aa_VmTs3QE.jpg
[15/Apr/2019 08:45:38] "GET /mooc/upload HTTP/1.1" 301 0
[15/Apr/2019 08:45:38] "GET /mooc/upload/ HTTP/1.1" 200 569
[15/Apr/2019 08:45:54] "GET /blog/index/ HTTP/1.1" 200 1230
[15/Apr/2019 08:45:56] "GET /mooc/upload/ HTTP/1.1" 200 569
Internal Server Error: /mooc/upload/
Traceback (most recent call last):
  File "/usr/local/lib/python3.7/site-packages/django/core/handlers/exception.py", line 34, in inner
    response = get_response(request)
  File "/usr/local/lib/python3.7/site-packages/django/core/handlers/base.py", line 126, in _get_response
    response = self.process_exception_by_middleware(e, request)
  File "/usr/local/lib/python3.7/site-packages/django/core/handlers/base.py", line 124, in _get_response
    response = wrapped_callback(request, *callback_args, **callback_kwargs)
  File "/home/django/myblog/mooc/views.py", line 24, in uploadImg
    picture_change(path2)
  File "/home/django/myblog/mooc/views.py", line 40, in picture_change
    im = Image.open(pictureUrl).convert('L')
  File "/usr/local/lib/python3.7/site-packages/PIL/Image.py", line 2652, in open
    fp = builtins.open(filename, "rb")
FileNotFoundError: [Errno 2] No such file or directory: '/home/django/myblog\\media\\img\\aa.jpg'
[15/Apr/2019 08:46:06] "POST /mooc/upload/ HTTP/1.1" 500 73182
Performing system checks...

System check identified no issues (0 silenced).
April 15, 2019 - 08:45:36
Django version 2.1.8, using settings 'myblog.settings'
Starting development server at http://0.0.0.0:8000/
Quit the server with CONTROL-C.
Unhandled exception in thread started by <function check_errors.<locals>.wrapper at 0x7fd0dd995488>
Traceback (most recent call last):
  File "/usr/local/lib/python3.6/site-packages/django/utils/autoreload.py", line 225, in wrapper
    fn(*args, **kwargs)
  File "/usr/local/lib/python3.6/site-packages/django/core/management/commands/runserver.py", line 117, in inner_run
    self.check(display_num_errors=True)
  File "/usr/local/lib/python3.6/site-packages/django/core/management/base.py", line 379, in check
    include_deployment_checks=include_deployment_checks,
  File "/usr/local/lib/python3.6/site-packages/django/core/management/base.py", line 366, in _run_checks
    return checks.run_checks(**kwargs)
  File "/usr/local/lib/python3.6/site-packages/django/core/checks/registry.py", line 71, in run_checks
    new_errors = check(app_configs=app_configs)
  File "/usr/local/lib/python3.6/site-packages/django/core/checks/urls.py", line 13, in check_url_config
    return check_resolver(resolver)
  File "/usr/local/lib/python3.6/site-packages/django/core/checks/urls.py", line 23, in check_resolver
    return check_method()
  File "/usr/local/lib/python3.6/site-packages/django/urls/resolvers.py", line 396, in check
    for pattern in self.url_patterns:
  File "/usr/local/lib/python3.6/site-packages/django/utils/functional.py", line 37, in __get__
    res = instance.__dict__[self.name] = self.func(instance)
  File "/usr/local/lib/python3.6/site-packages/django/urls/resolvers.py", line 533, in url_patterns
    patterns = getattr(self.urlconf_module, "urlpatterns", self.urlconf_module)
  File "/usr/local/lib/python3.6/site-packages/django/utils/functional.py", line 37, in __get__
    res = instance.__dict__[self.name] = self.func(instance)
  File "/usr/local/lib/python3.6/site-packages/django/urls/resolvers.py", line 526, in urlconf_module
    return import_module(self.urlconf_name)
  File "/usr/local/lib/python3.6/importlib/__init__.py", line 126, in import_module
    return _bootstrap._gcd_import(name[level:], package, level)
  File "<frozen importlib._bootstrap>", line 996, in _gcd_import
  File "<frozen importlib._bootstrap>", line 979, in _find_and_load
  File "<frozen importlib._bootstrap>", line 968, in _find_and_load_unlocked
  File "<frozen importlib._bootstrap>", line 673, in _load_unlocked
  File "<frozen importlib._bootstrap_external>", line 659, in exec_module
  File "<frozen importlib._bootstrap>", line 222, in _call_with_frames_removed
  File "/home/django/myblog/myblog/urls.py", line 26, in <module>
    path('mooc/',include(('mooc.urls','mooc'),namespace='mooc')),
  File "/usr/local/lib/python3.6/site-packages/django/urls/conf.py", line 34, in include
    urlconf_module = import_module(urlconf_module)
  File "/usr/local/lib/python3.6/importlib/__init__.py", line 126, in import_module
    return _bootstrap._gcd_import(name[level:], package, level)
  File "<frozen importlib._bootstrap>", line 996, in _gcd_import
  File "<frozen importlib._bootstrap>", line 979, in _find_and_load
  File "<frozen importlib._bootstrap>", line 968, in _find_and_load_unlocked
  File "<frozen importlib._bootstrap>", line 673, in _load_unlocked
  File "<frozen importlib._bootstrap_external>", line 659, in exec_module
  File "<frozen importlib._bootstrap>", line 222, in _call_with_frames_removed
  File "/home/django/myblog/mooc/urls.py", line 3, in <module>
    from . import views
  File "/home/django/myblog/mooc/views.py", line 3, in <module>
    import numpy as np
ImportError: No module named 'numpy'
Performing system checks...

[15/Apr/2019 08:47:31] "POST /mooc/upload/ HTTP/1.1" 200 569
[15/Apr/2019 08:47:39] "POST /mooc/upload/ HTTP/1.1" 200 569
[15/Apr/2019 08:47:41] "GET /mooc/show/ HTTP/1.1" 200 250
[15/Apr/2019 08:47:41] "GET /media/img/aa.jpg HTTP/1.1" 200 208275
[15/Apr/2019 08:47:41] "GET /media/img/aa_PMkgQSq.jpg HTTP/1.1" 200 281366
[15/Apr/2019 08:47:42] "GET /media/img/aa_9BaGAjy.jpg HTTP/1.1" 200 281366
Not Found: /index/
[15/Apr/2019 08:47:57] "GET /index/ HTTP/1.1" 404 2297
[15/Apr/2019 08:48:05] "GET /admin HTTP/1.1" 301 0
[15/Apr/2019 08:48:05] "GET /admin/ HTTP/1.1" 302 0
[15/Apr/2019 08:48:05] "GET /admin/login/?next=/admin/ HTTP/1.1" 200 1819
[15/Apr/2019 08:48:05] "GET /static/admin/css/login.css HTTP/1.1" 200 1203
[15/Apr/2019 08:48:05] "GET /static/admin/css/base.css HTTP/1.1" 200 16225
[15/Apr/2019 08:48:05] "GET /static/admin/css/responsive.css HTTP/1.1" 200 17976
[15/Apr/2019 08:48:06] "GET /static/admin/css/fonts.css HTTP/1.1" 200 423
[15/Apr/2019 08:48:06] "GET /static/admin/fonts/Roboto-Regular-webfont.woff HTTP/1.1" 200 80304
[15/Apr/2019 08:48:06] "GET /static/admin/fonts/Roboto-Light-webfont.woff HTTP/1.1" 200 81348
[15/Apr/2019 08:48:13] "POST /admin/login/?next=/admin/ HTTP/1.1" 302 0
[15/Apr/2019 08:48:14] "GET /admin/ HTTP/1.1" 200 6002
[15/Apr/2019 08:48:14] "GET /static/admin/css/dashboard.css HTTP/1.1" 200 412
[15/Apr/2019 08:48:14] "GET /static/admin/img/icon-addlink.svg HTTP/1.1" 200 331
[15/Apr/2019 08:48:14] "GET /static/admin/img/icon-changelink.svg HTTP/1.1" 200 380
[15/Apr/2019 08:48:14] "GET /static/admin/img/icon-deletelink.svg HTTP/1.1" 200 392
[15/Apr/2019 08:48:14] "GET /static/admin/fonts/Roboto-Bold-webfont.woff HTTP/1.1" 200 82564
[15/Apr/2019 08:48:15] "GET /admin/mooc/img/ HTTP/1.1" 200 4719
[15/Apr/2019 08:48:15] "GET /static/admin/css/changelists.css HTTP/1.1" 200 6170
[15/Apr/2019 08:48:15] "GET /admin/jsi18n/ HTTP/1.1" 200 3185
[15/Apr/2019 08:48:15] "GET /static/admin/js/vendor/jquery/jquery.js HTTP/1.1" 200 271751
[15/Apr/2019 08:48:15] "GET /static/admin/js/jquery.init.js HTTP/1.1" 200 363
[15/Apr/2019 08:48:15] "GET /static/admin/js/core.js HTTP/1.1" 200 7135
[15/Apr/2019 08:48:15] "GET /static/admin/js/admin/RelatedObjectLookups.js HTTP/1.1" 200 6918
[15/Apr/2019 08:48:16] "GET /static/admin/js/urlify.js HTTP/1.1" 200 8972
[15/Apr/2019 08:48:16] "GET /static/admin/js/actions.js HTTP/1.1" 200 6538
[15/Apr/2019 08:48:16] "GET /static/admin/js/prepopulate.js HTTP/1.1" 200 1530
[15/Apr/2019 08:48:16] "GET /static/admin/js/vendor/xregexp/xregexp.js HTTP/1.1" 200 128820
[15/Apr/2019 08:48:16] "GET /static/admin/img/tooltag-add.svg HTTP/1.1" 200 331
[15/Apr/2019 08:48:22] "POST /admin/mooc/img/ HTTP/1.1" 200 3553
[15/Apr/2019 08:48:22] "GET /static/admin/js/cancel.js HTTP/1.1" 200 410
[15/Apr/2019 08:48:23] "POST /admin/mooc/img/ HTTP/1.1" 302 0
[15/Apr/2019 08:48:24] "GET /admin/mooc/img/ HTTP/1.1" 200 3260
[15/Apr/2019 08:48:24] "GET /admin/jsi18n/ HTTP/1.1" 200 3185
[15/Apr/2019 08:48:24] "GET /static/admin/img/icon-yes.svg HTTP/1.1" 200 436
[15/Apr/2019 08:49:22] "GET /mooc/upload/ HTTP/1.1" 200 569
[15/Apr/2019 08:50:01] "GET /blog/edit/ HTTP/1.1" 200 552
[15/Apr/2019 08:51:27] "POST /blog/edit/action/ HTTP/1.1" 200 1382
[15/Apr/2019 08:51:29] "GET /blog/article/21/ HTTP/1.1" 200 374
[15/Apr/2019 08:51:39] "GET /blog/article/20/ HTTP/1.1" 200 412
[15/Apr/2019 08:51:42] "GET /blog/index/ HTTP/1.1" 200 1382
[15/Apr/2019 08:51:48] "GET /admin/mooc/ HTTP/1.1" 200 2401
[15/Apr/2019 08:51:48] "GET /static/admin/css/base.css HTTP/1.1" 304 0
[15/Apr/2019 08:51:48] "GET /static/admin/css/responsive.css HTTP/1.1" 304 0
[15/Apr/2019 08:51:48] "GET /static/admin/css/dashboard.css HTTP/1.1" 304 0
[15/Apr/2019 08:51:48] "GET /static/admin/css/fonts.css HTTP/1.1" 304 0
[15/Apr/2019 08:51:49] "GET /static/admin/img/icon-changelink.svg HTTP/1.1" 304 0
[15/Apr/2019 08:51:49] "GET /static/admin/img/icon-addlink.svg HTTP/1.1" 304 0
[15/Apr/2019 08:51:49] "GET /static/admin/fonts/Roboto-Light-webfont.woff HTTP/1.1" 304 0
[15/Apr/2019 08:51:49] "GET /static/admin/fonts/Roboto-Bold-webfont.woff HTTP/1.1" 304 0
[15/Apr/2019 08:51:49] "GET /static/admin/fonts/Roboto-Regular-webfont.woff HTTP/1.1" 304 0
[15/Apr/2019 08:51:51] "GET /admin/ HTTP/1.1" 200 6719
[15/Apr/2019 08:51:51] "GET /static/admin/img/icon-deletelink.svg HTTP/1.1" 304 0
[15/Apr/2019 08:51:54] "GET /admin/blog/article/ HTTP/1.1" 200 5520
[15/Apr/2019 08:51:54] "GET /admin/jsi18n/ HTTP/1.1" 200 3185
[15/Apr/2019 08:51:54] "GET /static/admin/css/changelists.css HTTP/1.1" 304 0
[15/Apr/2019 08:51:54] "GET /static/admin/js/jquery.init.js HTTP/1.1" 304 0
[15/Apr/2019 08:51:54] "GET /static/admin/js/vendor/jquery/jquery.js HTTP/1.1" 304 0
[15/Apr/2019 08:51:54] "GET /static/admin/js/core.js HTTP/1.1" 304 0
[15/Apr/2019 08:51:54] "GET /static/admin/js/admin/RelatedObjectLookups.js HTTP/1.1" 304 0
[15/Apr/2019 08:51:54] "GET /static/admin/js/actions.js HTTP/1.1" 304 0
[15/Apr/2019 08:51:54] "GET /static/admin/js/urlify.js HTTP/1.1" 304 0
[15/Apr/2019 08:51:54] "GET /static/admin/js/prepopulate.js HTTP/1.1" 304 0
[15/Apr/2019 08:51:54] "GET /static/admin/js/vendor/xregexp/xregexp.js HTTP/1.1" 304 0
[15/Apr/2019 08:51:54] "GET /static/admin/img/tooltag-add.svg HTTP/1.1" 304 0
[15/Apr/2019 08:51:59] "POST /admin/blog/article/ HTTP/1.1" 200 3340
[15/Apr/2019 08:52:00] "GET /static/admin/js/cancel.js HTTP/1.1" 304 0
[15/Apr/2019 08:52:01] "POST /admin/blog/article/ HTTP/1.1" 302 0
[15/Apr/2019 08:52:01] "GET /admin/blog/article/ HTTP/1.1" 200 5411
[15/Apr/2019 08:52:01] "GET /admin/jsi18n/ HTTP/1.1" 200 3185
[15/Apr/2019 08:52:01] "GET /static/admin/img/icon-yes.svg HTTP/1.1" 304 0
[15/Apr/2019 08:52:09] "GET /blog/index/ HTTP/1.1" 200 1254
[15/Apr/2019 09:18:06] "GET /mooc/upload/ HTTP/1.1" 200 569
[15/Apr/2019 09:18:16] "POST /mooc/upload/ HTTP/1.1" 200 569
[15/Apr/2019 09:18:17] "GET /mooc/show/ HTTP/1.1" 200 160
[15/Apr/2019 09:18:18] "GET /media/img/aa.jpg HTTP/1.1" 200 281366
[15/Apr/2019 09:18:21] "GET /mooc/show/ HTTP/1.1" 200 160
[15/Apr/2019 09:18:21] "GET /media/img/aa.jpg HTTP/1.1" 304 0
[15/Apr/2019 09:19:00] "GET /mooc/show/ HTTP/1.1" 200 160
[15/Apr/2019 09:19:00] "GET /media/img/aa.jpg HTTP/1.1" 304 0
[15/Apr/2019 09:19:28] "GET /mooc/show/ HTTP/1.1" 200 160
[15/Apr/2019 09:19:29] "GET /media/img/aa.jpg HTTP/1.1" 304 0
[15/Apr/2019 09:19:33] "GET /mooc/show/ HTTP/1.1" 200 160
[15/Apr/2019 09:19:35] "GET /mooc/show/ HTTP/1.1" 200 160
[15/Apr/2019 09:19:35] "GET /media/img/aa.jpg HTTP/1.1" 304 0
[15/Apr/2019 09:19:45] "GET /mooc/show/ HTTP/1.1" 200 160
[15/Apr/2019 09:19:45] "GET /media/img/aa.jpg HTTP/1.1" 304 0
[15/Apr/2019 09:19:48] "GET /mooc/show/ HTTP/1.1" 200 160
[15/Apr/2019 09:19:49] "GET /mooc/show/ HTTP/1.1" 200 160
[15/Apr/2019 09:19:49] "GET /mooc/show/ HTTP/1.1" 200 160
Performing system checks...

System check identified no issues (0 silenced).
April 15, 2019 - 08:47:27
Django version 2.1.8, using settings 'myblog.settings'
Starting development server at http://0.0.0.0:8000/
Quit the server with CONTROL-C.
[15/Apr/2019 09:33:18] "GET /blog/index/ HTTP/1.1" 200 1254
[15/Apr/2019 09:33:20] "GET /mooc/upload/ HTTP/1.1" 200 569
[15/Apr/2019 09:33:21] "GET /mooc/show/ HTTP/1.1" 200 211
[15/Apr/2019 09:33:22] "GET /media/img/aa.jpg HTTP/1.1" 304 0
[15/Apr/2019 09:33:24] "GET /mooc/delete/5/ HTTP/1.1" 200 123
Internal Server Error: /mooc/delete/5/
Traceback (most recent call last):
  File "/usr/local/lib/python3.7/site-packages/django/core/handlers/exception.py", line 34, in inner
    response = get_response(request)
  File "/usr/local/lib/python3.7/site-packages/django/core/handlers/base.py", line 126, in _get_response
    response = self.process_exception_by_middleware(e, request)
  File "/usr/local/lib/python3.7/site-packages/django/core/handlers/base.py", line 124, in _get_response
    response = wrapped_callback(request, *callback_args, **callback_kwargs)
  File "/home/django/myblog/mooc/views.py", line 37, in delete
    picture = models.Img.objects.get(pk = img_id)
  File "/usr/local/lib/python3.7/site-packages/django/db/models/manager.py", line 82, in manager_method
    return getattr(self.get_queryset(), name)(*args, **kwargs)
  File "/usr/local/lib/python3.7/site-packages/django/db/models/query.py", line 399, in get
    self.model._meta.object_name
mooc.models.Img.DoesNotExist: Img matching query does not exist.
[15/Apr/2019 09:33:25] "GET /mooc/delete/5/ HTTP/1.1" 500 71656
[15/Apr/2019 09:33:28] "GET /mooc/show/ HTTP/1.1" 200 123
[15/Apr/2019 09:34:12] "POST /mooc/upload/ HTTP/1.1" 200 569
[15/Apr/2019 09:34:14] "GET /mooc/show/ HTTP/1.1" 200 211
[15/Apr/2019 09:34:41] "GET /mooc/delete/6/ HTTP/1.1" 200 123
[15/Apr/2019 09:34:48] "GET /blog/article/21/ HTTP/1.1" 200 374
[15/Apr/2019 09:34:50] "GET /blog/edit/tocha/21/ HTTP/1.1" 200 678
[15/Apr/2019 09:35:37] "POST /blog/edit/change/21/ HTTP/1.1" 200 1254
[15/Apr/2019 09:35:40] "GET /blog/article/21/ HTTP/1.1" 200 411
[15/Apr/2019 09:35:44] "GET /blog/index/ HTTP/1.1" 200 1254
[15/Apr/2019 09:40:07] "GET /mooc/upload/ HTTP/1.1" 200 569
[15/Apr/2019 09:40:21] "POST /mooc/upload/ HTTP/1.1" 200 569
[15/Apr/2019 09:40:22] "GET /mooc/show/ HTTP/1.1" 200 211
[15/Apr/2019 09:40:22] "GET /media/img/aa.jpg HTTP/1.1" 200 281366
/usr/local/lib/python3.7/site-packages/PIL/Image.py:965: UserWarning: Palette images with Transparency   expressed in bytes should be converted to RGBA images
  ' expressed in bytes should be converted ' +
[15/Apr/2019 09:40:39] "POST /mooc/upload/ HTTP/1.1" 200 569
[15/Apr/2019 09:40:41] "GET /mooc/show/ HTTP/1.1" 200 309
[15/Apr/2019 09:40:41] "GET /media/img/aa.jpg HTTP/1.1" 304 0
[15/Apr/2019 09:40:41] "GET /media/img/PYG03-flower.png HTTP/1.1" 200 5069
[15/Apr/2019 09:40:45] "GET /mooc/delete/8/ HTTP/1.1" 200 211
[15/Apr/2019 09:40:45] "GET /media/img/aa.jpg HTTP/1.1" 304 0
[15/Apr/2019 09:41:17] "GET /mooc/delete/7/ HTTP/1.1" 200 123
[15/Apr/2019 09:46:21] "GET /mooc/show/ HTTP/1.1" 200 238
[15/Apr/2019 09:46:25] "GET /blog/index/ HTTP/1.1" 200 1254
[15/Apr/2019 09:46:26] "GET /mooc/upload/ HTTP/1.1" 200 569
[15/Apr/2019 09:46:27] "GET /mooc/show/ HTTP/1.1" 200 238
[15/Apr/2019 09:46:35] "GET /blog/index/ HTTP/1.1" 200 1254
[15/Apr/2019 09:48:17] "GET /mooc/upload/ HTTP/1.1" 200 569
[15/Apr/2019 09:48:18] "GET /mooc/show/ HTTP/1.1" 200 238
[15/Apr/2019 09:48:42] "GET /admin/ HTTP/1.1" 200 6974
[15/Apr/2019 09:48:42] "GET /static/admin/css/base.css HTTP/1.1" 304 0
[15/Apr/2019 09:48:42] "GET /static/admin/css/dashboard.css HTTP/1.1" 304 0
[15/Apr/2019 09:48:42] "GET /static/admin/css/responsive.css HTTP/1.1" 304 0
[15/Apr/2019 09:48:43] "GET /static/admin/css/fonts.css HTTP/1.1" 304 0
[15/Apr/2019 09:48:43] "GET /static/admin/img/icon-addlink.svg HTTP/1.1" 304 0
[15/Apr/2019 09:48:43] "GET /static/admin/img/icon-changelink.svg HTTP/1.1" 304 0
[15/Apr/2019 09:48:43] "GET /static/admin/img/icon-deletelink.svg HTTP/1.1" 304 0
[15/Apr/2019 09:48:43] "GET /static/admin/fonts/Roboto-Light-webfont.woff HTTP/1.1" 304 0
[15/Apr/2019 09:48:43] "GET /static/admin/fonts/Roboto-Bold-webfont.woff HTTP/1.1" 304 0
[15/Apr/2019 09:48:43] "GET /static/admin/fonts/Roboto-Regular-webfont.woff HTTP/1.1" 304 0
[15/Apr/2019 09:48:45] "GET /admin/mooc/img/ HTTP/1.1" 200 3140
[15/Apr/2019 09:48:45] "GET /static/admin/css/changelists.css HTTP/1.1" 304 0
[15/Apr/2019 09:48:45] "GET /static/admin/js/core.js HTTP/1.1" 304 0
[15/Apr/2019 09:48:45] "GET /static/admin/js/jquery.init.js HTTP/1.1" 304 0
[15/Apr/2019 09:48:45] "GET /static/admin/js/vendor/jquery/jquery.js HTTP/1.1" 304 0
[15/Apr/2019 09:48:45] "GET /static/admin/js/admin/RelatedObjectLookups.js HTTP/1.1" 304 0
[15/Apr/2019 09:48:45] "GET /admin/jsi18n/ HTTP/1.1" 200 3185
[15/Apr/2019 09:48:45] "GET /static/admin/js/actions.js HTTP/1.1" 304 0
[15/Apr/2019 09:48:45] "GET /static/admin/js/urlify.js HTTP/1.1" 304 0
[15/Apr/2019 09:48:45] "GET /static/admin/js/prepopulate.js HTTP/1.1" 304 0
[15/Apr/2019 09:48:45] "GET /static/admin/js/vendor/xregexp/xregexp.js HTTP/1.1" 304 0
[15/Apr/2019 09:48:46] "GET /static/admin/img/tooltag-add.svg HTTP/1.1" 304 0
[15/Apr/2019 09:48:48] "GET /admin/mooc/img/ HTTP/1.1" 200 3140
[15/Apr/2019 09:48:48] "GET /admin/jsi18n/ HTTP/1.1" 200 3185
[15/Apr/2019 09:48:49] "GET /admin/mooc/img/ HTTP/1.1" 200 3140
[15/Apr/2019 09:48:49] "GET /admin/jsi18n/ HTTP/1.1" 200 3185
Internal Server Error: /mooc/delete/6/
Traceback (most recent call last):
  File "/usr/local/lib/python3.7/site-packages/django/core/handlers/exception.py", line 34, in inner
    response = get_response(request)
  File "/usr/local/lib/python3.7/site-packages/django/core/handlers/base.py", line 126, in _get_response
    response = self.process_exception_by_middleware(e, request)
  File "/usr/local/lib/python3.7/site-packages/django/core/handlers/base.py", line 124, in _get_response
    response = wrapped_callback(request, *callback_args, **callback_kwargs)
  File "/home/django/myblog/mooc/views.py", line 37, in delete
    picture = models.Img.objects.get(pk = img_id)
  File "/usr/local/lib/python3.7/site-packages/django/db/models/manager.py", line 82, in manager_method
    return getattr(self.get_queryset(), name)(*args, **kwargs)
  File "/usr/local/lib/python3.7/site-packages/django/db/models/query.py", line 399, in get
    self.model._meta.object_name
mooc.models.Img.DoesNotExist: Img matching query does not exist.
[15/Apr/2019 10:00:01] "GET /mooc/delete/6/ HTTP/1.1" 500 71656
[15/Apr/2019 10:00:24] "GET /blog/index/ HTTP/1.1" 200 1254
[15/Apr/2019 10:00:25] "GET /mooc/upload/ HTTP/1.1" 200 569
[15/Apr/2019 10:00:27] "GET /mooc/show/ HTTP/1.1" 200 238
[15/Apr/2019 10:00:29] "GET /mooc/show/ HTTP/1.1" 200 238
[15/Apr/2019 10:00:29] "GET /mooc/show/ HTTP/1.1" 200 238
[15/Apr/2019 10:11:17] "GET /blog/index/?nsukey=eD59p8Oikn9Y7yWWyU5nHtpjliKsdbYlVtmupBYG6WRFkNa5xzxTxFFGMf5sK12r3xnKuh0CzUbIeJ8brbaygbW1t5apkKmHShfitU1hUupldRLkaR5VMyZ25i3yAGZf8dFJCZRU0R2YI77Dqb3t7oyZW5eFlYtZ%2Btcy7gVDcV5XY%2FN%2BMvZXlnIByl4MR7VUIUKMUClfMEM4vPxQfnKCIg%3D%3D HTTP/1.1" 200 1254
[15/Apr/2019 10:11:19] "GET /mooc/upload/ HTTP/1.1" 200 569
[15/Apr/2019 10:11:21] "GET /mooc/upload/?nsukey=l%2F1kcZ%2Fwdxh%2FAFrLjX87J36pbGZ%2FuVALbhtnLVPxs%2FSuaIH9h%2BQ8UP%2FGu0z88pI4Ex7SpjcCnXl9Cz5fCcyeQg8Yflc2rvWFMbjdC7DsuqaTBByMnm6AyHiXo3Ooplm26SWv9aHmVTVgOWUvkPa1aDaOS%2Bqt0fFs71lg7SOnsAGEk2s4ppEYoy68e7rTItRixKulIPauhffEYn0ndngSuA%3D%3D HTTP/1.1" 200 569
[15/Apr/2019 10:11:35] "POST /mooc/upload/?nsukey=l%2F1kcZ%2Fwdxh%2FAFrLjX87J36pbGZ%2FuVALbhtnLVPxs%2FSuaIH9h%2BQ8UP%2FGu0z88pI4Ex7SpjcCnXl9Cz5fCcyeQg8Yflc2rvWFMbjdC7DsuqaTBByMnm6AyHiXo3Ooplm26SWv9aHmVTVgOWUvkPa1aDaOS%2Bqt0fFs71lg7SOnsAGEk2s4ppEYoy68e7rTItRixKulIPauhffEYn0ndngSuA%3D%3D HTTP/1.1" 200 569
[15/Apr/2019 10:11:39] "GET /mooc/show/ HTTP/1.1" 200 361
[15/Apr/2019 10:11:39] "GET /media/img/E08EA3E2-A48C-462C-91C6-25E5975A5A24.jpeg HTTP/1.1" 200 574879
[15/Apr/2019 10:11:46] "GET /mooc/delete/9/ HTTP/1.1" 200 238
[15/Apr/2019 10:11:49] "GET /blog/index/ HTTP/1.1" 200 1254
[15/Apr/2019 10:11:51] "GET /mooc/upload/ HTTP/1.1" 200 569
[15/Apr/2019 10:12:16] "GET /blog/index HTTP/1.1" 301 0
[15/Apr/2019 10:12:17] "GET /blog/index/?nsukey=eD59p8Oikn9Y7yWWyU5nHtpjliKsdbYlVtmupBYG6WRFkNa5xzxTxFFGMf5sK12r3xnKuh0CzUbIeJ8brbaygbW1t5apkKmHShfitU1hUupldRLkaR5VMyZ25i3yAGZf8dFJCZRU0R2YI77Dqb3t7oyZW5eFlYtZ%2Btcy7gVDcV5XY%2FN%2BMvZXlnIByl4MR7VUIUKMUClfMEM4vPxQfnKCIg%3D%3D HTTP/1.1" 200 1254
[15/Apr/2019 10:12:20] "GET /mooc/upload HTTP/1.1" 301 0
[15/Apr/2019 10:12:21] "GET /mooc/upload/?nsukey=l%2F1kcZ%2Fwdxh%2FAFrLjX87J36pbGZ%2FuVALbhtnLVPxs%2FSuaIH9h%2BQ8UP%2FGu0z88pI4Ex7SpjcCnXl9Cz5fCcyeQg8Yflc2rvWFMbjdC7DsuqaTBByMnm6AyHiXo3Ooplm26SWv9aHmVTVgOWUvkPa1aDaOS%2Bqt0fFs71lg7SOnsAGEk2s4ppEYoy68e7rTItRixKulIPauhffEYn0ndngSuA%3D%3D HTTP/1.1" 200 569
[15/Apr/2019 10:12:38] "GET /mooc/show HTTP/1.1" 301 0
[15/Apr/2019 10:12:46] "GET /mooc/delete/9 HTTP/1.1" 301 0
Internal Server Error: /mooc/delete/9/
Traceback (most recent call last):
  File "/usr/local/lib/python3.7/site-packages/django/core/handlers/exception.py", line 34, in inner
    response = get_response(request)
  File "/usr/local/lib/python3.7/site-packages/django/core/handlers/base.py", line 126, in _get_response
    response = self.process_exception_by_middleware(e, request)
  File "/usr/local/lib/python3.7/site-packages/django/core/handlers/base.py", line 124, in _get_response
    response = wrapped_callback(request, *callback_args, **callback_kwargs)
  File "/home/django/myblog/mooc/views.py", line 37, in delete
    picture = models.Img.objects.get(pk = img_id)
  File "/usr/local/lib/python3.7/site-packages/django/db/models/manager.py", line 82, in manager_method
    return getattr(self.get_queryset(), name)(*args, **kwargs)
  File "/usr/local/lib/python3.7/site-packages/django/db/models/query.py", line 399, in get
    self.model._meta.object_name
mooc.models.Img.DoesNotExist: Img matching query does not exist.
[15/Apr/2019 10:12:47] "GET /mooc/delete/9/ HTTP/1.1" 500 70320
[15/Apr/2019 10:47:56] "GET /mooc/show HTTP/1.1" 301 0
[15/Apr/2019 10:47:56] "GET /mooc/show/ HTTP/1.1" 200 238
Not Found: /favicon.ico
[15/Apr/2019 10:47:57] "GET /favicon.ico HTTP/1.1" 404 2312
[15/Apr/2019 10:47:58] "GET /blog/index/ HTTP/1.1" 200 1254
Not Found: /favicon.ico
[15/Apr/2019 10:47:58] "GET /favicon.ico HTTP/1.1" 404 2312
[15/Apr/2019 10:48:00] "GET /mooc/upload/ HTTP/1.1" 200 569
Not Found: /favicon.ico
[15/Apr/2019 10:48:01] "GET /favicon.ico HTTP/1.1" 404 2312
[15/Apr/2019 10:48:26] "POST /mooc/upload/ HTTP/1.1" 200 569
Not Found: /favicon.ico
[15/Apr/2019 10:48:26] "GET /favicon.ico HTTP/1.1" 404 2312
[15/Apr/2019 10:48:27] "GET /mooc/show/ HTTP/1.1" 200 361
[15/Apr/2019 10:48:28] "GET /media/img/61999182-A1D6-4431-A4E5-079A0EB8769A.png HTTP/1.1" 200 502232
Not Found: /favicon.ico
[15/Apr/2019 10:48:29] "GET /favicon.ico HTTP/1.1" 404 2312
Not Found: /favicon.ico
[15/Apr/2019 10:48:46] "GET /favicon.ico HTTP/1.1" 404 2312
[15/Apr/2019 10:48:48] "GET /mooc/show/ HTTP/1.1" 200 361
Not Found: /favicon.ico
[15/Apr/2019 10:48:48] "GET /favicon.ico HTTP/1.1" 404 2312
Not Found: /favicon.ico
[15/Apr/2019 10:48:49] "GET /favicon.ico HTTP/1.1" 404 2312
Not Found: /favicon.ico
[15/Apr/2019 10:48:50] "GET /favicon.ico HTTP/1.1" 404 2312
Not Found: /favicon.ico
[15/Apr/2019 10:48:52] "GET /favicon.ico HTTP/1.1" 404 2312
[15/Apr/2019 10:48:54] "GET /blog/article/21/ HTTP/1.1" 200 411
Not Found: /favicon.ico
[15/Apr/2019 10:48:54] "GET /favicon.ico HTTP/1.1" 404 2312
Not Found: /favicon.ico
[15/Apr/2019 10:49:01] "GET /favicon.ico HTTP/1.1" 404 2312
[15/Apr/2019 10:49:03] "GET /blog/article/18/ HTTP/1.1" 200 394
Not Found: /favicon.ico
[15/Apr/2019 10:49:04] "GET /favicon.ico HTTP/1.1" 404 2312
Not Found: /favicon.ico
[15/Apr/2019 10:49:11] "GET /favicon.ico HTTP/1.1" 404 2312
Not Found: /favicon.ico
[15/Apr/2019 10:49:26] "GET /favicon.ico HTTP/1.1" 404 2312
Not Found: /favicon.ico
[15/Apr/2019 10:49:29] "GET /favicon.ico HTTP/1.1" 404 2312
[15/Apr/2019 10:49:35] "GET /blog/article/12/ HTTP/1.1" 200 342
Not Found: /favicon.ico
[15/Apr/2019 10:49:36] "GET /favicon.ico HTTP/1.1" 404 2312
Not Found: /favicon.ico
[15/Apr/2019 10:49:39] "GET /favicon.ico HTTP/1.1" 404 2312
Not Found: /favicon.ico
[15/Apr/2019 10:49:41] "GET /favicon.ico HTTP/1.1" 404 2312
[15/Apr/2019 10:49:42] "GET /mooc/upload/ HTTP/1.1" 200 569
Not Found: /favicon.ico
[15/Apr/2019 10:49:43] "GET /favicon.ico HTTP/1.1" 404 2312
[15/Apr/2019 10:49:45] "GET /mooc/show/ HTTP/1.1" 200 361
Not Found: /favicon.ico
[15/Apr/2019 10:49:45] "GET /favicon.ico HTTP/1.1" 404 2312
[15/Apr/2019 10:50:39] "GET /blog/index/ HTTP/1.1" 200 1254
Not Found: /favicon.ico
[15/Apr/2019 10:50:39] "GET /favicon.ico HTTP/1.1" 404 2312
[15/Apr/2019 10:50:40] "GET /mooc/upload/ HTTP/1.1" 200 569
Not Found: /favicon.ico
[15/Apr/2019 10:50:41] "GET /favicon.ico HTTP/1.1" 404 2312
[15/Apr/2019 10:50:57] "POST /mooc/upload/ HTTP/1.1" 200 569
Not Found: /favicon.ico
[15/Apr/2019 10:50:58] "GET /favicon.ico HTTP/1.1" 404 2312
[15/Apr/2019 10:51:01] "GET /mooc/show/ HTTP/1.1" 200 485
[15/Apr/2019 10:51:02] "GET /media/img/1719A373-970E-4D85-92A4-1AA4B298BAAB.jpeg HTTP/1.1" 200 2847847
[15/Apr/2019 10:51:06] "GET /mooc/delete/10/ HTTP/1.1" 200 362
Not Found: /favicon.ico
[15/Apr/2019 10:51:06] "GET /favicon.ico HTTP/1.1" 404 2312
Not Found: /favicon.ico
[15/Apr/2019 10:51:09] "GET /favicon.ico HTTP/1.1" 404 2312
[15/Apr/2019 10:51:09] "GET /blog/index/ HTTP/1.1" 200 1254
Not Found: /favicon.ico
[15/Apr/2019 10:51:09] "GET /favicon.ico HTTP/1.1" 404 2312
[15/Apr/2019 10:51:11] "GET /mooc/upload/ HTTP/1.1" 200 569
Not Found: /favicon.ico
[15/Apr/2019 10:51:11] "GET /favicon.ico HTTP/1.1" 404 2312
[15/Apr/2019 10:51:12] "GET /mooc/show/ HTTP/1.1" 200 362
Not Found: /favicon.ico
[15/Apr/2019 10:51:13] "GET /favicon.ico HTTP/1.1" 404 2312
Not Found: /http:/www.baidu.com/cache/global/img/gs.gif
[15/Apr/2019 11:01:35] "GET http://www.baidu.com/cache/global/img/gs.gif HTTP/1.1" 404 1738
----------------------------------------
Exception happened during processing of request from ('80.82.70.187', 35352)
Traceback (most recent call last):
  File "/usr/local/lib/python3.7/socketserver.py", line 647, in process_request_thread
    self.finish_request(request, client_address)
  File "/usr/local/lib/python3.7/socketserver.py", line 357, in finish_request
    self.RequestHandlerClass(request, client_address, self)
  File "/usr/local/lib/python3.7/socketserver.py", line 717, in __init__
    self.handle()
  File "/usr/local/lib/python3.7/site-packages/django/core/servers/basehttp.py", line 171, in handle
    self.handle_one_request()
  File "/usr/local/lib/python3.7/site-packages/django/core/servers/basehttp.py", line 179, in handle_one_request
    self.raw_requestline = self.rfile.readline(65537)
  File "/usr/local/lib/python3.7/socket.py", line 589, in readinto
    return self._sock.recv_into(b)
ConnectionResetError: [Errno 104] Connection reset by peer
----------------------------------------
Not Found: /http:/www.baidu.com/cache/global/img/gs.gif
[15/Apr/2019 21:06:18] "GET http://www.baidu.com/cache/global/img/gs.gif HTTP/1.1" 404 1738
----------------------------------------
Exception happened during processing of request from ('80.82.70.187', 50339)
Traceback (most recent call last):
  File "/usr/local/lib/python3.7/socketserver.py", line 647, in process_request_thread
    self.finish_request(request, client_address)
  File "/usr/local/lib/python3.7/socketserver.py", line 357, in finish_request
    self.RequestHandlerClass(request, client_address, self)
  File "/usr/local/lib/python3.7/socketserver.py", line 717, in __init__
    self.handle()
  File "/usr/local/lib/python3.7/site-packages/django/core/servers/basehttp.py", line 171, in handle
    self.handle_one_request()
  File "/usr/local/lib/python3.7/site-packages/django/core/servers/basehttp.py", line 179, in handle_one_request
    self.raw_requestline = self.rfile.readline(65537)
  File "/usr/local/lib/python3.7/socket.py", line 589, in readinto
    return self._sock.recv_into(b)
ConnectionResetError: [Errno 104] Connection reset by peer
----------------------------------------
[15/Apr/2019 23:52:07] "GET /mooc/show HTTP/1.1" 301 0
[15/Apr/2019 23:52:07] "GET /mooc/show/ HTTP/1.1" 200 362
[15/Apr/2019 23:52:07] "GET /media/img/1719A373-970E-4D85-92A4-1AA4B298BAAB.jpeg HTTP/1.1" 200 2847847
[15/Apr/2019 23:52:11] "GET /blog/index/ HTTP/1.1" 200 1254
Not Found: /favicon.ico
[15/Apr/2019 23:52:11] "GET /favicon.ico HTTP/1.1" 404 2312
[15/Apr/2019 23:52:22] "GET /blog/article/18/ HTTP/1.1" 200 394
Not Found: /favicon.ico
[15/Apr/2019 23:52:22] "GET /favicon.ico HTTP/1.1" 404 2312
Not Found: /favicon.ico
[15/Apr/2019 23:52:34] "GET /favicon.ico HTTP/1.1" 404 2312
[15/Apr/2019 23:52:37] "GET /mooc/upload/ HTTP/1.1" 200 569
Not Found: /favicon.ico
[15/Apr/2019 23:52:37] "GET /favicon.ico HTTP/1.1" 404 2312
[15/Apr/2019 23:52:39] "GET /mooc/show/ HTTP/1.1" 200 362
[15/Apr/2019 23:52:39] "GET /media/img/1719A373-970E-4D85-92A4-1AA4B298BAAB.jpeg HTTP/1.1" 304 0
Not Found: /favicon.ico
[15/Apr/2019 23:52:39] "GET /favicon.ico HTTP/1.1" 404 2312
[15/Apr/2019 23:52:43] "GET /mooc/delete/11/ HTTP/1.1" 200 238
Not Found: /favicon.ico
[15/Apr/2019 23:52:43] "GET /favicon.ico HTTP/1.1" 404 2312
[15/Apr/2019 23:52:45] "GET /blog/index/ HTTP/1.1" 200 1254
Not Found: /favicon.ico
[15/Apr/2019 23:52:45] "GET /favicon.ico HTTP/1.1" 404 2312
[15/Apr/2019 23:52:47] "GET /mooc/upload/ HTTP/1.1" 200 569
Not Found: /favicon.ico
[15/Apr/2019 23:52:47] "GET /favicon.ico HTTP/1.1" 404 2312
[15/Apr/2019 23:52:49] "GET /mooc/show/ HTTP/1.1" 200 238
Not Found: /favicon.ico
[15/Apr/2019 23:52:49] "GET /favicon.ico HTTP/1.1" 404 2312
Not Found: /favicon.ico
[15/Apr/2019 23:52:50] "GET /favicon.ico HTTP/1.1" 404 2312
Not Found: /favicon.ico
[15/Apr/2019 23:52:50] "GET /favicon.ico HTTP/1.1" 404 2312
Not Found: /favicon.ico
[15/Apr/2019 23:52:57] "GET /favicon.ico HTTP/1.1" 404 2312
[16/Apr/2019 01:34:55] "GET /blog/index/ HTTP/1.1" 200 1254
Not Found: /http:/www.bing.com/
[16/Apr/2019 04:18:33] "GET http://www.bing.com/ HTTP/1.1" 404 1665
Not Found: /http:/www.boxun.com/
[16/Apr/2019 04:18:33] "GET http://www.boxun.com/ HTTP/1.1" 404 1669
Not Found: /http:/www.123cha.com/
[16/Apr/2019 04:18:33] "GET http://www.123cha.com/ HTTP/1.1" 404 1673
Not Found: /http:/www.baidu.com/
[16/Apr/2019 04:18:33] "GET http://www.baidu.com/ HTTP/1.1" 404 1669
Not Found: /http:/www.rfa.org/
[16/Apr/2019 04:18:36] "GET http://www.rfa.org/ HTTP/1.1" 404 1661
Not Found: /http:/wujieliulan.com/
[16/Apr/2019 04:18:36] "GET http://wujieliulan.com/ HTTP/1.1" 404 1677
Not Found: /http:/www.epochtimes.com/
[16/Apr/2019 04:18:36] "GET http://www.epochtimes.com/ HTTP/1.1" 404 1689
Not Found: /http:/www.minghui.org/
[16/Apr/2019 04:18:36] "GET http://www.minghui.org/ HTTP/1.1" 404 1677
Not Found: /www.voanews.com:443
[16/Apr/2019 04:18:36] "CONNECT www.voanews.com:443 HTTP/1.0" 404 1683
[16/Apr/2019 06:04:10] "GET /blog/index/ HTTP/1.1" 200 1254
[16/Apr/2019 06:04:13] "GET /mooc/upload/ HTTP/1.1" 200 569
[16/Apr/2019 06:04:15] "GET /mooc/show/ HTTP/1.1" 200 238
[16/Apr/2019 06:04:20] "GET /mooc/show/ HTTP/1.1" 200 238
[16/Apr/2019 06:04:21] "GET /blog/index/ HTTP/1.1" 200 1254
[16/Apr/2019 06:04:34] "GET /blog/article/21/ HTTP/1.1" 200 411
[16/Apr/2019 06:04:37] "GET /blog/index/ HTTP/1.1" 200 1254
Not Found: /favicon.ico
[16/Apr/2019 06:04:38] "GET /favicon.ico HTTP/1.1" 404 2312
----------------------------------------
Exception happened during processing of request from ('123.127.3.49', 56727)
Traceback (most recent call last):
  File "/usr/local/lib/python3.7/socketserver.py", line 647, in process_request_thread
    self.finish_request(request, client_address)
  File "/usr/local/lib/python3.7/socketserver.py", line 357, in finish_request
    self.RequestHandlerClass(request, client_address, self)
  File "/usr/local/lib/python3.7/socketserver.py", line 717, in __init__
    self.handle()
  File "/usr/local/lib/python3.7/site-packages/django/core/servers/basehttp.py", line 171, in handle
    self.handle_one_request()
  File "/usr/local/lib/python3.7/site-packages/django/core/servers/basehttp.py", line 179, in handle_one_request
    self.raw_requestline = self.rfile.readline(65537)
  File "/usr/local/lib/python3.7/socket.py", line 589, in readinto
    return self._sock.recv_into(b)
ConnectionResetError: [Errno 104] Connection reset by peer
----------------------------------------
[16/Apr/2019 06:04:44] "GET /blog/edit/tocha/21/ HTTP/1.1" 200 715
[16/Apr/2019 06:04:46] "POST /blog/edit/change/21/ HTTP/1.1" 200 1254
[16/Apr/2019 06:04:46] "GET /mooc/upload/ HTTP/1.1" 200 569
Not Found: /favicon.ico
[16/Apr/2019 06:04:47] "GET /favicon.ico HTTP/1.1" 404 2312
----------------------------------------
Exception happened during processing of request from ('123.127.3.49', 56729)
Traceback (most recent call last):
  File "/usr/local/lib/python3.7/socketserver.py", line 647, in process_request_thread
    self.finish_request(request, client_address)
  File "/usr/local/lib/python3.7/socketserver.py", line 357, in finish_request
    self.RequestHandlerClass(request, client_address, self)
  File "/usr/local/lib/python3.7/socketserver.py", line 717, in __init__
    self.handle()
  File "/usr/local/lib/python3.7/site-packages/django/core/servers/basehttp.py", line 171, in handle
    self.handle_one_request()
  File "/usr/local/lib/python3.7/site-packages/django/core/servers/basehttp.py", line 179, in handle_one_request
    self.raw_requestline = self.rfile.readline(65537)
  File "/usr/local/lib/python3.7/socket.py", line 589, in readinto
    return self._sock.recv_into(b)
ConnectionResetError: [Errno 104] Connection reset by peer
----------------------------------------
[16/Apr/2019 06:04:50] "GET /blog/article/12/ HTTP/1.1" 200 342
[16/Apr/2019 06:04:51] "GET /blog/index/ HTTP/1.1" 200 1254
[16/Apr/2019 06:04:54] "GET /mooc/upload/ HTTP/1.1" 200 569
[16/Apr/2019 06:04:55] "GET /mooc/show/ HTTP/1.1" 200 238
[16/Apr/2019 06:04:56] "GET /blog/index/ HTTP/1.1" 200 1254
Forbidden (CSRF token missing or incorrect.): /mooc/upload/
[16/Apr/2019 06:05:03] "POST /mooc/upload/ HTTP/1.1" 403 2513
[16/Apr/2019 06:05:03] "GET /mooc/show/ HTTP/1.1" 200 238
Not Found: /favicon.ico
[16/Apr/2019 06:05:03] "GET /favicon.ico HTTP/1.1" 404 2312
----------------------------------------
Exception happened during processing of request from ('123.127.3.49', 56734)
Traceback (most recent call last):
  File "/usr/local/lib/python3.7/socketserver.py", line 647, in process_request_thread
    self.finish_request(request, client_address)
  File "/usr/local/lib/python3.7/socketserver.py", line 357, in finish_request
    self.RequestHandlerClass(request, client_address, self)
  File "/usr/local/lib/python3.7/socketserver.py", line 717, in __init__
    self.handle()
  File "/usr/local/lib/python3.7/site-packages/django/core/servers/basehttp.py", line 171, in handle
    self.handle_one_request()
  File "/usr/local/lib/python3.7/site-packages/django/core/servers/basehttp.py", line 179, in handle_one_request
    self.raw_requestline = self.rfile.readline(65537)
  File "/usr/local/lib/python3.7/socket.py", line 589, in readinto
    return self._sock.recv_into(b)
ConnectionResetError: [Errno 104] Connection reset by peer
----------------------------------------
[16/Apr/2019 06:05:06] "GET /blog/index/ HTTP/1.1" 200 1254
Not Found: /favicon.ico
[16/Apr/2019 06:05:06] "GET /favicon.ico HTTP/1.1" 404 2312
----------------------------------------
Exception happened during processing of request from ('123.127.3.49', 56735)
Traceback (most recent call last):
  File "/usr/local/lib/python3.7/socketserver.py", line 647, in process_request_thread
    self.finish_request(request, client_address)
  File "/usr/local/lib/python3.7/socketserver.py", line 357, in finish_request
    self.RequestHandlerClass(request, client_address, self)
  File "/usr/local/lib/python3.7/socketserver.py", line 717, in __init__
    self.handle()
  File "/usr/local/lib/python3.7/site-packages/django/core/servers/basehttp.py", line 171, in handle
    self.handle_one_request()
  File "/usr/local/lib/python3.7/site-packages/django/core/servers/basehttp.py", line 179, in handle_one_request
    self.raw_requestline = self.rfile.readline(65537)
  File "/usr/local/lib/python3.7/socket.py", line 589, in readinto
    return self._sock.recv_into(b)
ConnectionResetError: [Errno 104] Connection reset by peer
----------------------------------------
[16/Apr/2019 06:05:13] "GET /blog/article/21/ HTTP/1.1" 200 411
Not Found: /favicon.ico
[16/Apr/2019 06:05:14] "GET /favicon.ico HTTP/1.1" 404 2312
----------------------------------------
Exception happened during processing of request from ('123.127.3.49', 56737)
Traceback (most recent call last):
  File "/usr/local/lib/python3.7/socketserver.py", line 647, in process_request_thread
    self.finish_request(request, client_address)
  File "/usr/local/lib/python3.7/socketserver.py", line 357, in finish_request
    self.RequestHandlerClass(request, client_address, self)
  File "/usr/local/lib/python3.7/socketserver.py", line 717, in __init__
    self.handle()
  File "/usr/local/lib/python3.7/site-packages/django/core/servers/basehttp.py", line 171, in handle
    self.handle_one_request()
  File "/usr/local/lib/python3.7/site-packages/django/core/servers/basehttp.py", line 179, in handle_one_request
    self.raw_requestline = self.rfile.readline(65537)
  File "/usr/local/lib/python3.7/socket.py", line 589, in readinto
    return self._sock.recv_into(b)
ConnectionResetError: [Errno 104] Connection reset by peer
----------------------------------------
[16/Apr/2019 06:05:21] "GET /blog/index/ HTTP/1.1" 200 1254
Not Found: /favicon.ico
[16/Apr/2019 06:05:22] "GET /favicon.ico HTTP/1.1" 404 2312
----------------------------------------
Exception happened during processing of request from ('123.127.3.49', 56739)
Traceback (most recent call last):
  File "/usr/local/lib/python3.7/socketserver.py", line 647, in process_request_thread
    self.finish_request(request, client_address)
  File "/usr/local/lib/python3.7/socketserver.py", line 357, in finish_request
    self.RequestHandlerClass(request, client_address, self)
  File "/usr/local/lib/python3.7/socketserver.py", line 717, in __init__
    self.handle()
  File "/usr/local/lib/python3.7/site-packages/django/core/servers/basehttp.py", line 171, in handle
    self.handle_one_request()
  File "/usr/local/lib/python3.7/site-packages/django/core/servers/basehttp.py", line 179, in handle_one_request
    self.raw_requestline = self.rfile.readline(65537)
  File "/usr/local/lib/python3.7/socket.py", line 589, in readinto
    return self._sock.recv_into(b)
ConnectionResetError: [Errno 104] Connection reset by peer
----------------------------------------
[16/Apr/2019 06:05:26] "GET /mooc/upload/ HTTP/1.1" 200 569
Not Found: /favicon.ico
[16/Apr/2019 06:05:26] "GET /favicon.ico HTTP/1.1" 404 2312
----------------------------------------
Exception happened during processing of request from ('123.127.3.49', 56747)
Traceback (most recent call last):
  File "/usr/local/lib/python3.7/socketserver.py", line 647, in process_request_thread
    self.finish_request(request, client_address)
  File "/usr/local/lib/python3.7/socketserver.py", line 357, in finish_request
    self.RequestHandlerClass(request, client_address, self)
  File "/usr/local/lib/python3.7/socketserver.py", line 717, in __init__
    self.handle()
  File "/usr/local/lib/python3.7/site-packages/django/core/servers/basehttp.py", line 171, in handle
    self.handle_one_request()
  File "/usr/local/lib/python3.7/site-packages/django/core/servers/basehttp.py", line 179, in handle_one_request
    self.raw_requestline = self.rfile.readline(65537)
  File "/usr/local/lib/python3.7/socket.py", line 589, in readinto
    return self._sock.recv_into(b)
ConnectionResetError: [Errno 104] Connection reset by peer
----------------------------------------
Internal Server Error: /mooc/upload/
Traceback (most recent call last):
  File "/usr/local/lib/python3.7/site-packages/django/core/handlers/exception.py", line 34, in inner
    response = get_response(request)
  File "/usr/local/lib/python3.7/site-packages/django/core/handlers/base.py", line 126, in _get_response
    response = self.process_exception_by_middleware(e, request)
  File "/usr/local/lib/python3.7/site-packages/django/core/handlers/base.py", line 124, in _get_response
    response = wrapped_callback(request, *callback_args, **callback_kwargs)
  File "/home/django/myblog/mooc/views.py", line 19, in uploadImg
    name = request.FILES.get('img').name
AttributeError: 'NoneType' object has no attribute 'name'
[16/Apr/2019 06:05:28] "POST /mooc/upload/ HTTP/1.1" 500 63522
----------------------------------------
Exception happened during processing of request from ('123.127.3.49', 56748)
Traceback (most recent call last):
  File "/usr/local/lib/python3.7/socketserver.py", line 647, in process_request_thread
    self.finish_request(request, client_address)
  File "/usr/local/lib/python3.7/socketserver.py", line 357, in finish_request
    self.RequestHandlerClass(request, client_address, self)
  File "/usr/local/lib/python3.7/socketserver.py", line 717, in __init__
    self.handle()
  File "/usr/local/lib/python3.7/site-packages/django/core/servers/basehttp.py", line 171, in handle
    self.handle_one_request()
  File "/usr/local/lib/python3.7/site-packages/django/core/servers/basehttp.py", line 179, in handle_one_request
    self.raw_requestline = self.rfile.readline(65537)
  File "/usr/local/lib/python3.7/socket.py", line 589, in readinto
    return self._sock.recv_into(b)
ConnectionResetError: [Errno 104] Connection reset by peer
----------------------------------------
Not Found: /http:/www.baidu.com/cache/global/img/gs.gif
[16/Apr/2019 07:10:40] "GET http://www.baidu.com/cache/global/img/gs.gif HTTP/1.1" 404 1738
----------------------------------------
Exception happened during processing of request from ('80.82.70.187', 50369)
Traceback (most recent call last):
  File "/usr/local/lib/python3.7/socketserver.py", line 647, in process_request_thread
    self.finish_request(request, client_address)
  File "/usr/local/lib/python3.7/socketserver.py", line 357, in finish_request
    self.RequestHandlerClass(request, client_address, self)
  File "/usr/local/lib/python3.7/socketserver.py", line 717, in __init__
    self.handle()
  File "/usr/local/lib/python3.7/site-packages/django/core/servers/basehttp.py", line 171, in handle
    self.handle_one_request()
  File "/usr/local/lib/python3.7/site-packages/django/core/servers/basehttp.py", line 179, in handle_one_request
    self.raw_requestline = self.rfile.readline(65537)
  File "/usr/local/lib/python3.7/socket.py", line 589, in readinto
    return self._sock.recv_into(b)
ConnectionResetError: [Errno 104] Connection reset by peer
----------------------------------------
[16/Apr/2019 19:47:52] code 400, message Bad request version ('F\x07\x00tsXrcsXYs9\x00\x00\x00\x00\x00\x00\x00\x00\x00\x00\x00\x00\x00\x00\x00\x00\x00\x00\x00\x00\x00\x00bbXcsXctst\x00\x00\x00\x00\x00\x00')
[16/Apr/2019 19:47:52] "   TZ          0I    ¨À )t F tsXrcsXYs9                      bbXcsXctst      " 400 -
Not Found: /
[16/Apr/2019 21:11:42] "GET / HTTP/1.1" 404 2261
[17/Apr/2019 01:24:05] "GET /mooc/show HTTP/1.1" 301 0
[17/Apr/2019 01:24:05] "GET /mooc/show/ HTTP/1.1" 200 238
Not Found: /favicon.ico
[17/Apr/2019 01:24:06] "GET /favicon.ico HTTP/1.1" 404 2312
[17/Apr/2019 01:24:09] "GET /blog/index HTTP/1.1" 301 0
[17/Apr/2019 01:24:09] "GET /blog/index/ HTTP/1.1" 200 1254
Not Found: /favicon.ico
[17/Apr/2019 01:24:10] "GET /favicon.ico HTTP/1.1" 404 2312
Not Found: /http:/www.baidu.com/cache/global/img/gs.gif
[17/Apr/2019 03:19:44] "GET http://www.baidu.com/cache/global/img/gs.gif HTTP/1.1" 404 1738
----------------------------------------
Exception happened during processing of request from ('80.82.70.187', 42620)
Traceback (most recent call last):
  File "/usr/local/lib/python3.7/socketserver.py", line 647, in process_request_thread
    self.finish_request(request, client_address)
  File "/usr/local/lib/python3.7/socketserver.py", line 357, in finish_request
    self.RequestHandlerClass(request, client_address, self)
  File "/usr/local/lib/python3.7/socketserver.py", line 717, in __init__
    self.handle()
  File "/usr/local/lib/python3.7/site-packages/django/core/servers/basehttp.py", line 171, in handle
    self.handle_one_request()
  File "/usr/local/lib/python3.7/site-packages/django/core/servers/basehttp.py", line 179, in handle_one_request
    self.raw_requestline = self.rfile.readline(65537)
  File "/usr/local/lib/python3.7/socket.py", line 589, in readinto
    return self._sock.recv_into(b)
ConnectionResetError: [Errno 104] Connection reset by peer
----------------------------------------
Not Found: /http:/www.qq.com/404/search_children.js
[17/Apr/2019 06:45:39] "GET http://www.qq.com/404/search_children.js HTTP/1.1" 404 1723
----------------------------------------
Exception happened during processing of request from ('120.132.3.65', 42230)
Traceback (most recent call last):
  File "/usr/local/lib/python3.7/socketserver.py", line 647, in process_request_thread
    self.finish_request(request, client_address)
  File "/usr/local/lib/python3.7/socketserver.py", line 357, in finish_request
    self.RequestHandlerClass(request, client_address, self)
  File "/usr/local/lib/python3.7/socketserver.py", line 717, in __init__
    self.handle()
  File "/usr/local/lib/python3.7/site-packages/django/core/servers/basehttp.py", line 171, in handle
    self.handle_one_request()
  File "/usr/local/lib/python3.7/site-packages/django/core/servers/basehttp.py", line 179, in handle_one_request
    self.raw_requestline = self.rfile.readline(65537)
  File "/usr/local/lib/python3.7/socket.py", line 589, in readinto
    return self._sock.recv_into(b)
ConnectionResetError: [Errno 104] Connection reset by peer
----------------------------------------
[17/Apr/2019 06:45:44] code 400, message Bad request syntax ('\x04\x01\x00PpTi4\x00')
[17/Apr/2019 06:45:44] " PpTi4 " 400 -
[17/Apr/2019 06:45:44] code 400, message Bad request syntax ('\x05\x01\x00')
[17/Apr/2019 06:45:44] " " 400 -
[17/Apr/2019 08:34:58] "GET /blog/index/ HTTP/1.1" 200 1254
Not Found: /favicon.ico
[17/Apr/2019 08:34:58] "GET /favicon.ico HTTP/1.1" 404 2312
[17/Apr/2019 08:35:00] "GET /blog/article/12/ HTTP/1.1" 200 342
[17/Apr/2019 08:35:02] "GET /blog/index/ HTTP/1.1" 200 1254
[17/Apr/2019 08:35:04] "GET /blog/article/20/ HTTP/1.1" 200 412
[17/Apr/2019 08:35:05] "GET /blog/index/ HTTP/1.1" 200 1254
Not Found: /
[17/Apr/2019 12:47:23] "GET / HTTP/1.1" 404 2261
Not Found: /http:/www.baidu.com/cache/global/img/gs.gif
[17/Apr/2019 13:25:44] "GET http://www.baidu.com/cache/global/img/gs.gif HTTP/1.1" 404 1738
----------------------------------------
Exception happened during processing of request from ('80.82.70.187', 58817)
Traceback (most recent call last):
  File "/usr/local/lib/python3.7/socketserver.py", line 647, in process_request_thread
    self.finish_request(request, client_address)
  File "/usr/local/lib/python3.7/socketserver.py", line 357, in finish_request
    self.RequestHandlerClass(request, client_address, self)
  File "/usr/local/lib/python3.7/socketserver.py", line 717, in __init__
    self.handle()
  File "/usr/local/lib/python3.7/site-packages/django/core/servers/basehttp.py", line 171, in handle
    self.handle_one_request()
  File "/usr/local/lib/python3.7/site-packages/django/core/servers/basehttp.py", line 179, in handle_one_request
    self.raw_requestline = self.rfile.readline(65537)
  File "/usr/local/lib/python3.7/socket.py", line 589, in readinto
    return self._sock.recv_into(b)
ConnectionResetError: [Errno 104] Connection reset by peer
----------------------------------------
Not Found: /www.baidu.com:443
[17/Apr/2019 13:37:23] "CONNECT www.baidu.com:443 HTTP/1.0" 404 1662
Not Found: /
[17/Apr/2019 14:24:26] "GET / HTTP/1.1" 404 2261
----------------------------------------
Exception happened during processing of request from ('101.251.242.238', 36494)
Traceback (most recent call last):
  File "/usr/local/lib/python3.7/socketserver.py", line 647, in process_request_thread
    self.finish_request(request, client_address)
  File "/usr/local/lib/python3.7/socketserver.py", line 357, in finish_request
    self.RequestHandlerClass(request, client_address, self)
  File "/usr/local/lib/python3.7/socketserver.py", line 717, in __init__
    self.handle()
  File "/usr/local/lib/python3.7/site-packages/django/core/servers/basehttp.py", line 171, in handle
    self.handle_one_request()
  File "/usr/local/lib/python3.7/site-packages/django/core/servers/basehttp.py", line 179, in handle_one_request
    self.raw_requestline = self.rfile.readline(65537)
  File "/usr/local/lib/python3.7/socket.py", line 589, in readinto
    return self._sock.recv_into(b)
ConnectionResetError: [Errno 104] Connection reset by peer
----------------------------------------
[17/Apr/2019 16:10:08] "GET /blog/index/ HTTP/1.1" 200 1254
Not Found: /favicon.ico
[17/Apr/2019 16:10:09] "GET /favicon.ico HTTP/1.1" 404 2312
[17/Apr/2019 16:10:12] "GET /blog/index/ HTTP/1.1" 200 1254
Not Found: /
[17/Apr/2019 16:13:07] "GET / HTTP/1.1" 404 2256
Not Found: /favicon.ico
[17/Apr/2019 16:13:09] "GET /favicon.ico HTTP/1.1" 404 2312
Not Found: /http:/www.baidu.com/cache/global/img/gs.gif
[17/Apr/2019 23:30:43] "GET http://www.baidu.com/cache/global/img/gs.gif HTTP/1.1" 404 1738
----------------------------------------
Exception happened during processing of request from ('80.82.70.187', 35381)
Traceback (most recent call last):
  File "/usr/local/lib/python3.7/socketserver.py", line 647, in process_request_thread
    self.finish_request(request, client_address)
  File "/usr/local/lib/python3.7/socketserver.py", line 357, in finish_request
    self.RequestHandlerClass(request, client_address, self)
  File "/usr/local/lib/python3.7/socketserver.py", line 717, in __init__
    self.handle()
  File "/usr/local/lib/python3.7/site-packages/django/core/servers/basehttp.py", line 171, in handle
    self.handle_one_request()
  File "/usr/local/lib/python3.7/site-packages/django/core/servers/basehttp.py", line 179, in handle_one_request
    self.raw_requestline = self.rfile.readline(65537)
  File "/usr/local/lib/python3.7/socket.py", line 589, in readinto
    return self._sock.recv_into(b)
ConnectionResetError: [Errno 104] Connection reset by peer
----------------------------------------
Not Found: /
[17/Apr/2019 23:57:24] "GET / HTTP/1.1" 404 2262
[18/Apr/2019 01:13:08] "GET /blog/index HTTP/1.1" 301 0
[18/Apr/2019 01:13:08] "GET /blog/index/ HTTP/1.1" 200 1254
Not Found: /favicon.ico
[18/Apr/2019 01:13:09] "GET /favicon.ico HTTP/1.1" 404 2312
[18/Apr/2019 01:13:11] "GET /mooc/upload/ HTTP/1.1" 200 569
Not Found: /favicon.ico
[18/Apr/2019 01:13:11] "GET /favicon.ico HTTP/1.1" 404 2312
[18/Apr/2019 01:13:28] "POST /mooc/upload/ HTTP/1.1" 200 569
Not Found: /favicon.ico
[18/Apr/2019 01:13:29] "GET /favicon.ico HTTP/1.1" 404 2312
[18/Apr/2019 01:13:31] "GET /mooc/show/ HTTP/1.1" 200 362
[18/Apr/2019 01:13:31] "GET /media/img/5C23A80B-04EB-4B00-A4C2-97B3354B2469.jpeg HTTP/1.1" 200 1858156
Not Found: /favicon.ico
[18/Apr/2019 01:13:36] "GET /favicon.ico HTTP/1.1" 404 2312
Not Found: /favicon.ico
[18/Apr/2019 01:13:49] "GET /favicon.ico HTTP/1.1" 404 2312
[18/Apr/2019 01:13:51] "GET /mooc/show/ HTTP/1.1" 200 362
Not Found: /favicon.ico
[18/Apr/2019 01:13:53] "GET /favicon.ico HTTP/1.1" 404 2312
[18/Apr/2019 01:14:05] "GET /mooc/delete/12/ HTTP/1.1" 200 238
Not Found: /favicon.ico
[18/Apr/2019 01:14:05] "GET /favicon.ico HTTP/1.1" 404 2312
Not Found: /favicon.ico
[18/Apr/2019 01:14:06] "GET /favicon.ico HTTP/1.1" 404 2312
Not Found: /favicon.ico
[18/Apr/2019 01:14:07] "GET /favicon.ico HTTP/1.1" 404 2312
[18/Apr/2019 01:14:09] "GET /mooc/show/ HTTP/1.1" 200 238
Not Found: /favicon.ico
[18/Apr/2019 01:14:09] "GET /favicon.ico HTTP/1.1" 404 2312
Not Found: /favicon.ico
[18/Apr/2019 01:14:12] "GET /favicon.ico HTTP/1.1" 404 2312
Not Found: /favicon.ico
[18/Apr/2019 01:14:13] "GET /favicon.ico HTTP/1.1" 404 2312
Not Found: /favicon.ico
[18/Apr/2019 03:30:18] "GET /favicon.ico HTTP/1.1" 404 2312
Not Found: /
[18/Apr/2019 04:20:17] "GET / HTTP/1.0" 404 2271
Not Found: /
[18/Apr/2019 09:09:50] "GET / HTTP/1.1" 404 2261
Not Found: /http:/www.baidu.com/cache/global/img/gs.gif
[18/Apr/2019 09:34:22] "GET http://www.baidu.com/cache/global/img/gs.gif HTTP/1.1" 404 1738
----------------------------------------
Exception happened during processing of request from ('80.82.70.187', 33544)
Traceback (most recent call last):
  File "/usr/local/lib/python3.7/socketserver.py", line 647, in process_request_thread
    self.finish_request(request, client_address)
  File "/usr/local/lib/python3.7/socketserver.py", line 357, in finish_request
    self.RequestHandlerClass(request, client_address, self)
  File "/usr/local/lib/python3.7/socketserver.py", line 717, in __init__
    self.handle()
  File "/usr/local/lib/python3.7/site-packages/django/core/servers/basehttp.py", line 171, in handle
    self.handle_one_request()
  File "/usr/local/lib/python3.7/site-packages/django/core/servers/basehttp.py", line 179, in handle_one_request
    self.raw_requestline = self.rfile.readline(65537)
  File "/usr/local/lib/python3.7/socket.py", line 589, in readinto
    return self._sock.recv_into(b)
ConnectionResetError: [Errno 104] Connection reset by peer
----------------------------------------
Not Found: /favicon.ico
[18/Apr/2019 13:59:54] "GET /favicon.ico HTTP/1.1" 404 2312
Not Found: /http:/www.baidu.com/cache/global/img/gs.gif
[18/Apr/2019 19:37:50] "GET http://www.baidu.com/cache/global/img/gs.gif HTTP/1.1" 404 1738
----------------------------------------
Exception happened during processing of request from ('80.82.70.187', 44412)
Traceback (most recent call last):
  File "/usr/local/lib/python3.7/socketserver.py", line 647, in process_request_thread
    self.finish_request(request, client_address)
  File "/usr/local/lib/python3.7/socketserver.py", line 357, in finish_request
    self.RequestHandlerClass(request, client_address, self)
  File "/usr/local/lib/python3.7/socketserver.py", line 717, in __init__
    self.handle()
  File "/usr/local/lib/python3.7/site-packages/django/core/servers/basehttp.py", line 171, in handle
    self.handle_one_request()
  File "/usr/local/lib/python3.7/site-packages/django/core/servers/basehttp.py", line 179, in handle_one_request
    self.raw_requestline = self.rfile.readline(65537)
  File "/usr/local/lib/python3.7/socket.py", line 589, in readinto
    return self._sock.recv_into(b)
ConnectionResetError: [Errno 104] Connection reset by peer
----------------------------------------
Not Found: /
[19/Apr/2019 01:14:39] "GET / HTTP/1.1" 404 2261
Not Found: /http:/www.qq.com/404/search_children.js
[19/Apr/2019 02:01:16] "GET http://www.qq.com/404/search_children.js HTTP/1.1" 404 1723
[19/Apr/2019 02:01:21] code 400, message Bad request syntax ('\x04\x01\x00PpTi4\x00')
[19/Apr/2019 02:01:21] " PpTi4 " 400 -
[19/Apr/2019 02:01:21] code 400, message Bad request syntax ('\x05\x01\x00')
[19/Apr/2019 02:01:21] " " 400 -
Not Found: /
[19/Apr/2019 04:01:07] "GET / HTTP/1.1" 404 2261
----------------------------------------
Exception happened during processing of request from ('198.108.67.48', 63690)
Traceback (most recent call last):
  File "/usr/local/lib/python3.7/socketserver.py", line 647, in process_request_thread
    self.finish_request(request, client_address)
  File "/usr/local/lib/python3.7/socketserver.py", line 357, in finish_request
    self.RequestHandlerClass(request, client_address, self)
  File "/usr/local/lib/python3.7/socketserver.py", line 717, in __init__
    self.handle()
  File "/usr/local/lib/python3.7/site-packages/django/core/servers/basehttp.py", line 171, in handle
    self.handle_one_request()
  File "/usr/local/lib/python3.7/site-packages/django/core/servers/basehttp.py", line 179, in handle_one_request
    self.raw_requestline = self.rfile.readline(65537)
  File "/usr/local/lib/python3.7/socket.py", line 589, in readinto
    return self._sock.recv_into(b)
ConnectionResetError: [Errno 104] Connection reset by peer
----------------------------------------
Not Found: /http:/www.baidu.com/cache/global/img/gs.gif
[19/Apr/2019 05:46:00] "GET http://www.baidu.com/cache/global/img/gs.gif HTTP/1.1" 404 1738
----------------------------------------
Exception happened during processing of request from ('80.82.70.187', 37690)
Traceback (most recent call last):
  File "/usr/local/lib/python3.7/socketserver.py", line 647, in process_request_thread
    self.finish_request(request, client_address)
  File "/usr/local/lib/python3.7/socketserver.py", line 357, in finish_request
    self.RequestHandlerClass(request, client_address, self)
  File "/usr/local/lib/python3.7/socketserver.py", line 717, in __init__
    self.handle()
  File "/usr/local/lib/python3.7/site-packages/django/core/servers/basehttp.py", line 171, in handle
    self.handle_one_request()
  File "/usr/local/lib/python3.7/site-packages/django/core/servers/basehttp.py", line 179, in handle_one_request
    self.raw_requestline = self.rfile.readline(65537)
  File "/usr/local/lib/python3.7/socket.py", line 589, in readinto
    return self._sock.recv_into(b)
ConnectionResetError: [Errno 104] Connection reset by peer
----------------------------------------
Not Found: /robots.txt
[19/Apr/2019 06:46:35] "GET /robots.txt HTTP/1.1" 404 2309
[19/Apr/2019 06:46:36] "GET /blog/index/ HTTP/1.1" 200 1254
[19/Apr/2019 06:47:15] "GET /blog/article/18/ HTTP/1.1" 200 394
[19/Apr/2019 06:47:49] "GET /blog/edit/ HTTP/1.1" 200 552
[19/Apr/2019 06:49:01] "GET /mooc/upload/ HTTP/1.1" 200 569
[19/Apr/2019 06:49:57] "GET /mooc/show/ HTTP/1.1" 200 238
[19/Apr/2019 06:50:29] "GET /blog/article/21/ HTTP/1.1" 200 411
Not Found: /favicon.ico
[19/Apr/2019 07:17:13] "GET /favicon.ico HTTP/1.1" 404 2312
[19/Apr/2019 08:51:41] "GET /blog/index HTTP/1.1" 301 0
[19/Apr/2019 08:51:41] "GET /blog/index/ HTTP/1.1" 200 1254
Not Found: /favicon.ico
[19/Apr/2019 08:51:41] "GET /favicon.ico HTTP/1.1" 404 2312
[19/Apr/2019 09:19:51] "GET /blog/index/ HTTP/1.1" 200 1254
[19/Apr/2019 14:43:31] code 400, message Bad HTTP/0.9 request type ('\x03\x00\x00/*à\x00\x00\x00\x00\x00Cookie:')
[19/Apr/2019 14:43:31] "  /*à     Cookie: mstshash=Administr" 400 -
Not Found: /http:/www.baidu.com/cache/global/img/gs.gif
[19/Apr/2019 15:52:27] "GET http://www.baidu.com/cache/global/img/gs.gif HTTP/1.1" 404 1738
----------------------------------------
Exception happened during processing of request from ('80.82.70.187', 51367)
Traceback (most recent call last):
  File "/usr/local/lib/python3.7/socketserver.py", line 647, in process_request_thread
    self.finish_request(request, client_address)
  File "/usr/local/lib/python3.7/socketserver.py", line 357, in finish_request
    self.RequestHandlerClass(request, client_address, self)
  File "/usr/local/lib/python3.7/socketserver.py", line 717, in __init__
    self.handle()
  File "/usr/local/lib/python3.7/site-packages/django/core/servers/basehttp.py", line 171, in handle
    self.handle_one_request()
  File "/usr/local/lib/python3.7/site-packages/django/core/servers/basehttp.py", line 179, in handle_one_request
    self.raw_requestline = self.rfile.readline(65537)
  File "/usr/local/lib/python3.7/socket.py", line 589, in readinto
    return self._sock.recv_into(b)
ConnectionResetError: [Errno 104] Connection reset by peer
----------------------------------------
Not Found: /
[19/Apr/2019 19:53:09] "GET / HTTP/1.1" 404 2261
Not Found: /
[19/Apr/2019 22:47:58] "GET / HTTP/1.0" 404 2271
[20/Apr/2019 01:09:27] "GET /blog/index HTTP/1.1" 301 0
[20/Apr/2019 01:09:27] "GET /blog/index/ HTTP/1.1" 200 1254
Not Found: /favicon.ico
[20/Apr/2019 01:09:27] "GET /favicon.ico HTTP/1.1" 404 2312
[20/Apr/2019 01:09:30] "GET /mooc/upload/ HTTP/1.1" 200 569
Not Found: /favicon.ico
[20/Apr/2019 01:09:30] "GET /favicon.ico HTTP/1.1" 404 2312
[20/Apr/2019 01:09:44] "POST /mooc/upload/ HTTP/1.1" 200 569
Not Found: /favicon.ico
[20/Apr/2019 01:09:44] "GET /favicon.ico HTTP/1.1" 404 2312
[20/Apr/2019 01:09:46] "GET /mooc/show/ HTTP/1.1" 200 362
[20/Apr/2019 01:09:46] "GET /media/img/27A8993A-9901-4F21-8931-D1306868DF87.jpeg HTTP/1.1" 200 66203
Not Found: /favicon.ico
[20/Apr/2019 01:09:46] "GET /favicon.ico HTTP/1.1" 404 2312
[20/Apr/2019 01:09:58] "GET /blog/index/ HTTP/1.1" 200 1254
Not Found: /favicon.ico
[20/Apr/2019 01:09:58] "GET /favicon.ico HTTP/1.1" 404 2312
[20/Apr/2019 01:10:00] "GET /mooc/upload/ HTTP/1.1" 200 569
Not Found: /favicon.ico
[20/Apr/2019 01:10:00] "GET /favicon.ico HTTP/1.1" 404 2312
Internal Server Error: /mooc/upload/
Traceback (most recent call last):
  File "/usr/local/lib/python3.7/site-packages/django/core/handlers/exception.py", line 34, in inner
    response = get_response(request)
  File "/usr/local/lib/python3.7/site-packages/django/core/handlers/base.py", line 126, in _get_response
    response = self.process_exception_by_middleware(e, request)
  File "/usr/local/lib/python3.7/site-packages/django/core/handlers/base.py", line 124, in _get_response
    response = wrapped_callback(request, *callback_args, **callback_kwargs)
  File "/home/django/myblog/mooc/views.py", line 19, in uploadImg
    name = request.FILES.get('img').name
AttributeError: 'NoneType' object has no attribute 'name'
[20/Apr/2019 01:10:01] "POST /mooc/upload/ HTTP/1.1" 500 63820
Not Found: /favicon.ico
[20/Apr/2019 01:10:01] "GET /favicon.ico HTTP/1.1" 404 2312
Not Found: /favicon.ico
[20/Apr/2019 01:10:06] "GET /favicon.ico HTTP/1.1" 404 2312
[20/Apr/2019 01:10:07] "GET /mooc/show/ HTTP/1.1" 200 362
[20/Apr/2019 01:10:07] "GET /media/img/27A8993A-9901-4F21-8931-D1306868DF87.jpeg HTTP/1.1" 304 0
Not Found: /favicon.ico
[20/Apr/2019 01:10:08] "GET /favicon.ico HTTP/1.1" 404 2312
[20/Apr/2019 01:10:10] "GET /blog/index/ HTTP/1.1" 200 1254
Not Found: /favicon.ico
[20/Apr/2019 01:10:10] "GET /favicon.ico HTTP/1.1" 404 2312
[20/Apr/2019 01:10:11] "GET /blog/article/12/ HTTP/1.1" 200 342
Not Found: /favicon.ico
[20/Apr/2019 01:10:12] "GET /favicon.ico HTTP/1.1" 404 2312
Not Found: /favicon.ico
[20/Apr/2019 01:10:17] "GET /favicon.ico HTTP/1.1" 404 2312
Not Found: /favicon.ico
[20/Apr/2019 01:10:22] "GET /favicon.ico HTTP/1.1" 404 2312
Not Found: /http:/www.baidu.com/cache/global/img/gs.gif
[20/Apr/2019 01:59:06] "GET http://www.baidu.com/cache/global/img/gs.gif HTTP/1.1" 404 1738
----------------------------------------
Exception happened during processing of request from ('80.82.70.187', 40227)
Traceback (most recent call last):
  File "/usr/local/lib/python3.7/socketserver.py", line 647, in process_request_thread
    self.finish_request(request, client_address)
  File "/usr/local/lib/python3.7/socketserver.py", line 357, in finish_request
    self.RequestHandlerClass(request, client_address, self)
  File "/usr/local/lib/python3.7/socketserver.py", line 717, in __init__
    self.handle()
  File "/usr/local/lib/python3.7/site-packages/django/core/servers/basehttp.py", line 171, in handle
    self.handle_one_request()
  File "/usr/local/lib/python3.7/site-packages/django/core/servers/basehttp.py", line 179, in handle_one_request
    self.raw_requestline = self.rfile.readline(65537)
  File "/usr/local/lib/python3.7/socket.py", line 589, in readinto
    return self._sock.recv_into(b)
ConnectionResetError: [Errno 104] Connection reset by peer
----------------------------------------
Not Found: /http:/wujieliulan.com/
[20/Apr/2019 02:48:48] "GET http://wujieliulan.com/ HTTP/1.1" 404 1677
Not Found: /http:/www.minghui.org/
[20/Apr/2019 02:48:48] "GET http://www.minghui.org/ HTTP/1.1" 404 1677
Not Found: /www.voanews.com:443
[20/Apr/2019 02:48:48] "CONNECT www.voanews.com:443 HTTP/1.0" 404 1683
Not Found: /http:/www.epochtimes.com/
[20/Apr/2019 02:48:48] "GET http://www.epochtimes.com/ HTTP/1.1" 404 1689
Not Found: /http:/www.boxun.com/
[20/Apr/2019 02:48:48] "GET http://www.boxun.com/ HTTP/1.1" 404 1669
Not Found: /http:/www.bing.com/
[20/Apr/2019 02:48:48] "GET http://www.bing.com/ HTTP/1.1" 404 1665
Not Found: /http:/www.123cha.com/
[20/Apr/2019 02:48:48] "GET http://www.123cha.com/ HTTP/1.1" 404 1673
Not Found: /http:/www.baidu.com/
[20/Apr/2019 02:48:48] "GET http://www.baidu.com/ HTTP/1.1" 404 1669
Not Found: /http:/www.rfa.org/
[20/Apr/2019 02:48:54] "GET http://www.rfa.org/ HTTP/1.1" 404 1661
----------------------------------------
Exception happened during processing of request from ('104.152.52.22', 53300)
Traceback (most recent call last):
  File "/usr/local/lib/python3.7/socketserver.py", line 647, in process_request_thread
    self.finish_request(request, client_address)
  File "/usr/local/lib/python3.7/socketserver.py", line 357, in finish_request
    self.RequestHandlerClass(request, client_address, self)
  File "/usr/local/lib/python3.7/socketserver.py", line 717, in __init__
    self.handle()
  File "/usr/local/lib/python3.7/site-packages/django/core/servers/basehttp.py", line 169, in handle
    self.handle_one_request()
  File "/usr/local/lib/python3.7/site-packages/django/core/servers/basehttp.py", line 179, in handle_one_request
    self.raw_requestline = self.rfile.readline(65537)
  File "/usr/local/lib/python3.7/socket.py", line 589, in readinto
    return self._sock.recv_into(b)
ConnectionResetError: [Errno 104] Connection reset by peer
----------------------------------------
Not Found: /http:/www.baidu.com/cache/global/img/gs.gif
[20/Apr/2019 12:06:12] "GET http://www.baidu.com/cache/global/img/gs.gif HTTP/1.1" 404 1738
----------------------------------------
Exception happened during processing of request from ('80.82.70.187', 50387)
Traceback (most recent call last):
  File "/usr/local/lib/python3.7/socketserver.py", line 647, in process_request_thread
    self.finish_request(request, client_address)
  File "/usr/local/lib/python3.7/socketserver.py", line 357, in finish_request
    self.RequestHandlerClass(request, client_address, self)
  File "/usr/local/lib/python3.7/socketserver.py", line 717, in __init__
    self.handle()
  File "/usr/local/lib/python3.7/site-packages/django/core/servers/basehttp.py", line 171, in handle
    self.handle_one_request()
  File "/usr/local/lib/python3.7/site-packages/django/core/servers/basehttp.py", line 179, in handle_one_request
    self.raw_requestline = self.rfile.readline(65537)
  File "/usr/local/lib/python3.7/socket.py", line 589, in readinto
    return self._sock.recv_into(b)
ConnectionResetError: [Errno 104] Connection reset by peer
----------------------------------------
Not Found: /http:/www.baidu.com/cache/global/img/gs.gif
[20/Apr/2019 12:06:14] "GET http://www.baidu.com/cache/global/img/gs.gif HTTP/1.1" 404 1738
----------------------------------------
Exception happened during processing of request from ('80.82.70.187', 51160)
Traceback (most recent call last):
  File "/usr/local/lib/python3.7/socketserver.py", line 647, in process_request_thread
    self.finish_request(request, client_address)
  File "/usr/local/lib/python3.7/socketserver.py", line 357, in finish_request
    self.RequestHandlerClass(request, client_address, self)
  File "/usr/local/lib/python3.7/socketserver.py", line 717, in __init__
    self.handle()
  File "/usr/local/lib/python3.7/site-packages/django/core/servers/basehttp.py", line 171, in handle
    self.handle_one_request()
  File "/usr/local/lib/python3.7/site-packages/django/core/servers/basehttp.py", line 179, in handle_one_request
    self.raw_requestline = self.rfile.readline(65537)
  File "/usr/local/lib/python3.7/socket.py", line 589, in readinto
    return self._sock.recv_into(b)
ConnectionResetError: [Errno 104] Connection reset by peer
----------------------------------------
[20/Apr/2019 14:14:32] code 400, message Bad HTTP/0.9 request type ('\x03\x00\x00/*à\x00\x00\x00\x00\x00Cookie:')
[20/Apr/2019 14:14:32] "  /*à     Cookie: mstshash=Administr" 400 -
[20/Apr/2019 20:32:40] code 400, message Bad request syntax ('\x03\x00\x00\x13\x0eà\x00\x00\x00\x00\x00\x01\x00\x08\x00\x03\x00\x00\x00')
[20/Apr/2019 20:32:40] "  à          " 400 -
Not Found: /http:/www.baidu.com/cache/global/img/gs.gif
[20/Apr/2019 22:14:02] "GET http://www.baidu.com/cache/global/img/gs.gif HTTP/1.1" 404 1738
----------------------------------------
Exception happened during processing of request from ('80.82.70.187', 60048)
Traceback (most recent call last):
  File "/usr/local/lib/python3.7/socketserver.py", line 647, in process_request_thread
    self.finish_request(request, client_address)
  File "/usr/local/lib/python3.7/socketserver.py", line 357, in finish_request
    self.RequestHandlerClass(request, client_address, self)
  File "/usr/local/lib/python3.7/socketserver.py", line 717, in __init__
    self.handle()
  File "/usr/local/lib/python3.7/site-packages/django/core/servers/basehttp.py", line 171, in handle
    self.handle_one_request()
  File "/usr/local/lib/python3.7/site-packages/django/core/servers/basehttp.py", line 179, in handle_one_request
    self.raw_requestline = self.rfile.readline(65537)
  File "/usr/local/lib/python3.7/socket.py", line 589, in readinto
    return self._sock.recv_into(b)
ConnectionResetError: [Errno 104] Connection reset by peer
----------------------------------------
Not Found: /
[21/Apr/2019 03:37:33] "GET / HTTP/1.0" 404 2271
----------------------------------------
Exception happened during processing of request from ('121.8.152.115', 47102)
Traceback (most recent call last):
  File "/usr/local/lib/python3.7/socketserver.py", line 647, in process_request_thread
    self.finish_request(request, client_address)
  File "/usr/local/lib/python3.7/socketserver.py", line 357, in finish_request
    self.RequestHandlerClass(request, client_address, self)
  File "/usr/local/lib/python3.7/socketserver.py", line 717, in __init__
    self.handle()
  File "/usr/local/lib/python3.7/site-packages/django/core/servers/basehttp.py", line 169, in handle
    self.handle_one_request()
  File "/usr/local/lib/python3.7/site-packages/django/core/servers/basehttp.py", line 179, in handle_one_request
    self.raw_requestline = self.rfile.readline(65537)
  File "/usr/local/lib/python3.7/socket.py", line 589, in readinto
    return self._sock.recv_into(b)
ConnectionResetError: [Errno 104] Connection reset by peer
----------------------------------------
Not Found: /nice ports,/Trinity.txt.bak
[21/Apr/2019 03:37:41] "GET /nice%20ports%2C/Tri%6Eity.txt%2ebak HTTP/1.0" 404 2372
[21/Apr/2019 03:37:41] code 400, message Bad request version ('\x00/\x00')
[21/Apr/2019 03:37:41] You're accessing the development server over HTTPS, but it only supports HTTP.

[21/Apr/2019 03:37:41] code 400, message Bad request syntax ('\x16\x03\x00\x00S\x01\x00\x00O\x03\x00?G×÷º,îê²`~ó\x00ý\x82{¹Õ\x96Èw\x9bæÄÛ<=Ûoï\x10n\x00\x00(\x00\x16\x00\x13\x00')
[21/Apr/2019 03:37:41] You're accessing the development server over HTTPS, but it only supports HTTP.

----------------------------------------
Exception happened during processing of request from ('121.8.152.115', 11190)
Traceback (most recent call last):
  File "/usr/local/lib/python3.7/socketserver.py", line 647, in process_request_thread
    self.finish_request(request, client_address)
  File "/usr/local/lib/python3.7/socketserver.py", line 357, in finish_request
    self.RequestHandlerClass(request, client_address, self)
  File "/usr/local/lib/python3.7/socketserver.py", line 717, in __init__
    self.handle()
  File "/usr/local/lib/python3.7/site-packages/django/core/servers/basehttp.py", line 169, in handle
    self.handle_one_request()
  File "/usr/local/lib/python3.7/site-packages/django/core/servers/basehttp.py", line 179, in handle_one_request
    self.raw_requestline = self.rfile.readline(65537)
  File "/usr/local/lib/python3.7/socket.py", line 589, in readinto
    return self._sock.recv_into(b)
ConnectionResetError: [Errno 104] Connection reset by peer
----------------------------------------
[21/Apr/2019 03:37:49] code 400, message Bad request syntax ('HELP')
[21/Apr/2019 03:37:49] "HELP" 400 -
----------------------------------------
Exception happened during processing of request from ('121.8.152.115', 45145)
Traceback (most recent call last):
  File "/usr/local/lib/python3.7/socketserver.py", line 647, in process_request_thread
    self.finish_request(request, client_address)
  File "/usr/local/lib/python3.7/socketserver.py", line 357, in finish_request
    self.RequestHandlerClass(request, client_address, self)
  File "/usr/local/lib/python3.7/socketserver.py", line 717, in __init__
    self.handle()
  File "/usr/local/lib/python3.7/site-packages/django/core/servers/basehttp.py", line 169, in handle
    self.handle_one_request()
  File "/usr/local/lib/python3.7/site-packages/django/core/servers/basehttp.py", line 179, in handle_one_request
    self.raw_requestline = self.rfile.readline(65537)
  File "/usr/local/lib/python3.7/socket.py", line 589, in readinto
    return self._sock.recv_into(b)
ConnectionResetError: [Errno 104] Connection reset by peer
----------------------------------------
Not Found: /
[21/Apr/2019 03:37:57] "OPTIONS / HTTP/1.0" 404 2275
----------------------------------------
Exception happened during processing of request from ('121.8.152.115', 41989)
Traceback (most recent call last):
  File "/usr/local/lib/python3.7/socketserver.py", line 647, in process_request_thread
    self.finish_request(request, client_address)
  File "/usr/local/lib/python3.7/socketserver.py", line 357, in finish_request
    self.RequestHandlerClass(request, client_address, self)
  File "/usr/local/lib/python3.7/socketserver.py", line 717, in __init__
    self.handle()
  File "/usr/local/lib/python3.7/site-packages/django/core/servers/basehttp.py", line 169, in handle
    self.handle_one_request()
  File "/usr/local/lib/python3.7/site-packages/django/core/servers/basehttp.py", line 179, in handle_one_request
    self.raw_requestline = self.rfile.readline(65537)
  File "/usr/local/lib/python3.7/socket.py", line 589, in readinto
    return self._sock.recv_into(b)
ConnectionResetError: [Errno 104] Connection reset by peer
----------------------------------------
[21/Apr/2019 03:38:05] code 400, message Bad request version ('RTSP/1.0')
[21/Apr/2019 03:38:05] "OPTIONS / RTSP/1.0" 400 -
[21/Apr/2019 03:38:05] code 400, message Bad request syntax ('\x00\x00\x00qj\x81n0\x81k¡\x03\x02\x01\x05¢\x03\x02\x01')
[21/Apr/2019 03:38:05] "   qjn0k¡¢" 400 -
[21/Apr/2019 03:38:05] code 400, message Bad request version ('SIP/2.0')
[21/Apr/2019 03:38:05] "OPTIONS sip:nm SIP/2.0" 400 -
----------------------------------------
Exception happened during processing of request from ('121.8.152.115', 38841)
Traceback (most recent call last):
  File "/usr/local/lib/python3.7/socketserver.py", line 647, in process_request_thread
    self.finish_request(request, client_address)
  File "/usr/local/lib/python3.7/socketserver.py", line 357, in finish_request
    self.RequestHandlerClass(request, client_address, self)
  File "/usr/local/lib/python3.7/socketserver.py", line 717, in __init__
    self.handle()
  File "/usr/local/lib/python3.7/site-packages/django/core/servers/basehttp.py", line 169, in handle
    self.handle_one_request()
  File "/usr/local/lib/python3.7/site-packages/django/core/servers/basehttp.py", line 179, in handle_one_request
    self.raw_requestline = self.rfile.readline(65537)
  File "/usr/local/lib/python3.7/socket.py", line 589, in readinto
    return self._sock.recv_into(b)
ConnectionResetError: [Errno 104] Connection reset by peer
----------------------------------------
----------------------------------------
Exception happened during processing of request from ('121.8.152.115', 23403)
Traceback (most recent call last):
  File "/usr/local/lib/python3.7/socketserver.py", line 647, in process_request_thread
    self.finish_request(request, client_address)
  File "/usr/local/lib/python3.7/socketserver.py", line 357, in finish_request
    self.RequestHandlerClass(request, client_address, self)
  File "/usr/local/lib/python3.7/socketserver.py", line 717, in __init__
    self.handle()
  File "/usr/local/lib/python3.7/site-packages/django/core/servers/basehttp.py", line 169, in handle
    self.handle_one_request()
  File "/usr/local/lib/python3.7/site-packages/django/core/servers/basehttp.py", line 179, in handle_one_request
    self.raw_requestline = self.rfile.readline(65537)
  File "/usr/local/lib/python3.7/socket.py", line 589, in readinto
    return self._sock.recv_into(b)
ConnectionResetError: [Errno 104] Connection reset by peer
----------------------------------------
----------------------------------------
Exception happened during processing of request from ('121.8.152.115', 26318)
Traceback (most recent call last):
  File "/usr/local/lib/python3.7/socketserver.py", line 647, in process_request_thread
    self.finish_request(request, client_address)
  File "/usr/local/lib/python3.7/socketserver.py", line 357, in finish_request
    self.RequestHandlerClass(request, client_address, self)
  File "/usr/local/lib/python3.7/socketserver.py", line 717, in __init__
    self.handle()
  File "/usr/local/lib/python3.7/site-packages/django/core/servers/basehttp.py", line 169, in handle
    self.handle_one_request()
  File "/usr/local/lib/python3.7/site-packages/django/core/servers/basehttp.py", line 179, in handle_one_request
    self.raw_requestline = self.rfile.readline(65537)
  File "/usr/local/lib/python3.7/socket.py", line 589, in readinto
    return self._sock.recv_into(b)
ConnectionResetError: [Errno 104] Connection reset by peer
----------------------------------------
----------------------------------------
Exception happened during processing of request from ('121.8.152.115', 29510)
Traceback (most recent call last):
  File "/usr/local/lib/python3.7/socketserver.py", line 647, in process_request_thread
    self.finish_request(request, client_address)
  File "/usr/local/lib/python3.7/socketserver.py", line 357, in finish_request
    self.RequestHandlerClass(request, client_address, self)
  File "/usr/local/lib/python3.7/socketserver.py", line 717, in __init__
    self.handle()
  File "/usr/local/lib/python3.7/site-packages/django/core/servers/basehttp.py", line 169, in handle
    self.handle_one_request()
  File "/usr/local/lib/python3.7/site-packages/django/core/servers/basehttp.py", line 179, in handle_one_request
    self.raw_requestline = self.rfile.readline(65537)
  File "/usr/local/lib/python3.7/socket.py", line 589, in readinto
    return self._sock.recv_into(b)
ConnectionResetError: [Errno 104] Connection reset by peer
----------------------------------------
----------------------------------------
Exception happened during processing of request from ('121.8.152.115', 32523)
Traceback (most recent call last):
  File "/usr/local/lib/python3.7/socketserver.py", line 647, in process_request_thread
    self.finish_request(request, client_address)
  File "/usr/local/lib/python3.7/socketserver.py", line 357, in finish_request
    self.RequestHandlerClass(request, client_address, self)
  File "/usr/local/lib/python3.7/socketserver.py", line 717, in __init__
    self.handle()
  File "/usr/local/lib/python3.7/site-packages/django/core/servers/basehttp.py", line 169, in handle
    self.handle_one_request()
  File "/usr/local/lib/python3.7/site-packages/django/core/servers/basehttp.py", line 179, in handle_one_request
    self.raw_requestline = self.rfile.readline(65537)
  File "/usr/local/lib/python3.7/socket.py", line 589, in readinto
    return self._sock.recv_into(b)
ConnectionResetError: [Errno 104] Connection reset by peer
----------------------------------------
----------------------------------------
Exception happened during processing of request from ('121.8.152.115', 35561)
Traceback (most recent call last):
  File "/usr/local/lib/python3.7/socketserver.py", line 647, in process_request_thread
    self.finish_request(request, client_address)
  File "/usr/local/lib/python3.7/socketserver.py", line 357, in finish_request
    self.RequestHandlerClass(request, client_address, self)
  File "/usr/local/lib/python3.7/socketserver.py", line 717, in __init__
    self.handle()
  File "/usr/local/lib/python3.7/site-packages/django/core/servers/basehttp.py", line 169, in handle
    self.handle_one_request()
  File "/usr/local/lib/python3.7/site-packages/django/core/servers/basehttp.py", line 179, in handle_one_request
    self.raw_requestline = self.rfile.readline(65537)
  File "/usr/local/lib/python3.7/socket.py", line 589, in readinto
    return self._sock.recv_into(b)
ConnectionResetError: [Errno 104] Connection reset by peer
----------------------------------------
----------------------------------------
Exception happened during processing of request from ('121.8.152.115', 38631)
Traceback (most recent call last):
  File "/usr/local/lib/python3.7/socketserver.py", line 647, in process_request_thread
    self.finish_request(request, client_address)
  File "/usr/local/lib/python3.7/socketserver.py", line 357, in finish_request
    self.RequestHandlerClass(request, client_address, self)
  File "/usr/local/lib/python3.7/socketserver.py", line 717, in __init__
    self.handle()
  File "/usr/local/lib/python3.7/site-packages/django/core/servers/basehttp.py", line 169, in handle
    self.handle_one_request()
  File "/usr/local/lib/python3.7/site-packages/django/core/servers/basehttp.py", line 179, in handle_one_request
    self.raw_requestline = self.rfile.readline(65537)
  File "/usr/local/lib/python3.7/socket.py", line 589, in readinto
    return self._sock.recv_into(b)
ConnectionResetError: [Errno 104] Connection reset by peer
----------------------------------------
[21/Apr/2019 03:39:01] code 400, message Bad request syntax ('0\x84\x00\x00\x00-\x02\x01\x07c\x84\x00\x00\x00$\x04\x00')
[21/Apr/2019 03:39:01] "0   -c   $ " 400 -
[21/Apr/2019 03:39:01] code 400, message Bad request syntax ('\x01default')
[21/Apr/2019 03:39:01] "default" 400 -
----------------------------------------
Exception happened during processing of request from ('121.8.152.115', 41938)
Traceback (most recent call last):
  File "/usr/local/lib/python3.7/socketserver.py", line 647, in process_request_thread
    self.finish_request(request, client_address)
  File "/usr/local/lib/python3.7/socketserver.py", line 357, in finish_request
    self.RequestHandlerClass(request, client_address, self)
  File "/usr/local/lib/python3.7/socketserver.py", line 717, in __init__
    self.handle()
  File "/usr/local/lib/python3.7/site-packages/django/core/servers/basehttp.py", line 169, in handle
    self.handle_one_request()
  File "/usr/local/lib/python3.7/site-packages/django/core/servers/basehttp.py", line 179, in handle_one_request
    self.raw_requestline = self.rfile.readline(65537)
  File "/usr/local/lib/python3.7/socket.py", line 589, in readinto
    return self._sock.recv_into(b)
ConnectionResetError: [Errno 104] Connection reset by peer
----------------------------------------
----------------------------------------
Exception happened during processing of request from ('121.8.152.115', 45026)
Traceback (most recent call last):
  File "/usr/local/lib/python3.7/socketserver.py", line 647, in process_request_thread
    self.finish_request(request, client_address)
  File "/usr/local/lib/python3.7/socketserver.py", line 357, in finish_request
    self.RequestHandlerClass(request, client_address, self)
  File "/usr/local/lib/python3.7/socketserver.py", line 717, in __init__
    self.handle()
  File "/usr/local/lib/python3.7/site-packages/django/core/servers/basehttp.py", line 169, in handle
    self.handle_one_request()
  File "/usr/local/lib/python3.7/site-packages/django/core/servers/basehttp.py", line 179, in handle_one_request
    self.raw_requestline = self.rfile.readline(65537)
  File "/usr/local/lib/python3.7/socket.py", line 589, in readinto
    return self._sock.recv_into(b)
ConnectionResetError: [Errno 104] Connection reset by peer
----------------------------------------
----------------------------------------
Exception happened during processing of request from ('121.8.152.115', 48098)
Traceback (most recent call last):
  File "/usr/local/lib/python3.7/socketserver.py", line 647, in process_request_thread
    self.finish_request(request, client_address)
  File "/usr/local/lib/python3.7/socketserver.py", line 357, in finish_request
    self.RequestHandlerClass(request, client_address, self)
  File "/usr/local/lib/python3.7/socketserver.py", line 717, in __init__
    self.handle()
  File "/usr/local/lib/python3.7/site-packages/django/core/servers/basehttp.py", line 169, in handle
    self.handle_one_request()
  File "/usr/local/lib/python3.7/site-packages/django/core/servers/basehttp.py", line 179, in handle_one_request
    self.raw_requestline = self.rfile.readline(65537)
  File "/usr/local/lib/python3.7/socket.py", line 589, in readinto
    return self._sock.recv_into(b)
ConnectionResetError: [Errno 104] Connection reset by peer
----------------------------------------
----------------------------------------
Exception happened during processing of request from ('121.8.152.115', 12226)
Traceback (most recent call last):
  File "/usr/local/lib/python3.7/socketserver.py", line 647, in process_request_thread
    self.finish_request(request, client_address)
  File "/usr/local/lib/python3.7/socketserver.py", line 357, in finish_request
    self.RequestHandlerClass(request, client_address, self)
  File "/usr/local/lib/python3.7/socketserver.py", line 717, in __init__
    self.handle()
  File "/usr/local/lib/python3.7/site-packages/django/core/servers/basehttp.py", line 169, in handle
    self.handle_one_request()
  File "/usr/local/lib/python3.7/site-packages/django/core/servers/basehttp.py", line 179, in handle_one_request
    self.raw_requestline = self.rfile.readline(65537)
  File "/usr/local/lib/python3.7/socket.py", line 589, in readinto
    return self._sock.recv_into(b)
ConnectionResetError: [Errno 104] Connection reset by peer
----------------------------------------
----------------------------------------
Exception happened during processing of request from ('121.8.152.115', 15194)
Traceback (most recent call last):
  File "/usr/local/lib/python3.7/socketserver.py", line 647, in process_request_thread
    self.finish_request(request, client_address)
  File "/usr/local/lib/python3.7/socketserver.py", line 357, in finish_request
    self.RequestHandlerClass(request, client_address, self)
  File "/usr/local/lib/python3.7/socketserver.py", line 717, in __init__
    self.handle()
  File "/usr/local/lib/python3.7/site-packages/django/core/servers/basehttp.py", line 169, in handle
    self.handle_one_request()
  File "/usr/local/lib/python3.7/site-packages/django/core/servers/basehttp.py", line 179, in handle_one_request
    self.raw_requestline = self.rfile.readline(65537)
  File "/usr/local/lib/python3.7/socket.py", line 589, in readinto
    return self._sock.recv_into(b)
ConnectionResetError: [Errno 104] Connection reset by peer
----------------------------------------
Not Found: /http:/www.baidu.com/cache/global/img/gs.gif
[21/Apr/2019 08:23:05] "GET http://www.baidu.com/cache/global/img/gs.gif HTTP/1.1" 404 1738
----------------------------------------
Exception happened during processing of request from ('80.82.70.187', 35090)
Traceback (most recent call last):
  File "/usr/local/lib/python3.7/socketserver.py", line 647, in process_request_thread
    self.finish_request(request, client_address)
  File "/usr/local/lib/python3.7/socketserver.py", line 357, in finish_request
    self.RequestHandlerClass(request, client_address, self)
  File "/usr/local/lib/python3.7/socketserver.py", line 717, in __init__
    self.handle()
  File "/usr/local/lib/python3.7/site-packages/django/core/servers/basehttp.py", line 171, in handle
    self.handle_one_request()
  File "/usr/local/lib/python3.7/site-packages/django/core/servers/basehttp.py", line 179, in handle_one_request
    self.raw_requestline = self.rfile.readline(65537)
  File "/usr/local/lib/python3.7/socket.py", line 589, in readinto
    return self._sock.recv_into(b)
ConnectionResetError: [Errno 104] Connection reset by peer
----------------------------------------
Not Found: /
[21/Apr/2019 09:27:17] "GET / HTTP/1.1" 404 2260
Not Found: /
[21/Apr/2019 10:27:16] "GET / HTTP/1.1" 404 2261
Not Found: /http:/www.baidu.com/cache/global/img/gs.gif
[21/Apr/2019 18:31:00] "GET http://www.baidu.com/cache/global/img/gs.gif HTTP/1.1" 404 1738
----------------------------------------
Exception happened during processing of request from ('80.82.70.187', 49214)
Traceback (most recent call last):
  File "/usr/local/lib/python3.7/socketserver.py", line 647, in process_request_thread
    self.finish_request(request, client_address)
  File "/usr/local/lib/python3.7/socketserver.py", line 357, in finish_request
    self.RequestHandlerClass(request, client_address, self)
  File "/usr/local/lib/python3.7/socketserver.py", line 717, in __init__
    self.handle()
  File "/usr/local/lib/python3.7/site-packages/django/core/servers/basehttp.py", line 171, in handle
    self.handle_one_request()
  File "/usr/local/lib/python3.7/site-packages/django/core/servers/basehttp.py", line 179, in handle_one_request
    self.raw_requestline = self.rfile.readline(65537)
  File "/usr/local/lib/python3.7/socket.py", line 589, in readinto
    return self._sock.recv_into(b)
ConnectionResetError: [Errno 104] Connection reset by peer
----------------------------------------
Not Found: /
[21/Apr/2019 20:18:56] "GET / HTTP/1.1" 404 2261
[21/Apr/2019 22:50:30] code 400, message Bad request version ('F\x07\x00tsXrcsXYs9\x00\x00\x00\x00\x00\x00\x00\x00\x00\x00\x00\x00\x00\x00\x00\x00\x00\x00\x00\x00\x00\x00bbXcsXctst\x00\x00\x00\x00\x00\x00')
[21/Apr/2019 22:50:30] "   TZ          0I    ¨À )t F tsXrcsXYs9                      bbXcsXctst      " 400 -
[22/Apr/2019 02:32:31] "GET /blog/index/ HTTP/1.1" 200 1254
Not Found: /favicon.ico
[22/Apr/2019 02:32:31] "GET /favicon.ico HTTP/1.1" 404 2312
Not Found: /http:/www.baidu.com/cache/global/img/gs.gif
[22/Apr/2019 04:37:53] "GET http://www.baidu.com/cache/global/img/gs.gif HTTP/1.1" 404 1738
----------------------------------------
Exception happened during processing of request from ('80.82.70.187', 48547)
Traceback (most recent call last):
  File "/usr/local/lib/python3.7/socketserver.py", line 647, in process_request_thread
    self.finish_request(request, client_address)
  File "/usr/local/lib/python3.7/socketserver.py", line 357, in finish_request
    self.RequestHandlerClass(request, client_address, self)
  File "/usr/local/lib/python3.7/socketserver.py", line 717, in __init__
    self.handle()
  File "/usr/local/lib/python3.7/site-packages/django/core/servers/basehttp.py", line 171, in handle
    self.handle_one_request()
  File "/usr/local/lib/python3.7/site-packages/django/core/servers/basehttp.py", line 179, in handle_one_request
    self.raw_requestline = self.rfile.readline(65537)
  File "/usr/local/lib/python3.7/socket.py", line 589, in readinto
    return self._sock.recv_into(b)
ConnectionResetError: [Errno 104] Connection reset by peer
----------------------------------------
Not Found: /http:/www.qq.com/404/search_children.js
[22/Apr/2019 10:15:33] "GET http://www.qq.com/404/search_children.js HTTP/1.1" 404 1723
----------------------------------------
Exception happened during processing of request from ('120.132.3.65', 48174)
Traceback (most recent call last):
  File "/usr/local/lib/python3.7/socketserver.py", line 647, in process_request_thread
    self.finish_request(request, client_address)
  File "/usr/local/lib/python3.7/socketserver.py", line 357, in finish_request
    self.RequestHandlerClass(request, client_address, self)
  File "/usr/local/lib/python3.7/socketserver.py", line 717, in __init__
    self.handle()
  File "/usr/local/lib/python3.7/site-packages/django/core/servers/basehttp.py", line 171, in handle
    self.handle_one_request()
  File "/usr/local/lib/python3.7/site-packages/django/core/servers/basehttp.py", line 179, in handle_one_request
    self.raw_requestline = self.rfile.readline(65537)
  File "/usr/local/lib/python3.7/socket.py", line 589, in readinto
    return self._sock.recv_into(b)
ConnectionResetError: [Errno 104] Connection reset by peer
----------------------------------------
[22/Apr/2019 10:15:38] code 400, message Bad request syntax ('\x04\x01\x00PpTi4\x00')
[22/Apr/2019 10:15:38] " PpTi4 " 400 -
[22/Apr/2019 10:15:38] code 400, message Bad request syntax ('\x05\x01\x00')
[22/Apr/2019 10:15:38] " " 400 -
Not Found: /
[22/Apr/2019 13:01:56] "GET / HTTP/1.1" 404 2261
Not Found: /favicon.ico
[22/Apr/2019 13:01:56] "GET /favicon.ico HTTP/1.1" 404 2312
Not Found: /blod/index
[22/Apr/2019 13:02:12] "GET /blod/index HTTP/1.1" 404 2309
Not Found: /favicon.ico
[22/Apr/2019 13:02:12] "GET /favicon.ico HTTP/1.1" 404 2312
[22/Apr/2019 13:02:16] "GET /blog/index HTTP/1.1" 301 0
[22/Apr/2019 13:02:17] "GET /blog/index/ HTTP/1.1" 200 1254
Not Found: /favicon.ico
[22/Apr/2019 13:02:17] "GET /favicon.ico HTTP/1.1" 404 2312
[22/Apr/2019 13:02:20] "GET /blog/article/12/ HTTP/1.1" 200 342
[22/Apr/2019 13:02:30] "GET /blog/index/ HTTP/1.1" 200 1254
Not Found: /
[22/Apr/2019 13:02:57] "GET / HTTP/1.1" 404 2261
Not Found: /blod/index
[22/Apr/2019 13:03:12] "GET /blod/index HTTP/1.1" 404 2309
[22/Apr/2019 13:03:17] "GET /blog/index HTTP/1.1" 301 0
[22/Apr/2019 13:03:21] "GET /blog/article/12 HTTP/1.1" 301 0
Not Found: /favicon.ico
[22/Apr/2019 13:19:51] "GET /favicon.ico HTTP/1.1" 404 2312
Not Found: /http:/112.124.42.80:63435/
[22/Apr/2019 13:35:07] "HEAD http://112.124.42.80:63435/ HTTP/1.1" 404 1694
Not Found: /
[22/Apr/2019 23:01:41] "GET / HTTP/1.1" 404 2261
----------------------------------------
Exception happened during processing of request from ('198.108.67.48', 33574)
Traceback (most recent call last):
  File "/usr/local/lib/python3.7/socketserver.py", line 647, in process_request_thread
    self.finish_request(request, client_address)
  File "/usr/local/lib/python3.7/socketserver.py", line 357, in finish_request
    self.RequestHandlerClass(request, client_address, self)
  File "/usr/local/lib/python3.7/socketserver.py", line 717, in __init__
    self.handle()
  File "/usr/local/lib/python3.7/site-packages/django/core/servers/basehttp.py", line 171, in handle
    self.handle_one_request()
  File "/usr/local/lib/python3.7/site-packages/django/core/servers/basehttp.py", line 179, in handle_one_request
    self.raw_requestline = self.rfile.readline(65537)
  File "/usr/local/lib/python3.7/socket.py", line 589, in readinto
    return self._sock.recv_into(b)
ConnectionResetError: [Errno 104] Connection reset by peer
----------------------------------------
Not Found: /http:/www.baidu.com/cache/global/img/gs.gif
[23/Apr/2019 00:48:33] "GET http://www.baidu.com/cache/global/img/gs.gif HTTP/1.1" 404 1738
----------------------------------------
Exception happened during processing of request from ('80.82.70.187', 57491)
Traceback (most recent call last):
  File "/usr/local/lib/python3.7/socketserver.py", line 647, in process_request_thread
    self.finish_request(request, client_address)
  File "/usr/local/lib/python3.7/socketserver.py", line 357, in finish_request
    self.RequestHandlerClass(request, client_address, self)
  File "/usr/local/lib/python3.7/socketserver.py", line 717, in __init__
    self.handle()
  File "/usr/local/lib/python3.7/site-packages/django/core/servers/basehttp.py", line 171, in handle
    self.handle_one_request()
  File "/usr/local/lib/python3.7/site-packages/django/core/servers/basehttp.py", line 179, in handle_one_request
    self.raw_requestline = self.rfile.readline(65537)
  File "/usr/local/lib/python3.7/socket.py", line 589, in readinto
    return self._sock.recv_into(b)
ConnectionResetError: [Errno 104] Connection reset by peer
----------------------------------------
[23/Apr/2019 02:04:24] "GET /blog/index/ HTTP/1.1" 200 1254
Not Found: /favicon.ico
[23/Apr/2019 02:04:25] "GET /favicon.ico HTTP/1.1" 404 2312
[23/Apr/2019 02:04:58] "GET /blog/article/17/ HTTP/1.1" 200 263
[23/Apr/2019 02:26:44] "GET /blog/index/ HTTP/1.1" 200 1254
Not Found: /favicon.ico
[23/Apr/2019 02:26:44] "GET /favicon.ico HTTP/1.1" 404 2312
Performing system checks...

System check identified no issues (0 silenced).
April 15, 2019 - 09:33:01
Django version 2.1.8, using settings 'myblog.settings'
Starting development server at http://0.0.0.0:8000/
Quit the server with CONTROL-C.
[23/Apr/2019 07:32:25] "GET /newblog/index/ HTTP/1.1" 200 19
Internal Server Error: /newblog/essay/
Traceback (most recent call last):
  File "/usr/local/lib/python3.7/site-packages/django/db/backends/utils.py", line 85, in _execute
    return self.cursor.execute(sql, params)
  File "/usr/local/lib/python3.7/site-packages/django/db/backends/sqlite3/base.py", line 298, in execute
    return Database.Cursor.execute(self, query, params)
sqlite3.OperationalError: no such table: newblog_essay

The above exception was the direct cause of the following exception:

Traceback (most recent call last):
  File "/usr/local/lib/python3.7/site-packages/django/core/handlers/exception.py", line 34, in inner
    response = get_response(request)
  File "/usr/local/lib/python3.7/site-packages/django/core/handlers/base.py", line 126, in _get_response
    response = self.process_exception_by_middleware(e, request)
  File "/usr/local/lib/python3.7/site-packages/django/core/handlers/base.py", line 124, in _get_response
    response = wrapped_callback(request, *callback_args, **callback_kwargs)
  File "/home/django/myblog/newblog/views.py", line 20, in get_index_page
    return render(request, 'newblog/index.html', {'essays': essays})
  File "/usr/local/lib/python3.7/site-packages/django/shortcuts.py", line 36, in render
    content = loader.render_to_string(template_name, context, request, using=using)
  File "/usr/local/lib/python3.7/site-packages/django/template/loader.py", line 62, in render_to_string
    return template.render(context, request)
  File "/usr/local/lib/python3.7/site-packages/django/template/backends/django.py", line 61, in render
    return self.template.render(context)
  File "/usr/local/lib/python3.7/site-packages/django/template/base.py", line 171, in render
    return self._render(context)
  File "/usr/local/lib/python3.7/site-packages/django/template/base.py", line 163, in _render
    return self.nodelist.render(context)
  File "/usr/local/lib/python3.7/site-packages/django/template/base.py", line 937, in render
    bit = node.render_annotated(context)
  File "/usr/local/lib/python3.7/site-packages/django/template/base.py", line 904, in render_annotated
    return self.render(context)
  File "/usr/local/lib/python3.7/site-packages/django/template/defaulttags.py", line 166, in render
    len_values = len(values)
  File "/usr/local/lib/python3.7/site-packages/django/db/models/query.py", line 250, in __len__
    self._fetch_all()
  File "/usr/local/lib/python3.7/site-packages/django/db/models/query.py", line 1186, in _fetch_all
    self._result_cache = list(self._iterable_class(self))
  File "/usr/local/lib/python3.7/site-packages/django/db/models/query.py", line 54, in __iter__
    results = compiler.execute_sql(chunked_fetch=self.chunked_fetch, chunk_size=self.chunk_size)
  File "/usr/local/lib/python3.7/site-packages/django/db/models/sql/compiler.py", line 1065, in execute_sql
    cursor.execute(sql, params)
  File "/usr/local/lib/python3.7/site-packages/django/db/backends/utils.py", line 100, in execute
    return super().execute(sql, params)
  File "/usr/local/lib/python3.7/site-packages/django/db/backends/utils.py", line 68, in execute
    return self._execute_with_wrappers(sql, params, many=False, executor=self._execute)
  File "/usr/local/lib/python3.7/site-packages/django/db/backends/utils.py", line 77, in _execute_with_wrappers
    return executor(sql, params, many, context)
  File "/usr/local/lib/python3.7/site-packages/django/db/backends/utils.py", line 85, in _execute
    return self.cursor.execute(sql, params)
  File "/usr/local/lib/python3.7/site-packages/django/db/utils.py", line 89, in __exit__
    raise dj_exc_value.with_traceback(traceback) from exc_value
  File "/usr/local/lib/python3.7/site-packages/django/db/backends/utils.py", line 85, in _execute
    return self.cursor.execute(sql, params)
  File "/usr/local/lib/python3.7/site-packages/django/db/backends/sqlite3/base.py", line 298, in execute
    return Database.Cursor.execute(self, query, params)
django.db.utils.OperationalError: no such table: newblog_essay
[23/Apr/2019 07:32:34] "GET /newblog/essay/ HTTP/1.1" 500 163049
Internal Server Error: /newblog/essay/
Traceback (most recent call last):
  File "/usr/local/lib/python3.7/site-packages/django/db/backends/utils.py", line 85, in _execute
    return self.cursor.execute(sql, params)
  File "/usr/local/lib/python3.7/site-packages/django/db/backends/sqlite3/base.py", line 298, in execute
    return Database.Cursor.execute(self, query, params)
sqlite3.OperationalError: no such table: newblog_essay

The above exception was the direct cause of the following exception:

Traceback (most recent call last):
  File "/usr/local/lib/python3.7/site-packages/django/core/handlers/exception.py", line 34, in inner
    response = get_response(request)
  File "/usr/local/lib/python3.7/site-packages/django/core/handlers/base.py", line 126, in _get_response
    response = self.process_exception_by_middleware(e, request)
  File "/usr/local/lib/python3.7/site-packages/django/core/handlers/base.py", line 124, in _get_response
    response = wrapped_callback(request, *callback_args, **callback_kwargs)
  File "/home/django/myblog/newblog/views.py", line 20, in get_index_page
    return render(request, 'newblog/index.html', {'essays': essays})
  File "/usr/local/lib/python3.7/site-packages/django/shortcuts.py", line 36, in render
    content = loader.render_to_string(template_name, context, request, using=using)
  File "/usr/local/lib/python3.7/site-packages/django/template/loader.py", line 62, in render_to_string
    return template.render(context, request)
  File "/usr/local/lib/python3.7/site-packages/django/template/backends/django.py", line 61, in render
    return self.template.render(context)
  File "/usr/local/lib/python3.7/site-packages/django/template/base.py", line 171, in render
    return self._render(context)
  File "/usr/local/lib/python3.7/site-packages/django/template/base.py", line 163, in _render
    return self.nodelist.render(context)
  File "/usr/local/lib/python3.7/site-packages/django/template/base.py", line 937, in render
    bit = node.render_annotated(context)
  File "/usr/local/lib/python3.7/site-packages/django/template/base.py", line 904, in render_annotated
    return self.render(context)
  File "/usr/local/lib/python3.7/site-packages/django/template/defaulttags.py", line 166, in render
    len_values = len(values)
  File "/usr/local/lib/python3.7/site-packages/django/db/models/query.py", line 250, in __len__
    self._fetch_all()
  File "/usr/local/lib/python3.7/site-packages/django/db/models/query.py", line 1186, in _fetch_all
    self._result_cache = list(self._iterable_class(self))
  File "/usr/local/lib/python3.7/site-packages/django/db/models/query.py", line 54, in __iter__
    results = compiler.execute_sql(chunked_fetch=self.chunked_fetch, chunk_size=self.chunk_size)
  File "/usr/local/lib/python3.7/site-packages/django/db/models/sql/compiler.py", line 1065, in execute_sql
    cursor.execute(sql, params)
  File "/usr/local/lib/python3.7/site-packages/django/db/backends/utils.py", line 100, in execute
    return super().execute(sql, params)
  File "/usr/local/lib/python3.7/site-packages/django/db/backends/utils.py", line 68, in execute
    return self._execute_with_wrappers(sql, params, many=False, executor=self._execute)
  File "/usr/local/lib/python3.7/site-packages/django/db/backends/utils.py", line 77, in _execute_with_wrappers
    return executor(sql, params, many, context)
  File "/usr/local/lib/python3.7/site-packages/django/db/backends/utils.py", line 85, in _execute
    return self.cursor.execute(sql, params)
  File "/usr/local/lib/python3.7/site-packages/django/db/utils.py", line 89, in __exit__
    raise dj_exc_value.with_traceback(traceback) from exc_value
  File "/usr/local/lib/python3.7/site-packages/django/db/backends/utils.py", line 85, in _execute
    return self.cursor.execute(sql, params)
  File "/usr/local/lib/python3.7/site-packages/django/db/backends/sqlite3/base.py", line 298, in execute
    return Database.Cursor.execute(self, query, params)
django.db.utils.OperationalError: no such table: newblog_essay
[23/Apr/2019 07:39:12] "GET /newblog/essay/ HTTP/1.1" 500 163184
[23/Apr/2019 07:39:24] "GET /newblog/index/ HTTP/1.1" 200 19
[23/Apr/2019 07:39:34] "GET /admin HTTP/1.1" 301 0
[23/Apr/2019 07:39:34] "GET /admin/ HTTP/1.1" 200 7652
[23/Apr/2019 07:39:34] "GET /static/admin/css/base.css HTTP/1.1" 200 16225
[23/Apr/2019 07:39:35] "GET /static/admin/css/dashboard.css HTTP/1.1" 200 412
[23/Apr/2019 07:39:35] "GET /static/admin/css/responsive.css HTTP/1.1" 200 17976
[23/Apr/2019 07:39:35] "GET /static/admin/css/fonts.css HTTP/1.1" 200 423
[23/Apr/2019 07:39:35] "GET /static/admin/img/icon-changelink.svg HTTP/1.1" 200 380
[23/Apr/2019 07:39:35] "GET /static/admin/img/icon-deletelink.svg HTTP/1.1" 200 392
[23/Apr/2019 07:39:35] "GET /static/admin/img/icon-addlink.svg HTTP/1.1" 200 331
[23/Apr/2019 07:39:35] "GET /static/admin/fonts/Roboto-Light-webfont.woff HTTP/1.1" 200 81348
[23/Apr/2019 07:39:35] "GET /static/admin/fonts/Roboto-Bold-webfont.woff HTTP/1.1" 200 82564
[23/Apr/2019 07:39:35] "GET /static/admin/fonts/Roboto-Regular-webfont.woff HTTP/1.1" 200 80304
Internal Server Error: /admin/newblog/essay/
Traceback (most recent call last):
  File "/usr/local/lib/python3.7/site-packages/django/db/backends/utils.py", line 85, in _execute
    return self.cursor.execute(sql, params)
  File "/usr/local/lib/python3.7/site-packages/django/db/backends/sqlite3/base.py", line 298, in execute
    return Database.Cursor.execute(self, query, params)
sqlite3.OperationalError: no such table: newblog_essay

The above exception was the direct cause of the following exception:

Traceback (most recent call last):
  File "/usr/local/lib/python3.7/site-packages/django/core/handlers/exception.py", line 34, in inner
    response = get_response(request)
  File "/usr/local/lib/python3.7/site-packages/django/core/handlers/base.py", line 126, in _get_response
    response = self.process_exception_by_middleware(e, request)
  File "/usr/local/lib/python3.7/site-packages/django/core/handlers/base.py", line 124, in _get_response
    response = wrapped_callback(request, *callback_args, **callback_kwargs)
  File "/usr/local/lib/python3.7/site-packages/django/contrib/admin/options.py", line 604, in wrapper
    return self.admin_site.admin_view(view)(*args, **kwargs)
  File "/usr/local/lib/python3.7/site-packages/django/utils/decorators.py", line 142, in _wrapped_view
    response = view_func(request, *args, **kwargs)
  File "/usr/local/lib/python3.7/site-packages/django/views/decorators/cache.py", line 44, in _wrapped_view_func
    response = view_func(request, *args, **kwargs)
  File "/usr/local/lib/python3.7/site-packages/django/contrib/admin/sites.py", line 223, in inner
    return view(request, *args, **kwargs)
  File "/usr/local/lib/python3.7/site-packages/django/utils/decorators.py", line 45, in _wrapper
    return bound_method(*args, **kwargs)
  File "/usr/local/lib/python3.7/site-packages/django/utils/decorators.py", line 142, in _wrapped_view
    response = view_func(request, *args, **kwargs)
  File "/usr/local/lib/python3.7/site-packages/django/contrib/admin/options.py", line 1675, in changelist_view
    cl = self.get_changelist_instance(request)
  File "/usr/local/lib/python3.7/site-packages/django/contrib/admin/options.py", line 742, in get_changelist_instance
    sortable_by,
  File "/usr/local/lib/python3.7/site-packages/django/contrib/admin/views/main.py", line 81, in __init__
    self.get_results(request)
  File "/usr/local/lib/python3.7/site-packages/django/contrib/admin/views/main.py", line 209, in get_results
    result_count = paginator.count
  File "/usr/local/lib/python3.7/site-packages/django/utils/functional.py", line 37, in __get__
    res = instance.__dict__[self.name] = self.func(instance)
  File "/usr/local/lib/python3.7/site-packages/django/core/paginator.py", line 87, in count
    return self.object_list.count()
  File "/usr/local/lib/python3.7/site-packages/django/db/models/query.py", line 383, in count
    return self.query.get_count(using=self.db)
  File "/usr/local/lib/python3.7/site-packages/django/db/models/sql/query.py", line 498, in get_count
    number = obj.get_aggregation(using, ['__count'])['__count']
  File "/usr/local/lib/python3.7/site-packages/django/db/models/sql/query.py", line 483, in get_aggregation
    result = compiler.execute_sql(SINGLE)
  File "/usr/local/lib/python3.7/site-packages/django/db/models/sql/compiler.py", line 1065, in execute_sql
    cursor.execute(sql, params)
  File "/usr/local/lib/python3.7/site-packages/django/db/backends/utils.py", line 100, in execute
    return super().execute(sql, params)
  File "/usr/local/lib/python3.7/site-packages/django/db/backends/utils.py", line 68, in execute
    return self._execute_with_wrappers(sql, params, many=False, executor=self._execute)
  File "/usr/local/lib/python3.7/site-packages/django/db/backends/utils.py", line 77, in _execute_with_wrappers
    return executor(sql, params, many, context)
  File "/usr/local/lib/python3.7/site-packages/django/db/backends/utils.py", line 85, in _execute
    return self.cursor.execute(sql, params)
  File "/usr/local/lib/python3.7/site-packages/django/db/utils.py", line 89, in __exit__
    raise dj_exc_value.with_traceback(traceback) from exc_value
  File "/usr/local/lib/python3.7/site-packages/django/db/backends/utils.py", line 85, in _execute
    return self.cursor.execute(sql, params)
  File "/usr/local/lib/python3.7/site-packages/django/db/backends/sqlite3/base.py", line 298, in execute
    return Database.Cursor.execute(self, query, params)
django.db.utils.OperationalError: no such table: newblog_essay
[23/Apr/2019 07:39:37] "GET /admin/newblog/essay/ HTTP/1.1" 500 174095
[23/Apr/2019 07:44:09] "GET /admin/newblog/essay/ HTTP/1.1" 200 3166
[23/Apr/2019 07:44:09] "GET /static/admin/css/changelists.css HTTP/1.1" 200 6170
[23/Apr/2019 07:44:09] "GET /admin/jsi18n/ HTTP/1.1" 200 3185
[23/Apr/2019 07:44:10] "GET /static/admin/js/jquery.init.js HTTP/1.1" 200 363
[23/Apr/2019 07:44:10] "GET /static/admin/js/admin/RelatedObjectLookups.js HTTP/1.1" 200 6918
[23/Apr/2019 07:44:10] "GET /static/admin/js/core.js HTTP/1.1" 200 7135
[23/Apr/2019 07:44:10] "GET /static/admin/js/actions.js HTTP/1.1" 200 6538
[23/Apr/2019 07:44:10] "GET /static/admin/js/urlify.js HTTP/1.1" 200 8972
[23/Apr/2019 07:44:10] "GET /static/admin/js/prepopulate.js HTTP/1.1" 200 1530
[23/Apr/2019 07:44:10] "GET /static/admin/js/vendor/jquery/jquery.js HTTP/1.1" 200 271751
[23/Apr/2019 07:44:10] "GET /static/admin/js/vendor/xregexp/xregexp.js HTTP/1.1" 200 128820
[23/Apr/2019 07:44:10] "GET /static/admin/img/tooltag-add.svg HTTP/1.1" 200 331
[23/Apr/2019 07:44:16] "GET /admin/ HTTP/1.1" 200 7652
[23/Apr/2019 07:44:19] "GET /admin/newblog/essay/ HTTP/1.1" 200 3166
[23/Apr/2019 07:44:19] "GET /admin/jsi18n/ HTTP/1.1" 200 3185
[23/Apr/2019 07:44:30] "GET /admin/ HTTP/1.1" 200 7652
[23/Apr/2019 07:44:38] "GET /newblog/index/ HTTP/1.1" 200 19
[23/Apr/2019 07:44:44] "GET /newblog/essay/ HTTP/1.1" 200 1061
[23/Apr/2019 07:45:01] "GET /admin/ HTTP/1.1" 200 7652
[23/Apr/2019 07:45:04] "GET /admin/newblog/essay/ HTTP/1.1" 200 3166
[23/Apr/2019 07:45:04] "GET /admin/jsi18n/ HTTP/1.1" 200 3185
[23/Apr/2019 07:45:06] "GET /admin/newblog/essay/add/ HTTP/1.1" 200 5014
[23/Apr/2019 07:45:06] "GET /admin/jsi18n/ HTTP/1.1" 200 3185
[23/Apr/2019 07:45:06] "GET /static/admin/css/forms.css HTTP/1.1" 200 8505
[23/Apr/2019 07:45:06] "GET /static/admin/js/change_form.js HTTP/1.1" 200 712
[23/Apr/2019 07:45:06] "GET /static/admin/js/prepopulate_init.js HTTP/1.1" 200 495
[23/Apr/2019 07:45:06] "GET /static/admin/css/widgets.css HTTP/1.1" 200 10340
[23/Apr/2019 07:46:14] "POST /admin/newblog/essay/add/ HTTP/1.1" 302 0
[23/Apr/2019 07:46:14] "GET /admin/newblog/essay/ HTTP/1.1" 200 4510
[23/Apr/2019 07:46:14] "GET /admin/jsi18n/ HTTP/1.1" 200 3185
[23/Apr/2019 07:46:14] "GET /static/admin/img/icon-yes.svg HTTP/1.1" 200 436
[23/Apr/2019 07:46:27] "GET /newblog/essay/ HTTP/1.1" 200 1263
[23/Apr/2019 07:46:29] "GET /newblog/detail/1/ HTTP/1.1" 200 2957
[23/Apr/2019 07:46:37] "GET /newblog/detail/1/ HTTP/1.1" 200 2957
[23/Apr/2019 08:22:23] "GET /admin/newblog/essay/ HTTP/1.1" 200 4328
Not Found: /robots.txt
[23/Apr/2019 14:42:17] "GET /robots.txt HTTP/1.1" 404 2417
[23/Apr/2019 14:42:17] "GET /blog/edit/tocha/21/ HTTP/1.1" 200 715
[23/Apr/2019 14:43:14] "GET /blog/article/12/ HTTP/1.1" 200 344
[23/Apr/2019 14:44:22] "GET /blog/article/17/ HTTP/1.1" 200 265
[23/Apr/2019 14:45:21] "GET /blog/article/20/ HTTP/1.1" 200 424
[23/Apr/2019 14:45:39] "GET /blog/edit/tocha/20/ HTTP/1.1" 200 716
[23/Apr/2019 14:46:03] "GET /blog/edit/tocha/18/ HTTP/1.1" 200 698
[23/Apr/2019 14:46:57] "GET /blog/edit/tocha/12/ HTTP/1.1" 200 646
[23/Apr/2019 20:01:57] code 400, message Bad HTTP/0.9 request type ('\x03\x00\x00/*à\x00\x00\x00\x00\x00Cookie:')
[23/Apr/2019 20:01:57] "  /*à     Cookie: mstshash=Administr" 400 -
Not Found: /http:/www.baidu.com/cache/global/img/gs.gif
[23/Apr/2019 21:00:27] "GET http://www.baidu.com/cache/global/img/gs.gif HTTP/1.1" 404 1738
----------------------------------------
Exception happened during processing of request from ('80.82.70.187', 54897)
Traceback (most recent call last):
  File "/usr/local/lib/python3.7/socketserver.py", line 647, in process_request_thread
    self.finish_request(request, client_address)
  File "/usr/local/lib/python3.7/socketserver.py", line 357, in finish_request
    self.RequestHandlerClass(request, client_address, self)
  File "/usr/local/lib/python3.7/socketserver.py", line 717, in __init__
    self.handle()
  File "/usr/local/lib/python3.7/site-packages/django/core/servers/basehttp.py", line 171, in handle
    self.handle_one_request()
  File "/usr/local/lib/python3.7/site-packages/django/core/servers/basehttp.py", line 179, in handle_one_request
    self.raw_requestline = self.rfile.readline(65537)
  File "/usr/local/lib/python3.7/socket.py", line 589, in readinto
    return self._sock.recv_into(b)
ConnectionResetError: [Errno 104] Connection reset by peer
----------------------------------------
Not Found: /
[24/Apr/2019 01:22:08] "GET / HTTP/1.1" 404 2368
[24/Apr/2019 02:27:13] "GET /blog/edit/tocha/17/ HTTP/1.1" 200 567
Performing system checks...

System check identified no issues (0 silenced).
April 23, 2019 - 07:43:53
Django version 2.1.8, using settings 'myblog.settings'
Starting development server at http://0.0.0.0:8000/
Quit the server with CONTROL-C.
